<mujoco model="x02a">
  <compiler angle="radian" meshdir="./meshes/"/>
  <default>
    <joint damping="0.1" armature="0.01" frictionloss="0.0"/>
  </default>
  <asset>
    <mesh name="pelvis_link" file="pelvis_link.STL"/>
    <mesh name="L_hip_yaw_link" file="L_hip_yaw_link.STL"/>
    <mesh name="L_hip_roll_link" file="L_hip_roll_link.STL"/>
    <mesh name="L_hip_pitch_link" file="L_hip_pitch_link.STL"/>
    <mesh name="L_knee_pitch_link" file="L_knee_pitch_link.STL"/>
    <mesh name="L_ankle_pitch_link" file="L_ankle_pitch_link.STL"/>
    <mesh name="L_ankle_roll_link" file="L_ankle_roll_link.STL"/>
    <mesh name="R_hip_yaw_link" file="R_hip_yaw_link.STL"/>
    <mesh name="R_hip_roll_link" file="R_hip_roll_link.STL"/>
    <mesh name="R_hip_pitch_link" file="R_hip_pitch_link.STL"/>
    <mesh name="R_knee_pitch_link" file="R_knee_pitch_link.STL"/>
    <mesh name="R_ankle_pitch_link" file="R_ankle_pitch_link.STL"/>
    <mesh name="R_ankle_roll_link" file="R_ankle_roll_link.STL"/>
    <mesh name="L_shoulder_pitch_link" file="L_shoulder_pitch_link.STL"/>
    <mesh name="L_shoulder_roll_link" file="L_shoulder_roll_link.STL"/>
    <mesh name="L_shoulder_yaw_link" file="L_shoulder_yaw_link.STL"/>
    <mesh name="L_elbow_link" file="L_elbow_link.STL"/>
    <mesh name="L_forearm_yaw_link" file="L_forearm_yaw_link.STL"/>
    <mesh name="R_shoulder_pitch_link" file="R_shoulder_pitch_link.STL"/>
    <mesh name="R_shoulder_roll_link" file="R_shoulder_roll_link.STL"/>
    <mesh name="R_shoulder_yaw_link" file="R_shoulder_yaw_link.STL"/>
    <mesh name="R_elbow_link" file="R_elbow_link.STL"/>
    <mesh name="R_forearm_yaw_link" file="R_forearm_yaw_link.STL"/>
    <mesh name="Head_yaw_link" file="Head_yaw_link.STL"/>
    <mesh name="L_base_link" file="L_base_link.STL"/>
    <mesh name="L_thumb_prox" file="L_thumb_prox.STL"/>
    <mesh name="L_thumb_dist" file="L_thumb_dist.STL"/>
    <mesh name="L_Index_prox" file="L_Index_prox.STL"/>
    <mesh name="L_index_dist" file="L_index_dist.STL"/>
    <mesh name="L_middle_prox" file="L_middle_prox.STL"/>
    <mesh name="L_middle_dist" file="L_middle_dist.STL"/>
    <mesh name="L_ring_prox" file="L_ring_prox.STL"/>
    <mesh name="L_ring_dist" file="L_ring_dist.STL"/>
    <mesh name="L_little_prox" file="L_little_prox.STL"/>
    <mesh name="L_little_dist" file="L_little_dist.STL"/>
    <mesh name="R_base_link" file="R_base_link.STL"/>
    <mesh name="R_thumb_prox" file="R_thumb_prox.STL"/>
    <mesh name="R_thumb_dist" file="R_thumb_dist.STL"/>
    <mesh name="R_index_prox" file="R_index_prox.STL"/>
    <mesh name="R_index_dist" file="R_index_dist.STL"/>
    <mesh name="R_middle_prox" file="R_middle_prox.STL"/>
    <mesh name="R_middle_dist" file="R_middle_dist.STL"/>
    <mesh name="R_ring_prox" file="R_ring_prox.STL"/>
    <mesh name="R_ring_dist" file="R_ring_dist.STL"/>
    <mesh name="R_little_prox" file="R_little_prox.STL"/>
    <mesh name="R_little_dist" file="R_little_dist.STL"/>
    <mesh name="logo_link" file="logo_link.STL"/>
  </asset>

  <worldbody>
    <body name="pelvis_link" pos="0 0 1.15">
      <inertial pos="0.0172208 0.000655771 0.0631088" quat="0.99545 -0.0177194 -0.0935854 0.00260872" mass="18.6721" diaginertia="0.854165 0.528441 0.508055"/>
      <joint name="pelvis_link" type="free" limited="false" actuatorfrclimited="false"/>
      <geom type="mesh" contype="0" conaffinity="0" group="1" density="0" rgba="1 1 1 1" mesh="pelvis_link"/>
      <geom pos="0 0 0.324" quat="1 0 0 0" type="mesh" contype="0" conaffinity="0" group="1" density="0" rgba="1 1 1 1" mesh="Head_yaw_link"/>
      <geom type="mesh" contype="0" conaffinity="0" group="1" density="0" rgba="1 0 0 1" mesh="logo_link"/>
      <geom type="mesh" rgba="1 0 0 1" mesh="logo_link"/>
      <site name="imu" pos="0 0 0.17"/>
      <body name="L_hip_yaw_link" pos="0 0 -0.0629">
        <inertial pos="-0.00037185 0.013126 -0.025013" quat="0.871794 0.489586 0.00687091 0.0152604" mass="1.941" diaginertia="0.00462978 0.00385458 0.00224935"/>
        <joint name="L_hip_yaw" pos="0 0 0" axis="0 0 1" range="-0.7854 0.7854" actuatorfrcrange="-50 50"/>
        <geom type="mesh" contype="0" conaffinity="0" group="1" density="0" rgba="1 1 1 1" mesh="L_hip_yaw_link"/>
        <body name="L_hip_roll_link" pos="-0.0095 0.1 -0.053">
          <inertial pos="-0.032475 0.0001785 -0.072646" quat="0.695944 -0.175355 -0.176963 0.673496" mass="2.667" diaginertia="0.0108626 0.0106462 0.0065995"/>
          <joint name="L_hip_roll" pos="0 0 0" axis="1 0 0" range="-0.2618 0.4363" actuatorfrcrange="-110 110"/>
          <geom type="mesh" contype="0" conaffinity="0" group="1" density="0" rgba="1 1 1 1" mesh="L_hip_roll_link"/>
          <body name="L_hip_pitch_link" pos="0.0085 -0.001 -0.11">
            <inertial pos="0.004636 -5.5617e-07 -0.2027" quat="0.706939 -0.0146691 -0.0146744 0.70697" mass="1.664" diaginertia="0.0218979 0.0215921 0.00293018"/>
            <joint name="L_hip_pitch" pos="0 0 0" axis="0 -1 0" range="-0.5236 2.4434" actuatorfrcrange="-72 72"/>
            <geom type="mesh" contype="0" conaffinity="0" group="1" density="0" rgba="1 1 1 1" mesh="L_hip_pitch_link"/>
            <geom type="mesh" rgba="1 1 1 1" mesh="L_hip_pitch_link"/>
            <body name="L_knee_pitch_link" pos="0 0 -0.4">
              <inertial pos="0.00014102 1.128e-07 -0.16681" quat="0.707107 0.00106414 0.00106882 0.707105" mass="1.125" diaginertia="0.0157862 0.0156878 0.000680003"/>
              <joint name="L_knee_pitch" pos="0 0 0" axis="0 -1 0" range="-2.3561 0" actuatorfrcrange="-150 150"/>
              <geom type="mesh" contype="0" conaffinity="0" group="1" density="0" rgba="1 1 1 1" mesh="L_knee_pitch_link"/>
              <geom type="mesh" rgba="1 1 1 1" mesh="L_knee_pitch_link"/>
              <body name="L_ankle_pitch_link" pos="0.00052612 0 -0.4" quat="1 0 -0.00065765 0">
                <inertial pos="-0.00070872 -0.00023066 -0.023393" quat="-0.0214786 0.711162 0.015863 0.702521" mass="0.176" diaginertia="0.000148894 9.71392e-05 7.48666e-05"/>
                <joint name="L_ankle_pitch" pos="0 0 0" axis="0 -1 0" range="-1.3963 1.2217" actuatorfrcrange="-45 45"/>
                <geom type="mesh" contype="0" conaffinity="0" group="1" density="0" rgba="1 1 1 1" mesh="L_ankle_pitch_link"/>
                <body name="L_ankle_roll_link" pos="0 0 -0.046003">
                  <inertial pos="0.055088 -0.0010393 -0.019994" quat="0 0.705477 0 0.708733" mass="0.624" diaginertia="0.00250004 0.00215 0.000549959"/>
                  <joint name="L_ankle_roll" pos="0 0 0" axis="1 0 0" range="-0.5275 0.5275" actuatorfrcrange="-50 50"/>
                  <geom type="mesh" contype="0" conaffinity="0" group="1" density="0" rgba="1 1 1 1" mesh="L_ankle_roll_link"/>
                  <geom type="mesh" rgba="1 1 1 1" mesh="L_ankle_roll_link"/>
                </body>
              </body>
            </body>
          </body>
        </body>
      </body>
      <body name="R_hip_yaw_link" pos="0 0 -0.1159">
        <inertial pos="-0.0011645 -0.040449 0" quat="0.707002 0.707002 0.012174 0.012174" mass="0.947" diaginertia="0.00258678 0.00239929 0.000678198"/>
        <joint name="R_hip_yaw" pos="0 0 0" axis="0 0 -1" range="-0.7854 0.7854" actuatorfrcrange="-50 50"/>
        <geom type="mesh" contype="0" conaffinity="0" group="1" density="0" rgba="1 1 1 1" mesh="R_hip_yaw_link"/>
        <body name="R_hip_roll_link" pos="-0.0095 -0.1 0">
          <inertial pos="-0.032475 0.0001785 -0.072646" quat="0.646219 -0.186129 -0.16556 0.721351" mass="2.667" diaginertia="0.0108649 0.0106437 0.00659962"/>
          <joint name="R_hip_roll" pos="0 0 0" axis="-1 0 0" range="-0.2618 0.4363" actuatorfrcrange="-110 110"/>
          <geom type="mesh" contype="0" conaffinity="0" group="1" density="0" rgba="1 1 1 1" mesh="R_hip_roll_link"/>
          <body name="R_hip_pitch_link" pos="0.0085 -0.001 -0.11">
            <inertial pos="0.004636 -5.5647e-07 -0.2027" quat="0.70697 -0.0146744 -0.0146691 0.706939" mass="1.664" diaginertia="0.0218979 0.0215921 0.00293018"/>
            <joint name="R_hip_pitch" pos="0 0 0" axis="0 -1 0" range="-0.5236 2.4434" actuatorfrcrange="-72 72"/>
            <geom type="mesh" contype="0" conaffinity="0" group="1" density="0" rgba="1 1 1 1" mesh="R_hip_pitch_link"/>
            <geom type="mesh" rgba="1 1 1 1" mesh="R_hip_pitch_link"/>
            <body name="R_knee_pitch_link" pos="0 0 -0.4">
              <inertial pos="0.000141021 1.13178e-07 -0.16681" quat="0.707105 0.00106882 0.00106414 0.707107" mass="1.125" diaginertia="0.0157862 0.0156878 0.000680003"/>
              <joint name="R_knee_pitch" pos="0 0 0" axis="0 -1 0" range="-2.3561 0" actuatorfrcrange="-150 150"/>
              <geom type="mesh" contype="0" conaffinity="0" group="1" density="0" rgba="1 1 1 1" mesh="R_knee_pitch_link"/>
              <geom type="mesh" rgba="1 1 1 1" mesh="R_knee_pitch_link"/>
              <body name="R_ankle_pitch_link" pos="0.00052612 0 -0.4" quat="1 0 -0.00065765 0">
                <inertial pos="-0.00070873 0.00023066 -0.023393" quat="0.0214786 0.711162 -0.015863 0.702521" mass="0.176" diaginertia="0.000148894 9.71392e-05 7.48666e-05"/>
                <joint name="R_ankle_pitch" pos="0 0 0" axis="0 -1 0" range="-1.2217 1.3963" actuatorfrcrange="-45 45"/>
                <geom type="mesh" contype="0" conaffinity="0" group="1" density="0" rgba="1 1 1 1" mesh="R_ankle_pitch_link"/>
                <body name="R_ankle_roll_link" pos="0 0 -0.046003">
                  <inertial pos="0.055088 0.0010393 -0.019994" quat="0 0.708733 0 0.705477" mass="0.624" diaginertia="0.00250004 0.00215 0.000549959"/>
                  <joint name="R_ankle_roll" pos="0 0 0" axis="-1 0 0" range="-0.5275 0.5275" actuatorfrcrange="-50 50"/>
                  <geom type="mesh" contype="0" conaffinity="0" group="1" density="0" rgba="1 1 1 1" mesh="R_ankle_roll_link"/>
                  <geom type="mesh" rgba="1 1 1 1" mesh="R_ankle_roll_link"/>
                </body>
              </body>
            </body>
          </body>
        </body>
      </body>
      <body name="L_shoulder_pitch_link" pos="0 0.14043 0.29123" quat="0.560984 -0.430461 0.430459 0.560986">
        <inertial pos="4.4218e-09 -4.5215e-08 0.02287" quat="0.707107 0.707106 -1.10054e-06 -1.10055e-06" mass="0.763" diaginertia="5.177e-05 3.6513e-05 2.7775e-05"/>
        <joint name="L_shoulder_pitch" pos="0 0 0" axis="0 0 -1" range="-1.5707 3.1416" actuatorfrcrange="-50 50"/>
        <geom type="mesh" contype="0" conaffinity="0" group="1" density="0" rgba="1 1 1 1" mesh="L_shoulder_pitch_link"/>
        <body name="L_shoulder_roll_link" pos="0 0 0.0575" quat="0.701056 -0.701059 0.092296 0.0922963">
          <inertial pos="0.03472 -0.00020364 -3.868e-09" quat="0.00242789 0.707103 -0.00242789 0.707103" mass="0.725" diaginertia="0.00084896 0.000839629 0.000223601"/>
          <joint name="L_shoulder_roll" pos="0 0 0" axis="0 0 -1" range="0 1.5707" actuatorfrcrange="-50 50"/>
          <geom type="mesh" contype="0" conaffinity="0" group="1" density="0" rgba="1 1 1 1" mesh="L_shoulder_roll_link"/>
          <geom type="mesh" rgba="1 1 1 1" mesh="L_shoulder_roll_link"/>
          <body name="L_shoulder_yaw_link" pos="0.112 0 0" quat="0.499998 0.5 0.500002 0.5">
            <inertial pos="1.0693e-08 0.00040667 0.084068" quat="0.706773 0.0217385 -0.0217385 0.706773" mass="0.513" diaginertia="0.0012506 0.0012458 0.000218964"/>
            <joint name="L_shoulder_yaw" pos="0 0 0" axis="0 0 -1" range="-2.2689 2.2689" actuatorfrcrange="-50 50"/>
            <geom type="mesh" contype="0" conaffinity="0" group="1" density="0" rgba="1 1 1 1" mesh="L_shoulder_yaw_link"/>
            <geom type="mesh" rgba="1 1 1 1" mesh="L_shoulder_yaw_link"/>
            <body name="L_elbow_link" pos="0 -0.01 0.148" quat="-3.89602e-06 0.707107 1.29867e-06 0.707107">
              <inertial pos="0.227276 -0.00924825 -0.00211715" quat="0.492776 0.52564 0.506827 0.473287" mass="2.233" diaginertia="0.0258461 0.021599 0.0136355"/>
              <joint name="L_elbow" pos="0 0 0" axis="0 0 1" range="0 2.5307" actuatorfrcrange="-50 50"/>
              <geom type="mesh" contype="0" conaffinity="0" group="1" density="0" rgba="1 1 1 1" mesh="L_elbow_link"/>
              <geom type="mesh" rgba="1 1 1 1" mesh="L_elbow_link"/>
              <geom pos="0.1085 -0.01 0" quat="-3.89602e-06 0.707107 1.29867e-06 0.707107" type="mesh" contype="0" conaffinity="0" group="1" density="0" rgba="1 1 1 1" mesh="L_forearm_yaw_link"/>
              <geom pos="0.2585 -0.0099989 2.02384e-12" quat="-0.707109 -3.89602e-06 -1.29868e-06 0.707104" type="mesh" contype="0" conaffinity="0" group="1" density="0" rgba="0.75294 0.75294 0.75294 1" mesh="L_base_link"/>
              <geom pos="0.281132 0.0145011 0.0232633" quat="-0.594515 0.340416 0.382825 0.619769" type="mesh" contype="0" conaffinity="0" group="1" density="0" rgba="0.75294 0.75294 0.75294 1" mesh="L_thumb_prox"/>
              <geom pos="0.280678 0.0265008 0.0297473" quat="-0.640868 0.233254 0.687249 0.250139" type="mesh" contype="0" conaffinity="0" group="1" density="0" rgba="0.75294 0.75294 0.75294 1" mesh="L_thumb_dist"/>
              <geom pos="0.346791 0.0190047 0.00221604" quat="-0.719286 -0.00761023 -0.0290422 0.694065" type="mesh" contype="0" conaffinity="0" group="1" density="0" rgba="0.75294 0.75294 0.75294 1" mesh="L_Index_prox"/>
              <geom pos="0.381752 0.0202798 0.00118821" quat="-0.715186 -0.0770677 0.0381501 0.693624" type="mesh" contype="0" conaffinity="0" group="1" density="0" rgba="0.75294 0.75294 0.75294 1" mesh="L_index_dist"/>
              <geom pos="0.350784 -0.00199821 -0.0017703" quat="-0.707109 -3.89602e-06 -1.29868e-06 0.707104" type="mesh" contype="0" conaffinity="0" group="1" density="0" rgba="0.75294 0.75294 0.75294 1" mesh="L_middle_prox"/>
              <geom pos="0.392784 -0.0019979 -0.00177015" quat="-0.704133 -0.0648148 0.0648092 0.704128" type="mesh" contype="0" conaffinity="0" group="1" density="0" rgba="0.75294 0.75294 0.75294 1" mesh="L_middle_dist"/>
              <geom pos="0.348791 -0.0231012 -0.00178426" quat="-0.694328 0.0220333 0.0148613 0.719167" type="mesh" contype="0" conaffinity="0" group="1" density="0" rgba="0.75294 0.75294 0.75294 1" mesh="L_ring_prox"/>
              <geom pos="0.390763 -0.0245869 -0.00217155" quat="-0.693768 -0.0355467 0.0743717 0.715466" type="mesh" contype="0" conaffinity="0" group="1" density="0" rgba="0.75294 0.75294 0.75294 1" mesh="L_ring_dist"/>
              <geom pos="0.342277 -0.0437293 0.00221556" quat="-0.681476 0.0276301 0.00874467 0.731266" type="mesh" contype="0" conaffinity="0" group="1" density="0" rgba="1 1 1 1" mesh="L_little_prox"/>
              <geom pos="0.377178 -0.0462153 0.00134514" quat="-0.68077 -0.0415428 0.082774 0.726619" type="mesh" contype="0" conaffinity="0" group="1" density="0" rgba="0.75294 0.75294 0.75294 1" mesh="L_little_dist"/>
            </body>
          </body>
        </body>
      </body>
      <body name="R_shoulder_pitch_link" pos="0 -0.14043 0.29123" quat="0.560984 0.430461 0.430459 -0.560986">
        <inertial pos="4.4218e-09 -4.5215e-08 0.02287" quat="0.707107 0.707106 -1.10054e-06 -1.10055e-06" mass="0.763" diaginertia="5.177e-05 3.6513e-05 2.7775e-05"/>
        <joint name="R_shoulder_pitch" pos="0 0 0" axis="0 0 1" range="-1.5707 3.1416" actuatorfrcrange="-50 50"/>
        <geom type="mesh" contype="0" conaffinity="0" group="1" density="0" rgba="1 1 1 1" mesh="R_shoulder_pitch_link"/>
        <body name="R_shoulder_roll_link" pos="0 0 0.0575" quat="0.701056 -0.701059 0.092296 0.0922963">
          <inertial pos="0.03472 -0.00020364 -3.8447e-09" quat="0.00242789 0.707103 -0.00242789 0.707103" mass="0.725" diaginertia="0.00084896 0.000839629 0.000223601"/>
          <joint name="R_shoulder_roll" pos="0 0 0" axis="0 0 -1" range="0 1.5707" actuatorfrcrange="-50 50"/>
          <geom type="mesh" contype="0" conaffinity="0" group="1" density="0" rgba="1 1 1 1" mesh="R_shoulder_roll_link"/>
          <geom type="mesh" rgba="1 1 1 1" mesh="R_shoulder_roll_link"/>
          <body name="R_shoulder_yaw_link" pos="0.112 0 0" quat="0.499998 0.5 0.500002 0.5">
            <inertial pos="-1.0693e-08 -0.00040667 0.084068" quat="0.706773 -0.0217385 0.0217385 0.706773" mass="0.513" diaginertia="0.0012506 0.0012458 0.000218964"/>
            <joint name="R_shoulder_yaw" pos="0 0 0" axis="0 0 1" range="-2.2689 2.2689" actuatorfrcrange="-50 50"/>
            <geom type="mesh" contype="0" conaffinity="0" group="1" density="0" rgba="1 1 1 1" mesh="R_shoulder_yaw_link"/>
            <geom type="mesh" rgba="1 1 1 1" mesh="R_shoulder_yaw_link"/>
            <body name="R_elbow_link" pos="0 0.01 0.148" quat="-3.89602e-06 0.707107 1.29867e-06 0.707107">
              <inertial pos="0.234352 0.00809061 0.00406422" quat="0.138274 0.693187 0.123703 0.69647" mass="2.233" diaginertia="0.0174068 0.0171631 0.000591723"/>
              <joint name="R_elbow" pos="0 0 0" axis="0 0 -1" range="0 2.5307" actuatorfrcrange="-50 50"/>
              <geom type="mesh" contype="0" conaffinity="0" group="1" density="0" rgba="1 1 1 1" mesh="R_elbow_link"/>
              <geom type="mesh" rgba="1 1 1 1" mesh="R_elbow_link"/>
              <geom pos="0.1085 0.01 0" quat="-3.89602e-06 0.707107 1.29867e-06 0.707107" type="mesh" contype="0" conaffinity="0" group="1" density="0" rgba="1 1 1 1" mesh="R_forearm_yaw_link"/>
              <geom pos="0.2585 0.0100011 2.02385e-12" quat="-0.707109 -3.89602e-06 -1.29868e-06 0.707104" type="mesh" contype="0" conaffinity="0" group="1" density="0" rgba="0.75294 0.75294 0.75294 1" mesh="R_base_link"/>
              <geom pos="0.2827 -0.0144989 0.0216279" quat="-0.685439 0.17371 0.173714 0.685435" type="mesh" contype="0" conaffinity="0" group="1" density="0" rgba="1 1 1 1" mesh="R_thumb_prox"/>
              <geom pos="0.2827 -0.0264986 0.0281276" quat="-0.342025 -5.47405e-06 -5.10525e-06 0.939691" type="mesh" contype="0" conaffinity="0" group="1" density="0" rgba="0.75294 0.75294 0.75294 1" mesh="R_thumb_dist"/>
              <geom pos="0.346731 -0.0190012 -0.00394869" quat="-0.693914 0.054122 -0.0166219 0.717829" type="mesh" contype="0" conaffinity="0" group="1" density="0" rgba="0.75294 0.75294 0.75294 1" mesh="R_index_prox"/>
              <geom pos="0.381536 -0.0202757 -0.00741283" quat="-0.695896 -0.013173 0.0528082 0.716077" type="mesh" contype="0" conaffinity="0" group="1" density="0" rgba="0.75294 0.75294 0.75294 1" mesh="R_index_dist"/>
              <geom pos="0.350435 0.00200184 -0.00820352" quat="-0.706679 0.0246738 -0.0246788 0.706673" type="mesh" contype="0" conaffinity="0" group="1" density="0" rgba="0.75294 0.75294 0.75294 1" mesh="R_middle_prox"/>
              <geom pos="0.392333 0.00200217 -0.0111331" quat="-0.705966 -0.0402015 0.040196 0.705961" type="mesh" contype="0" conaffinity="0" group="1" density="0" rgba="0.75294 0.75294 0.75294 1" mesh="R_middle_dist"/>
              <geom pos="0.348447 0.0231048 -0.00807817" quat="-0.717965 0.00937448 -0.0471239 0.694419" type="mesh" contype="0" conaffinity="0" group="1" density="0" rgba="0.75294 0.75294 0.75294 1" mesh="R_ring_prox"/>
              <geom pos="0.39029 0.0245912 -0.0113923" quat="-0.716275 -0.0501196 0.0105498 0.695936" type="mesh" contype="0" conaffinity="0" group="1" density="0" rgba="0.75294 0.75294 0.75294 1" mesh="R_ring_dist"/>
              <geom pos="0.342227 0.0437327 -0.00363334" quat="-0.729862 0.0150387 -0.0531393 0.681361" type="mesh" contype="0" conaffinity="0" group="1" density="0" rgba="0.75294 0.75294 0.75294 1" mesh="R_little_prox"/>
              <geom pos="0.376982 0.0462193 -0.00693617" quat="-0.727631 -0.0589706 0.0161531 0.683239" type="mesh" contype="0" conaffinity="0" group="1" density="0" rgba="0.75294 0.75294 0.75294 1" mesh="R_little_dist"/>
            </body>
          </body>
        </body>
      </body>
    </body>
  </worldbody>
  <actuator>
    <motor name="L_hip_yaw" joint="L_hip_yaw"  ctrlrange="-50.0 50.0" ctrllimited="true" /> <!-- Leg Left -->
    <motor name="L_hip_roll" joint="L_hip_roll"  ctrlrange="-110.0 110.0" ctrllimited="true" />
    <motor name="L_hip_pitch" joint="L_hip_pitch" ctrlrange="-72.0 72.0" ctrllimited="true" />
    <motor name="L_knee_pitch" joint="L_knee_pitch" ctrlrange="-150.0 150.0" ctrllimited="true" />
    <motor name="L_ankle_pitch" joint="L_ankle_pitch" ctrlrange="-45.0 45.0" ctrllimited="true" />
    <motor name="L_ankle_roll" joint="L_ankle_roll" ctrlrange="-20.0 20.0" ctrllimited="true" />

    <motor name="R_hip_yaw" joint="R_hip_yaw"    ctrlrange="-50.0 50.0" ctrllimited="true" /> <!-- Leg Right -->
    <motor name="R_hip_roll" joint="R_hip_roll"   ctrlrange="-110.0 110.0" ctrllimited="true" />
    <motor name="R_hip_pitch" joint="R_hip_pitch"   ctrlrange="-72.0 72.0" ctrllimited="true" />
    <motor name="R_knee_pitch" joint="R_knee_pitch"  ctrlrange="-150.0 150.0" ctrllimited="true" />
    <motor name="R_ankle_pitch" joint="R_ankle_pitch" ctrlrange="-45.0 45.0" ctrllimited="true" />
    <motor name="R_ankle_roll" joint="R_ankle_roll" ctrlrange="-20.0 20.0" ctrllimited="true" />

    <motor name="L_shoulder_pitch" joint="L_shoulder_pitch" ctrlrange="-20.0 20.0" ctrllimited="true" /> <!-- Leg Left -->
    <motor name="L_shoulder_roll"  joint="L_shoulder_roll"  ctrlrange="-20.0 20.0" ctrllimited="true" />
    <motor name="L_shoulder_yaw"   joint="L_shoulder_yaw"   ctrlrange="-20.0 20.0" ctrllimited="true" />
    <motor name="L_elbow"          joint="L_elbow"          ctrlrange="-20.0 20.0" ctrllimited="true" />

    <motor name="R_shoulder_pitch" joint="R_shoulder_pitch" ctrlrange="-20.0 20.0" ctrllimited="true" /> <!-- Leg Left -->
    <motor name="R_shoulder_roll"  joint="R_shoulder_roll"  ctrlrange="-20.0 20.0" ctrllimited="true" />
    <motor name="R_shoulder_yaw"   joint="R_shoulder_yaw"   ctrlrange="-20.0 20.0" ctrllimited="true" />
    <motor name="R_elbow"          joint="R_elbow"          ctrlrange="-20.0 20.0" ctrllimited="true" />
  </actuator>
  <sensor>
    <framequat name="bq" objtype="site" noise="0.001" objname="imu" />
    <gyro name="gyro" site="imu" noise="0.005" />
  </sensor>
</mujoco>
