<?xml version="1.0" encoding="utf-8"?>
<!-- This URDF was automatically created by SolidWorks to URDF Exporter! Originally created by Stephen Brawner (brawner@gmail.com) 
     Commit Version: 1.6.0-4-g7f85cfe  Build Version: 1.6.7995.38578
     For more information, please see http://wiki.ros.org/sw_urdf_exporter -->
<robot name="x02a">

  <!-- <mujoco>
    <compiler meshdir="./meshes" discardvisual="false"/>
  </mujoco>

  <link name="world"></link>
  <joint name="pelvis_link" type="floating">
    <parent link="world"/>
    <child link="pelvis_link"/>
  </joint> -->

  <link name="pelvis_link">
    <inertial>
      <origin xyz="0.0017069 8.8509E-09 0.0017759" rpy="0 0 0" />
      <mass value="9.129" />
      <inertia ixx="0.13973477" ixy="0.00000011" ixz="-0.00047829" iyy="0.12694500" iyz="-0.00000018" izz="0.07556794" />
    </inertial>
    <visual>
      <origin xyz="0 0 0" rpy="0 0 0" />
      <geometry>
        <mesh filename="meshes/pelvis_link.STL" />
      </geometry>
      <material name="">
        <color rgba="1 1 1 1" />
      </material>
    </visual>
    <collision>
      <origin xyz="0.01 0 0.15" rpy="0 0 0" />
      <geometry>
        <box size="0.25 0.3 0.4" />
      </geometry>
    </collision>
  </link>
  <link name="L_hip_yaw_link">
    <inertial>
      <origin xyz="-0.00037185 0.013126 -0.025013" rpy="0 0 0" />
      <mass value="1.941" />
      <inertia ixx="0.00462775" ixy="0.00006271" ixz="-0.00002020" iyy="0.00268629" iyz="0.00071316" izz="0.00341967" />
    </inertial>
    <visual>
      <origin xyz="0 0 0" rpy="0 0 0" />
      <geometry>
        <mesh filename="meshes/L_hip_yaw_link.STL" />
      </geometry>
      <material name="">
        <color rgba="1 1 1 1" />
      </material>
    </visual>
  </link>
  <joint name="L_hip_yaw" type="revolute">
    <origin xyz="0 0 -0.0629" rpy="0 0 0" />
    <parent link="pelvis_link" />
    <child link="L_hip_yaw_link" />
    <axis xyz="0 0 1" />
    <limit lower="-0.7854" upper="0.7854" effort="50" velocity="20" />
  </joint>
  <link name="L_hip_roll_link">
    <inertial>
      <origin xyz="-0.032475 0.0001785 -0.072646" rpy="0 0 0" />
      <mass value="2.667" />
      <inertia ixx="0.00970422" ixy="0.00001767" ixz="0.00171027" iyy="0.01086223" iyz="-0.00001804" izz="0.00754180" />
    </inertial>
    <visual>
      <origin xyz="0 0 0" rpy="0 0 0" />
      <geometry>
        <mesh filename="meshes/L_hip_roll_link.STL" />
      </geometry>
      <material name="">
        <color rgba="1 1 1 1" />
      </material>
    </visual>
  </link>
  <joint name="L_hip_roll" type="revolute">
    <origin xyz="-0.0095 0.1 -0.053" rpy="0 0 0" />
    <parent link="L_hip_yaw_link" />
    <child link="L_hip_roll_link" />
    <axis xyz="1 0 0" />
    <limit lower="-0.2618" upper="0.4363" effort="110" velocity="20" />
  </joint>
  <link name="L_hip_pitch_link">
    <inertial>
      <origin xyz="0.004636 -5.5617E-07 -0.2027" rpy="0 0 0" />
      <mass value="1.664" />
      <inertia ixx="0.02156000" ixy="-0.00000002" ixz="0.00077360" iyy="0.02189789" iyz="0.00000016" izz="0.00296230" />
    </inertial>
    <visual>
      <origin xyz="0 0 0" rpy="0 0 0" />
      <geometry>
        <mesh filename="meshes/L_hip_pitch_link.STL" />
      </geometry>
      <material name="">
        <color rgba="1 1 1 1" />
      </material>
    </visual>
    <collision>
      <origin xyz="0 0 -0.22" rpy="0 0 0" />
      <geometry>
        <cylinder radius="0.07" length="0.25" />
      </geometry>
    </collision>
  </link>
  <joint name="L_hip_pitch" type="revolute">
    <origin xyz="0.0085 -0.001 -0.11" rpy="0 0 0" />
    <parent link="L_hip_roll_link" />
    <child link="L_hip_pitch_link" />
    <axis xyz="0 -1 0" />
    <limit lower="-0.5236" upper="2.4434" effort="72" velocity="20" />
  </joint>
  <link name="L_knee_pitch_link">
    <inertial>
      <origin xyz="0.00014102 1.128E-07 -0.16681" rpy="0 0 0" />
      <mass value="1.125" />
      <inertia ixx="0.01568763" ixy="-0.00000000" ixz="-0.00004527" iyy="0.01578617" iyz="-0.00000010" izz="0.00068014" />
    </inertial>
    <visual>
      <origin xyz="0 0 0" rpy="0 0 0" />
      <geometry>
        <mesh filename="meshes/L_knee_pitch_link.STL" />
      </geometry>
      <material name="">
        <color rgba="1 1 1 1" />
      </material>
    </visual>
    <collision>
      <origin xyz="0 0 -0.2" rpy="0 0 0" />
      <geometry>
        <cylinder radius="0.05" length="0.2" />
      </geometry>
    </collision>
  </link>
  <joint name="L_knee_pitch" type="revolute">
    <origin xyz="0 0 -0.4" rpy="0 0 0" />
    <parent link="L_hip_pitch_link" />
    <child link="L_knee_pitch_link" />
    <axis xyz="0 -1 0" />
    <limit lower="-2.3561" upper="0" effort="150" velocity="30" />
  </joint>
  <link name="L_ankle_pitch_link">
    <inertial>
      <origin xyz="-0.00070872 -0.00023066 -0.023393" rpy="0 0 0" />
      <mass value="0.176" />
      <inertia ixx="0.00007494" ixy="-0.00000118" ixz="0.00000091" iyy="0.00009708" iyz="-0.00000038" izz="0.00014888" />
    </inertial>
    <visual>
      <origin xyz="0 0 0" rpy="0 0 0" />
      <geometry>
        <mesh filename="meshes/L_ankle_pitch_link.STL" />
      </geometry>
      <material name="">
        <color rgba="1 1 1 1" />
      </material>
    </visual>
  </link>
  <joint name="L_ankle_pitch" type="revolute">
    <origin xyz="0.00052612 0 -0.4" rpy="0 -0.0013153 0" />
    <parent link="L_knee_pitch_link" />
    <child link="L_ankle_pitch_link" />
    <axis xyz="0 -1 0" />
    <limit lower="-1.3963" upper="1.2217" effort="45" velocity="20" />
  </joint>
  <link name="L_ankle_roll_link">
    <inertial>
      <origin xyz="0.055088 -0.0010393 -0.019994" rpy="0 0 0" />
      <mass value="0.624" />
      <inertia ixx="0.00055" ixy="0.0" ixz="-0.00000898" iyy="0.00215" iyz="0.0" izz="0.0025" />
    </inertial>
    <visual>
      <origin xyz="0 0 0" rpy="0 0 0" />
      <geometry>
        <mesh filename="meshes/L_ankle_roll_link.STL" />
      </geometry>
      <material name="">
        <color rgba="1 1 1 1" />
      </material>
    </visual>
    <collision>
      <origin xyz="0.0515 0 -0.022" rpy="0 0 0" />
      <geometry>
        <box size="0.234 0.08 0.03" />
      </geometry>
    </collision>
  </link>
  <joint name="L_ankle_roll" type="revolute">
    <origin xyz="0 0 -0.046003" rpy="0 0 0" />
    <parent link="L_ankle_pitch_link" />
    <child link="L_ankle_roll_link" />
    <axis xyz="1 0 0" />
    <limit lower="-0.5275" upper="0.5275" effort="50" velocity="20" />
  </joint>
  <link name="R_hip_yaw_link">
    <inertial>
      <origin xyz="-0.0011645 -0.040449 1.9321E-18" rpy="0 0 0" />
      <mass value="0.947" />
      <inertia ixx="0.00258452" ixy="0.00006567" ixz="0.00000000" iyy="0.00068046" iyz="-0.00000000" izz="0.00239929" />
    </inertial>
    <visual>
      <origin xyz="0 0 0" rpy="0 0 0" />
      <geometry>
        <mesh filename="meshes/R_hip_yaw_link.STL" />
      </geometry>
      <material name="">
        <color rgba="1 1 1 1" />
      </material>
    </visual>
  </link>
  <joint name="R_hip_yaw" type="revolute">
    <origin xyz="0 0 -0.1159" rpy="0 0 0" />
    <parent link="pelvis_link" />
    <child link="R_hip_yaw_link" />
    <axis xyz="0 0 -1" />
    <limit lower="-0.7854" upper="0.7854" effort="50" velocity="20" />
  </joint>
  <link name="R_hip_roll_link">
    <inertial>
      <origin xyz="-0.032475 0.0001785 -0.072646" rpy="0 0 0" />
      <mass value="2.667" />
      <inertia ixx="0.00970422" ixy="-0.00001767" ixz="0.00171027" iyy="0.01086223" iyz="-0.00001804" izz="0.00754180" />
    </inertial>
    <visual>
      <origin xyz="0 0 0" rpy="0 0 0" />
      <geometry>
        <mesh filename="meshes/R_hip_roll_link.STL" />
      </geometry>
      <material name="">
        <color rgba="1 1 1 1" />
      </material>
    </visual>
  </link>
  <joint name="R_hip_roll" type="revolute">
    <origin xyz="-0.0095 -0.1 0" rpy="0 0 0" />
    <parent link="R_hip_yaw_link" />
    <child link="R_hip_roll_link" />
    <axis xyz="-1 0 0" />
    <limit lower="-0.2618" upper="0.4363" effort="110" velocity="20" />
  </joint>
  <link name="R_hip_pitch_link">
    <inertial>
      <origin xyz="0.004636 -5.5647E-07 -0.2027" rpy="0 0 0" />
      <mass value="1.664" />
      <inertia ixx="0.02156000" ixy="0.00000002" ixz="0.00077360" iyy="0.02189789" iyz="-0.00000016" izz="0.00296230" />
    </inertial>
    <visual>
      <origin xyz="0 0 0" rpy="0 0 0" />
      <geometry>
        <mesh filename="meshes/R_hip_pitch_link.STL" />
      </geometry>
      <material name="">
        <color rgba="1 1 1 1" />
      </material>
    </visual>
    <collision>
      <origin xyz="0 0 -0.22" rpy="0 0 0" />
      <geometry>
        <cylinder radius="0.07" length="0.25" />
      </geometry>
    </collision>
  </link>
  <joint name="R_hip_pitch" type="revolute">
    <origin xyz="0.0085 -0.001 -0.11" rpy="0 0 0" />
    <parent link="R_hip_roll_link" />
    <child link="R_hip_pitch_link" />
    <axis xyz="0 -1 0" />
    <limit lower="-0.5236" upper="2.4434" effort="72" velocity="20" />
  </joint>
  <link name="R_knee_pitch_link">
    <inertial>
      <origin xyz="0.000141021249585588 1.13177978405821E-07 -0.166810293466822" rpy="0 0 0" />
      <mass value="1.125" />
      <inertia ixx="0.01568763" ixy="0.00000000" ixz="-0.00004527" iyy="0.01578617" iyz="0.00000010" izz="0.00068014" />
    </inertial>
    <visual>
      <origin xyz="0 0 0" rpy="0 0 0" />
      <geometry>
        <mesh filename="meshes/R_knee_pitch_link.STL" />
      </geometry>
      <material name="">
        <color rgba="1 1 1 1" />
      </material>
    </visual>
    <collision>
      <origin xyz="0 0 -0.2" rpy="0 0 0" />
      <geometry>
        <cylinder radius="0.05" length="0.2" />
      </geometry>
    </collision>
  </link>
  <joint name="R_knee_pitch" type="revolute">
    <origin xyz="0 0 -0.4" rpy="0 0 0" />
    <parent link="R_hip_pitch_link" />
    <child link="R_knee_pitch_link" />
    <axis xyz="0 -1 0" />
    <limit lower="-2.3561" upper="0" effort="150" velocity="30" />
  </joint>
  <link name="R_ankle_pitch_link">
    <inertial>
      <origin xyz="-0.00070873 0.00023066 -0.023393" rpy="0 0 0" />
      <mass value="0.176" />
      <inertia ixx="0.00007494" ixy="0.00000118" ixz="0.00000091" iyy="0.00009708" iyz="0.00000038" izz="0.00014888" />
    </inertial>
    <visual>
      <origin xyz="0 0 0" rpy="0 0 0" />
      <geometry>
        <mesh filename="meshes/R_ankle_pitch_link.STL" />
      </geometry>
      <material name="">
        <color rgba="1 1 1 1" />
      </material>
    </visual>
  </link>
  <joint name="R_ankle_pitch" type="revolute">
    <origin xyz="0.00052612 0 -0.4" rpy="0 -0.0013153 0" />
    <parent link="R_knee_pitch_link" />
    <child link="R_ankle_pitch_link" />
    <axis xyz="0 -1 0" />
    <limit lower="-1.2217" upper="1.3963" effort="45" velocity="20" />
  </joint>
  <link name="R_ankle_roll_link">
    <inertial>
      <origin xyz="0.055088 0.0010393 -0.019994" rpy="0 0 0" />
      <mass value="0.624" />
      <inertia ixx="0.00055" ixy="-0.0" ixz="0.00000898" iyy="0.00215" iyz="0.0" izz="0.0025" />
    </inertial>
    <visual>
      <origin xyz="0 0 0" rpy="0 0 0" />
      <geometry>
        <mesh filename="meshes/R_ankle_roll_link.STL" />
      </geometry>
      <material name="">
        <color rgba="1 1 1 1" />
      </material>
    </visual>
    <collision>
      <origin xyz="0.0515 0 -0.022" rpy="0 0 0" />
      <geometry>
        <box size="0.234 0.08 0.03" />
      </geometry>
    </collision>
  </link>
  <joint name="R_ankle_roll" type="revolute">
    <origin xyz="0 0 -0.046003" rpy="0 0 0" />
    <parent link="R_ankle_pitch_link" />
    <child link="R_ankle_roll_link" />
    <axis xyz="-1 0 0" />
    <limit lower="-0.5275" upper="0.5275" effort="50" velocity="20" />
  </joint>

  <link name="L_shoulder_pitch_link">
    <inertial>
      <origin xyz="4.4218E-09 -4.5215E-08 0.02287" rpy="0 0 0" />
      <mass value="0.763" />
      <inertia ixx="5.177E-05" ixy="-7.4692E-11" ixz="6.7773E-12" iyy="2.7775E-05" iyz="1.632E-11" izz="3.6513E-05" />
    </inertial>
    <visual>
      <origin xyz="0 0 0" rpy="0 0 0" />
      <geometry>
        <mesh filename="meshes/L_shoulder_pitch_link.STL" />
      </geometry>
      <material name="">
        <color rgba="1 1 1 1" />
      </material>
    </visual>
  </link>
  <joint name="L_shoulder_pitch" type="fixed">
    <origin xyz="0 0.14043 0.29123" rpy="1.0 1.0 2.6" />
    <parent link="pelvis_link" />
    <child link="L_shoulder_pitch_link" />
    <axis xyz="0 0 -1" />
    <limit lower="-1.5707" upper="3.1416" effort="50" velocity="5" />
  </joint>
  <link name="L_shoulder_roll_link">
    <inertial>
      <origin xyz="0.03472 -0.00020364 -3.868E-09" rpy="0 0 0" />
      <mass value="0.725" />
      <inertia ixx="0.00022363" ixy="4.2302E-06" ixz="1.3637E-10" iyy="0.0008396" iyz="-9.6914E-12" izz="0.00084896" />
    </inertial>
    <visual>
      <origin xyz="0 0 0" rpy="0 0 0" />
      <geometry>
        <mesh filename="meshes/L_shoulder_roll_link.STL" />
      </geometry>
      <material name="">
        <color rgba="1 1 1 1" />
      </material>
    </visual>
  </link>
  <joint name="L_shoulder_roll" type="fixed">
    <origin xyz="0 0 0.0575" rpy="-1.5708 0.2618 0" />
    <parent link="L_shoulder_pitch_link" />
    <child link="L_shoulder_roll_link" />
    <axis xyz="0 0 -1" />
    <limit lower="0" upper="1.5707" effort="50" velocity="5" />
  </joint>
  <link name="L_shoulder_yaw_link">
    <inertial>
      <origin xyz="1.0693E-08 0.00040667 0.084068" rpy="0 0 0" />
      <mass value="0.513" />
      <inertia ixx="0.0012458" ixy="5.297E-11" ixz="3.2573E-10" iyy="0.0012467" iyz="6.3281E-05" izz="0.00022286" />
    </inertial>
    <visual>
      <origin xyz="0 0 0" rpy="0 0 0" />
      <geometry>
        <mesh filename="meshes/L_shoulder_yaw_link.STL" />
      </geometry>
      <material name="">
        <color rgba="1 1 1 1" />
      </material>
    </visual>
  </link>
  <joint name="L_shoulder_yaw" type="fixed">
    <origin xyz="0.112 0 0" rpy="1.5708 0 1.5708" />
    <parent link="L_shoulder_roll_link" />
    <child link="L_shoulder_yaw_link" />
    <axis xyz="0 0 -1" />
    <limit lower="-2.2689" upper="2.2689" effort="50" velocity="5" />
  </joint>
  <link name="L_elbow_link">
    <inertial>
      <origin xyz="0.056038 -0.011478 2.3322E-08" rpy="0 0 0" />
      <mass value="0.385" />
      <inertia ixx="9.5648E-05" ixy="-8.4499E-06" ixz="-2.3351E-10" iyy="0.00027307" iyz="-3.1899E-10" izz="0.00024995" />
    </inertial>
    <visual>
      <origin xyz="0 0 0" rpy="0 0 0" />
      <geometry>
        <mesh filename="meshes/L_elbow_link.STL" />
      </geometry>
      <material name="">
        <color rgba="1 1 1 1" />
      </material>
    </visual>
  </link>
  <joint name="L_elbow" type="fixed">
    <origin xyz="0 -0.01 0.148" rpy="1.5708 -3.1415 1.5708" />
    <parent link="L_shoulder_yaw_link" />
    <child link="L_elbow_link" />
    <axis xyz="0 0 1" />
    <limit lower="0" upper="2.5307" effort="50" velocity="5" />
  </joint>
  <link name="L_forearm_yaw_link">
    <inertial>
      <origin xyz="0.0070988 -0.0018426 0.14628" rpy="0 0 0" />
      <mass value="1.3" />
      <inertia ixx="0.00024244" ixy="9.1136E-07" ixz="-8.1946E-07" iyy="0.00024264" iyz="-2.2015E-08" izz="0.00014634" />
    </inertial>
    <visual>
      <origin xyz="0 0 0" rpy="0 0 0" />
      <geometry>
        <mesh filename="meshes/L_forearm_yaw_link.STL" />
      </geometry>
      <material name="">
        <color rgba="1 1 1 1" />
      </material>
    </visual>
  </link>
  <joint name="L_forearm_yaw" type="fixed">
    <origin xyz="0.1085 -0.01 0" rpy="1.5708 -1.5708 1.5708" />
    <parent link="L_elbow_link" />
    <child link="L_forearm_yaw_link" />
    <axis xyz="0 0 -1" />
    <limit lower="-2.2689" upper="2.2689" effort="50" velocity="5" />
  </joint>
  <link name="R_shoulder_pitch_link">
    <inertial>
      <origin xyz="4.4218E-09 -4.5215E-08 0.02287" rpy="0 0 0" />
      <mass value="0.763" />
      <inertia ixx="5.177E-05" ixy="-7.4692E-11" ixz="6.7773E-12" iyy="2.7775E-05" iyz="1.632E-11" izz="3.6513E-05" />
    </inertial>
    <visual>
      <origin xyz="0 0 0" rpy="0 0 0" />
      <geometry>
        <mesh filename="meshes/R_shoulder_pitch_link.STL" />
      </geometry>
      <material name="">
        <color rgba="1 1 1 1" />
      </material>
    </visual>
  </link>
  <joint name="R_shoulder_pitch" type="fixed">
    <origin xyz="0 -0.14043 0.29123" rpy="-1.0 1.0 -2.6" />
    <parent link="pelvis_link" />
    <child link="R_shoulder_pitch_link" />
    <axis xyz="0 0 1" />
    <limit lower="-1.5707" upper="3.1416" effort="50" velocity="5" />
  </joint>
  <link name="R_shoulder_roll_link">
    <inertial>
      <origin xyz="0.03472 -0.00020364 -3.8447E-09" rpy="0 0 0" />
      <mass value="0.725" />
      <inertia ixx="0.00022363" ixy="4.2302E-06" ixz="1.3594E-10" iyy="0.0008396" iyz="-9.7226E-12" izz="0.00084896" />
    </inertial>
    <visual>
      <origin xyz="0 0 0" rpy="0 0 0" />
      <geometry>
        <mesh filename="meshes/R_shoulder_roll_link.STL" />
      </geometry>
      <material name="">
        <color rgba="1 1 1 1" />
      </material>
    </visual>
  </link>
  <joint name="R_shoulder_roll" type="fixed">
    <origin xyz="0 0 0.0575" rpy="-1.5708 0.2618 0" />
    <parent link="R_shoulder_pitch_link" />
    <child link="R_shoulder_roll_link" />
    <axis xyz="0 0 -1" />
    <limit lower="0" upper="1.5707" effort="50" velocity="5" />
  </joint>
  <link name="R_shoulder_yaw_link">
    <inertial>
      <origin xyz="-1.0693E-08 -0.00040667 0.084068" rpy="0 0 0" />
      <mass value="0.513" />
      <inertia ixx="0.0012458" ixy="5.2971E-11" ixz="-3.2573E-10" iyy="0.0012467" iyz="-6.3281E-05" izz="0.00022286" />
    </inertial>
    <visual>
      <origin xyz="0 0 0" rpy="0 0 0" />
      <geometry>
        <mesh filename="meshes/R_shoulder_yaw_link.STL" />
      </geometry>
      <material name="">
        <color rgba="1 1 1 1" />
      </material>
    </visual>
  </link>
  <joint name="R_shoulder_yaw" type="fixed">
    <origin xyz="0.112 0 0" rpy="1.5708 0 1.5708" />
    <parent link="R_shoulder_roll_link" />
    <child link="R_shoulder_yaw_link" />
    <axis xyz="0 0 1" />
    <limit lower="-2.2689" upper="2.2689" effort="50" velocity="5" />
  </joint>
  <link name="R_elbow_link">
    <inertial>
      <origin xyz="0.056038 0.011478 -2.3316E-08" rpy="0 0 0" />
      <mass value="0.385" />
      <inertia ixx="9.5648E-05" ixy="8.4499E-06" ixz="2.3352E-10" iyy="0.00027307" iyz="-3.1899E-10" izz="0.00024995" />
    </inertial>
    <visual>
      <origin xyz="0 0 0" rpy="0 0 0" />
      <geometry>
        <mesh filename="meshes/R_elbow_link.STL" />
      </geometry>
      <material name="">
        <color rgba="1 1 1 1" />
      </material>
    </visual>
  </link>
  <joint name="R_elbow" type="fixed">
    <origin xyz="0 0.01 0.148" rpy="1.5708 0 1.5708" />
    <parent link="R_shoulder_yaw_link" />
    <child link="R_elbow_link" />
    <axis xyz="0 0 -1" />
    <limit lower="0" upper="2.5307" effort="50" velocity="5" />
  </joint>
  <link name="R_forearm_yaw_link">
    <inertial>
      <origin xyz="0.0070988 0.0018422 0.14628" rpy="0 0 0" />
      <mass value="1.3" />
      <inertia ixx="0.00024245" ixy="-9.1191E-07" ixz="-8.2197E-07" iyy="0.00024264" iyz="1.7973E-08" izz="0.00014634" />
    </inertial>
    <visual>
      <origin xyz="0 0 0" rpy="0 0 0" />
      <geometry>
        <mesh filename="meshes/R_forearm_yaw_link.STL" />
      </geometry>
      <material name="">
        <color rgba="1 1 1 1" />
      </material>
    </visual>
  </link>
  <joint name="R_forearm_yaw" type="fixed">
    <origin xyz="0.1085 0.01 0" rpy="1.5708 -1.5708 1.5708" />
    <parent link="R_elbow_link" />
    <child link="R_forearm_yaw_link" />
    <axis xyz="0 0 1" />
    <limit lower="-2.2689" upper="2.2689" effort="50" velocity="5" />
  </joint>
  <link name="Head_yaw_link">
    <inertial>
      <origin xyz="0 0 0" rpy="0 0 0" />
      <mass value="1.07" />
      <inertia ixx="0.0066666" ixy="-1.0328E-06" ixz="-0.00038297" iyy="0.0069077" iyz="-2.0283E-06" izz="0.0042095" />
    </inertial>
    <visual>
      <origin xyz="0 0 0" rpy="0 0 0" />
      <geometry>
        <mesh filename="meshes/Head_yaw_link.STL" />
      </geometry>
      <material name="">
        <color rgba="1 1 1 1" />
      </material>
    </visual>
    <collision>
      <origin xyz="0.02 0 0.19" rpy="0 0 0" />
      <geometry>
        <sphere radius="0.12" />
      </geometry>
    </collision>
  </link>
  <joint name="Head_yaw" type="fixed">
    <origin xyz="0 0 0.324" rpy="0 0 0" />
    <parent link="pelvis_link" />
    <child link="Head_yaw_link" />
    <axis xyz="0 0 1" />
    <limit lower="-1.571" upper="1.571" effort="50" velocity="5" />
  </joint>
  <link name="L_base_link">
    <inertial>
      <origin xyz="0.0017239 0.0051432 -0.031065" rpy="0 0 0" />
      <mass value="0.427" />
      <inertia ixx="0.0010405" ixy="-3.7268E-05" ixz="-3.9415E-05" iyy="0.0013244" iyz="-4.7638E-05" izz="0.00053219" />
    </inertial>
    <visual>
      <origin xyz="0 0 0" rpy="0 0 0" />
      <geometry>
        <mesh filename="meshes/L_base_link.STL" />
      </geometry>
      <material name="">
        <color rgba="0.75294 0.75294 0.75294 1" />
      </material>
    </visual>
  </link>
  <joint name="L_base_link" type="fixed">
    <origin xyz="0 0 0.15" rpy="1.5708 0 1.5708" />
    <parent link="L_forearm_yaw_link" />
    <child link="L_base_link" />
    <axis xyz="0 0 -1" />
    <limit lower="-2.2689" upper="2.2689" effort="50" velocity="5" />
  </joint>
  <link name="L_thumb_prox">
    <inertial>
      <origin xyz="0.0017239 0.0051432 -0.031065" rpy="0 0 0" />
      <mass value="0.005" />
      <inertia ixx="0.0010405" ixy="-3.7268E-05" ixz="-3.9415E-05" iyy="0.0013244" iyz="-4.7638E-05" izz="0.00053219" />
    </inertial>
    <visual>
      <origin xyz="0 0 0" rpy="0 0 0" />
      <geometry>
        <mesh filename="meshes/L_thumb_prox.STL" />
      </geometry>
      <material name="">
        <color rgba="0.75294 0.75294 0.75294 1" />
      </material>
    </visual>
  </link>
  <joint name="L_thumbCMC" type="fixed">
    <origin xyz="-0.0245 0.022632 0.023263" rpy="0.14578 -1.0699 -0.12808" />
    <parent link="L_base_link" />
    <child link="L_thumb_prox" />
    <axis xyz="0 1 0" />
    <limit lower="0" upper="1.5708" effort="0" velocity="0" />
    <dynamics damping="0" friction="0" />
  </joint>
  <link name="L_thumb_dist">
    <inertial>
      <origin xyz="0.0017239 0.0051432 -0.031065" rpy="0 0 0" />
      <mass value="0.04" />
      <inertia ixx="0.0010405" ixy="-3.7268E-05" ixz="-3.9415E-05" iyy="0.0013244" iyz="-4.7638E-05" izz="0.00053219" />
    </inertial>
    <visual>
      <origin xyz="0 0 0" rpy="0 0 0" />
      <geometry>
        <mesh filename="meshes/L_thumb_dist.STL" />
      </geometry>
      <material name="">
        <color rgba="0.75294 0.75294 0.75294 1" />
      </material>
    </visual>
  </link>
  <joint name="L_thumbMCP" type="fixed">
    <origin xyz="0 0 0.013647" rpy="0.87266 -0.49642 0" />
    <parent link="L_thumb_prox" />
    <child link="L_thumb_dist" />
    <axis xyz="-1 0 0" />
    <limit lower="0" upper="0.8727" effort="0" velocity="0" />
    <dynamics damping="0" friction="0" />
  </joint>
  <link name="L_Index_prox">
    <inertial>
      <origin xyz="0.0017239 0.0051432 -0.031065" rpy="0 0 0" />
      <mass value="0.008" />
      <inertia ixx="0.0010405" ixy="-3.7268E-05" ixz="-3.9415E-05" iyy="0.0013244" iyz="-4.7638E-05" izz="0.00053219" />
    </inertial>
    <visual>
      <origin xyz="0 0 0" rpy="0 0 0" />
      <geometry>
        <mesh filename="meshes/L_Index_prox.STL" />
      </geometry>
      <material name="">
        <color rgba="0.75294 0.75294 0.75294 1" />
      </material>
    </visual>
  </link>
  <joint name="L_indexMCP" type="fixed">
    <origin xyz="-0.029003 0.088291 0.0022155" rpy="-0.029415 0.05236 0.034907" />
    <parent link="L_base_link" />
    <child link="L_Index_prox" />
    <axis xyz="1 0 0" />
    <limit lower="0" upper="1.309" effort="0" velocity="0" />
    <dynamics damping="0" friction="0" />
  </joint>
  <link name="L_index_dist">
    <inertial>
      <origin xyz="0.0017239 0.0051432 -0.031065" rpy="0 0 0" />
      <mass value="0.011" />
      <inertia ixx="0.0010405" ixy="-3.7268E-05" ixz="-3.9415E-05" iyy="0.0013244" iyz="-4.7638E-05" izz="0.00053219" />
    </inertial>
    <visual>
      <origin xyz="0 0 0" rpy="0 0 0" />
      <geometry>
        <mesh filename="meshes/L_index_dist.STL" />
      </geometry>
      <material name="">
        <color rgba="0.75294 0.75294 0.75294 1" />
      </material>
    </visual>
  </link>
  <joint name="L_indexPIP" type="fixed">
    <origin xyz="0 0.035 0" rpy="0.19353 0 0" />
    <parent link="L_Index_prox" />
    <child link="L_index_dist" />
    <axis xyz="1 0 0" />
    <limit lower="0" upper="2.0944" effort="0" velocity="0" />
  </joint>
  <link name="L_middle_prox">
    <inertial>
      <origin xyz="0.0017239 0.0051432 -0.031065" rpy="0 0 0" />
      <mass value="0.011" />
      <inertia ixx="0.0010405" ixy="-3.7268E-05" ixz="-3.9415E-05" iyy="0.0013244" iyz="-4.7638E-05" izz="0.00053219" />
    </inertial>
    <visual>
      <origin xyz="0 0 0" rpy="0 0 0" />
      <geometry>
        <mesh filename="meshes/L_middle_prox.STL" />
      </geometry>
      <material name="">
        <color rgba="0.75294 0.75294 0.75294 1" />
      </material>
    </visual>
  </link>
  <joint name="L_middleMCP" type="fixed">
    <origin xyz="-0.008 0.092284 -0.0017707" rpy="0 0 0" />
    <parent link="L_base_link" />
    <child link="L_middle_prox" />
    <axis xyz="1 0 0" />
    <limit lower="0" upper="1.309" effort="0" velocity="0" />
    <dynamics damping="0" friction="0" />
  </joint>
  <link name="L_middle_dist">
    <inertial>
      <origin xyz="0.0017239 0.0051432 -0.031065" rpy="0 0 0" />
      <mass value="0.011" />
      <inertia ixx="0.0010405" ixy="-3.7268E-05" ixz="-3.9415E-05" iyy="0.0013244" iyz="-4.7638E-05" izz="0.00053219" />
    </inertial>
    <visual>
      <origin xyz="0 0 0" rpy="0 0 0" />
      <geometry>
        <mesh filename="meshes/L_middle_dist.STL" />
      </geometry>
      <material name="">
        <color rgba="0.75294 0.75294 0.75294 1" />
      </material>
    </visual>
  </link>
  <joint name="L_middlePIP" type="fixed">
    <origin xyz="0 0.042 0" rpy="0.18357 0 0" />
    <parent link="L_middle_prox" />
    <child link="L_middle_dist" />
    <axis xyz="1 0 0" />
    <limit lower="0" upper="2.0944" effort="0" velocity="0" />
  </joint>
  <link name="L_ring_prox">
    <inertial>
      <origin xyz="0.0017239 0.0051432 -0.031065" rpy="0 0 0" />
      <mass value="0.011" />
      <inertia ixx="0.0010405" ixy="-3.7268E-05" ixz="-3.9415E-05" iyy="0.0013244" iyz="-4.7638E-05" izz="0.00053219" />
    </inertial>
    <visual>
      <origin xyz="0 0 0" rpy="0 0 0" />
      <geometry>
        <mesh filename="meshes/L_ring_prox.STL" />
      </geometry>
      <material name="">
        <color rgba="0.75294 0.75294 0.75294 1" />
      </material>
    </visual>
  </link>
  <joint name="L_ringMCP" type="fixed">
    <origin xyz="0.013103 0.090291 -0.0017845" rpy="-0.0092374 -0.05236 -0.034907" />
    <parent link="L_base_link" />
    <child link="L_ring_prox" />
    <axis xyz="1 0 0" />
    <limit lower="0" upper="1.309" effort="0" velocity="0" />
    <dynamics damping="0" friction="0" />
  </joint>
  <link name="L_ring_dist">
    <inertial>
      <origin xyz="0.0017239 0.0051432 -0.031065" rpy="0 0 0" />
      <mass value="0.008" />
      <inertia ixx="0.0010405" ixy="-3.7268E-05" ixz="-3.9415E-05" iyy="0.0013244" iyz="-4.7638E-05" izz="0.00053219" />
    </inertial>
    <visual>
      <origin xyz="0 0 0" rpy="0 0 0" />
      <geometry>
        <mesh filename="meshes/L_ring_dist.STL" />
      </geometry>
      <material name="">
        <color rgba="0.75294 0.75294 0.75294 1" />
      </material>
    </visual>
  </link>
  <joint name="L_ringPIP" type="fixed">
    <origin xyz="0 0.042 0" rpy="0.16583 0 0" />
    <parent link="L_ring_prox" />
    <child link="L_ring_dist" />
    <axis xyz="1 0 0" />
    <limit lower="0" upper="2.0944" effort="0" velocity="0" />
  </joint>
  <link name="L_little_prox">
    <inertial>
      <origin xyz="0 0 0" rpy="0 0 0" />
      <mass value="0.008" />
      <inertia ixx="3.3526E-07" ixy="2.8461E-11" ixz="-2.3358E-12" iyy="1.0129E-07" iyz="2.1346E-08" izz="3.7096E-07" />
    </inertial>
    <visual>
      <origin xyz="0 0 0" rpy="0 0 0" />
      <geometry>
        <mesh filename="meshes/L_little_prox.STL" />
      </geometry>
      <material name="">
        <color rgba="1 1 1 1" />
      </material>
    </visual>
  </link>
  <joint name="L_littleMCP" type="fixed">
    <origin xyz="0.033731 0.083777 0.0022155" rpy="-0.024909 -0.05236 -0.069813" />
    <parent link="L_base_link" />
    <child link="L_little_prox" />
    <axis xyz="1 0 0" />
    <limit lower="0" upper="1.309" effort="0" velocity="0" />
    <dynamics damping="0" friction="0" />
  </joint>
  <link name="L_little_dist">
    <inertial>
      <origin xyz="0.0017239 0.0051432 -0.031065" rpy="0 0 0" />
      <mass value="0.008" />
      <inertia ixx="0.0010405" ixy="-3.7268E-05" ixz="-3.9415E-05" iyy="0.0013244" iyz="-4.7638E-05" izz="0.00053219" />
    </inertial>
    <visual>
      <origin xyz="0 0 0" rpy="0 0 0" />
      <geometry>
        <mesh filename="meshes/L_little_dist.STL" />
      </geometry>
      <material name="">
        <color rgba="0.75294 0.75294 0.75294 1" />
      </material>
    </visual>
  </link>
  <joint name="L_littlePIP" type="fixed">
    <origin xyz="0 0.035 0" rpy="0.20294 0 0" />
    <parent link="L_little_prox" />
    <child link="L_little_dist" />
    <axis xyz="1 0 0" />
    <limit lower="0" upper="2.0944" effort="0" velocity="0" />
  </joint>
  <link name="R_base_link">
    <inertial>
      <origin xyz="-0.00099373 0.040537 -0.0022835" rpy="0 0 0" />
      <mass value="0.427" />
      <inertia ixx="3.4364E-05" ixy="-1.2404E-06" ixz="5.654E-07" iyy="3.9467E-05" iyz="3.8955E-06" izz="6.3984E-05" />
    </inertial>
    <visual>
      <origin xyz="0 0 0" rpy="0 0 0" />
      <geometry>
        <mesh filename="meshes/R_base_link.STL" />
      </geometry>
      <material name="">
        <color rgba="0.75294 0.75294 0.75294 1" />
      </material>
    </visual>
  </link>
  <joint name="R_base_link" type="fixed">
    <origin xyz="0 0 0.15" rpy="1.5708 0 1.5708" />
    <parent link="R_forearm_yaw_link" />
    <child link="R_base_link" />
    <axis xyz="0 0 -1" />
    <limit lower="-2.2689" upper="2.2689" effort="50" velocity="5" />
  </joint>
  <link name="R_thumb_prox">
    <inertial>
      <origin xyz="0.0062041 -7.9383E-08 0.0015306" rpy="0 0 0" />
      <mass value="0.005" />
      <inertia ixx="4.0639E-08" ixy="5.8675E-13" ixz="2.4299E-09" iyy="9.2485E-08" iyz="7.1049E-13" izz="8.5586E-08" />
    </inertial>
    <visual>
      <origin xyz="0 0 0" rpy="0 0 0" />
      <geometry>
        <mesh filename="meshes/R_thumb_prox.STL" />
      </geometry>
      <material name="">
        <color rgba="1 1 1 1" />
      </material>
    </visual>
  </link>
  <joint name="R_thumbCMC" type="fixed">
    <origin xyz="0.0245 0.0242 0.021628" rpy="0 -0.49642 0" />
    <parent link="R_base_link" />
    <child link="R_thumb_prox" />
    <axis xyz="0 -1 0" />
    <limit lower="0" upper="1.5708" effort="0" velocity="0" />
  </joint>
  <link name="R_thumb_dist">
    <inertial>
      <origin xyz="0.0083564 0.037204 -3.5884E-07" rpy="0 0 0" />
      <mass value="0.04" />
      <inertia ixx="7.1498E-06" ixy="2.0157E-07" ixz="-6.0726E-11" iyy="9.1501E-07" iyz="5.4502E-10" izz="6.8747E-06" />
    </inertial>
    <visual>
      <origin xyz="0 0 0" rpy="0 0 0" />
      <geometry>
        <mesh filename="meshes/R_thumb_dist.STL" />
      </geometry>
      <material name="">
        <color rgba="0.75294 0.75294 0.75294 1" />
      </material>
    </visual>
  </link>
  <joint name="R_thumbMCP" type="fixed">
    <origin xyz="0.013647 0 0" rpy="-0.39332 0.31115 -0.93514" />
    <parent link="R_thumb_prox" />
    <child link="R_thumb_dist" />
    <axis xyz="0 0 1" />
    <limit lower="0" upper="0.87266" effort="0" velocity="0" />
  </joint>
  <link name="R_index_prox">
    <inertial>
      <origin xyz="-5.571E-07 0.016609 0.00045746" rpy="0 0 0" />
      <mass value="0.008" />
      <inertia ixx="3.3526E-07" ixy="2.9401E-11" ixz="-2.4782E-12" iyy="1.0133E-07" iyz="2.0576E-08" izz="3.7092E-07" />
    </inertial>
    <visual>
      <origin xyz="0 0 0" rpy="0 0 0" />
      <geometry>
        <mesh filename="meshes/R_index_prox.STL" />
      </geometry>
      <material name="">
        <color rgba="0.75294 0.75294 0.75294 1" />
      </material>
    </visual>
  </link>
  <joint name="R_indexMCP" type="fixed">
    <origin xyz="0.029003 0.088231 -0.0039488" rpy="-0.09929 -0.054667 -0.031168" />
    <parent link="R_base_link" />
    <child link="R_index_prox" />
    <axis xyz="1 0 0" />
    <limit lower="0" upper="1.309" effort="0" velocity="0" />
  </joint>
  <link name="R_index_dist">
    <inertial>
      <origin xyz="5.9401E-06 0.025449 0.003278" rpy="0 0 0" />
      <mass value="0.011" />
      <inertia ixx="8.4801E-07" ixy="-1.0878E-09" ixz="-1.3683E-10" iyy="1.4147E-07" iyz="-1.0078E-07" izz="8.5502E-07" />
    </inertial>
    <visual>
      <origin xyz="0 0 0" rpy="0 0 0" />
      <geometry>
        <mesh filename="meshes/R_index_dist.STL" />
      </geometry>
      <material name="">
        <color rgba="0.75294 0.75294 0.75294 1" />
      </material>
    </visual>
  </link>
  <joint name="R_indexPIP" type="fixed">
    <origin xyz="0 0.035 0" rpy="0.19353 0 0" />
    <parent link="R_index_prox" />
    <child link="R_index_dist" />
    <axis xyz="1 0 0" />
    <limit lower="0" upper="2.0944" effort="0" velocity="0" />
  </joint>
  <link name="R_middle_prox">
    <inertial>
      <origin xyz="2.3779E-07 0.020205 0.00053993" rpy="0 0 0" />
      <mass value="0.011" />
      <inertia ixx="5.5624E-07" ixy="8E-12" ixz="-8.5151E-12" iyy="1.3298E-07" iyz="2.669E-08" izz="6.0146E-07" />
    </inertial>
    <visual>
      <origin xyz="0 0 0" rpy="0 0 0" />
      <geometry>
        <mesh filename="meshes/R_middle_prox.STL" />
      </geometry>
      <material name="">
        <color rgba="0.75294 0.75294 0.75294 1" />
      </material>
    </visual>
  </link>
  <joint name="R_middleMCP" type="fixed">
    <origin xyz="0.008 0.091935 -0.0082038" rpy="-0.069813 0 0" />
    <parent link="R_base_link" />
    <child link="R_middle_prox" />
    <axis xyz="1 0 0" />
    <limit lower="0" upper="1.309" effort="0" velocity="0" />
  </joint>
  <link name="R_middle_dist">
    <inertial>
      <origin xyz="5.9404E-06 0.025449 0.003278" rpy="0 0 0" />
      <mass value="0.011" />
      <inertia ixx="8.4801E-07" ixy="-1.0879E-09" ixz="-1.3705E-10" iyy="1.4147E-07" iyz="-1.0078E-07" izz="8.5501E-07" />
    </inertial>
    <visual>
      <origin xyz="0 0 0" rpy="0 0 0" />
      <geometry>
        <mesh filename="meshes/R_middle_dist.STL" />
      </geometry>
      <material name="">
        <color rgba="0.75294 0.75294 0.75294 1" />
      </material>
    </visual>
  </link>
  <joint name="R_middlePIP" type="fixed">
    <origin xyz="0 0.042 0" rpy="0.18357 0 0" />
    <parent link="R_middle_prox" />
    <child link="R_middle_dist" />
    <axis xyz="1 0 0" />
    <limit lower="0" upper="2.0944" effort="0" velocity="0" />
  </joint>
  <link name="R_ring_prox">
    <inertial>
      <origin xyz="2.4507E-07 0.020236 0.00042373" rpy="0 0 0" />
      <mass value="0.011" />
      <inertia ixx="5.5623E-07" ixy="7.4604E-12" ixz="-8.5876E-12" iyy="1.3295E-07" iyz="2.7719E-08" izz="6.0149E-07" />
    </inertial>
    <visual>
      <origin xyz="0 0 0" rpy="0 0 0" />
      <geometry>
        <mesh filename="meshes/R_ring_prox.STL" />
      </geometry>
      <material name="">
        <color rgba="0.75294 0.75294 0.75294 1" />
      </material>
    </visual>
  </link>
  <joint name="R_ringMCP" type="fixed">
    <origin xyz="-0.013103 0.089947 -0.0080786" rpy="-0.079113 0.054667 0.031168" />
    <parent link="R_base_link" />
    <child link="R_ring_prox" />
    <axis xyz="1 0 0" />
    <limit lower="0" upper="1.309" effort="0" velocity="0" />
  </joint>
  <link name="R_ring_dist">
    <inertial>
      <origin xyz="5.5799E-07 0.020388 0.0029077" rpy="0 0 0" />
      <mass value="0.008" />
      <inertia ixx="3.6793E-07" ixy="-6.504E-13" ixz="-1.1541E-11" iyy="8.4208E-08" iyz="-4.5737E-08" izz="3.8369E-07" />
    </inertial>
    <visual>
      <origin xyz="0 0 0" rpy="0 0 0" />
      <geometry>
        <mesh filename="meshes/R_ring_dist.STL" />
      </geometry>
      <material name="">
        <color rgba="0.75294 0.75294 0.75294 1" />
      </material>
    </visual>
  </link>
  <joint name="R_ringPIP" type="fixed">
    <origin xyz="0 0.042 0" rpy="0.16583 0 0" />
    <parent link="R_ring_prox" />
    <child link="R_ring_dist" />
    <axis xyz="1 0 0" />
    <limit lower="0" upper="2.0944" effort="0" velocity="0" />
  </joint>
  <link name="R_little_prox">
    <inertial>
      <origin xyz="-5.4618E-07 0.016662 0.00040738" rpy="0 0 0" />
      <mass value="0.008" />
      <inertia ixx="3.3526E-07" ixy="2.8461E-11" ixz="-2.3358E-12" iyy="1.0129E-07" iyz="2.1346E-08" izz="3.7096E-07" />
    </inertial>
    <visual>
      <origin xyz="0 0 0" rpy="0 0 0" />
      <geometry>
        <mesh filename="meshes/R_little_prox.STL" />
      </geometry>
      <material name="">
        <color rgba="0.75294 0.75294 0.75294 1" />
      </material>
    </visual>
  </link>
  <joint name="R_littleMCP" type="fixed">
    <origin xyz="-0.033731 0.083727 -0.0036339" rpy="-0.094666 0.057099 0.065996" />
    <parent link="R_base_link" />
    <child link="R_little_prox" />
    <axis xyz="1 0 0" />
    <limit lower="0" upper="1.309" effort="0" velocity="0" />
  </joint>
  <link name="R_little_dist">
    <inertial>
      <origin xyz="1.062E-05 0.017869 0.0020864" rpy="0 0 0" />
      <mass value="0.008" />
      <inertia ixx="2.3262E-07" ixy="-4.9135E-10" ixz="-4.9506E-11" iyy="6.4304E-08" iyz="-2.3564E-08" izz="2.4916E-07" />
    </inertial>
    <visual>
      <origin xyz="0 0 0" rpy="0 0 0" />
      <geometry>
        <mesh filename="meshes/R_little_dist.STL" />
      </geometry>
      <material name="">
        <color rgba="0.75294 0.75294 0.75294 1" />
      </material>
    </visual>
  </link>
  <joint name="R_littlePIP" type="fixed">
    <origin xyz="0 0.035 0" rpy="0.20294 0 0" />
    <parent link="R_little_prox" />
    <child link="R_little_dist" />
    <axis xyz="1 0 0" />
    <limit lower="0" upper="2.0944" effort="0" velocity="0" />
  </joint>
  <link name="logo_link">
    <inertial>
      <origin xyz="0.0871329867569411 0.00031141383229557 0.206173346061323" rpy="0 0 0" />
      <mass value="0.00512067016144956" />
      <inertia ixx="1.2355192806033E-06" ixy="-8.30865202777827E-11" ixz="4.47381968468081E-07" iyy="1.10152197060949E-06" iyz="5.47449866435603E-10" izz="9.74577588899789E-07" />
    </inertial>
    <visual>
      <origin xyz="0 0 0" rpy="0 0 0" />
      <geometry>
        <mesh filename="meshes/logo_link.STL" />
      </geometry>
      <material name="">
        <color rgba="1 0 0 1" />
      </material>
    </visual>
  </link>
  <joint name="logo" type="fixed">
    <origin xyz="0 0 0" rpy="0 0 0" />
    <parent link="pelvis_link" />
    <child link="logo_link" />
    <axis xyz="0 0 0" />
  </joint>
</robot>