<mujoco model="x2">
  <compiler angle="radian" meshdir="./meshes/"/>
  <default>
    <joint damping="0.1" armature="0.01" frictionloss="0.0"/>
  </default>
  <asset>
    <mesh name="pelvis_link" file="pelvis_link.STL"/>
    <mesh name="L_hip_yaw_link" file="L_hip_yaw_link.STL"/>
    <mesh name="L_hip_roll_link" file="L_hip_roll_link.STL"/>
    <mesh name="L_hip_pitch_link" file="L_hip_pitch_link.STL"/>
    <mesh name="L_knee_pitch_link" file="L_knee_pitch_link.STL"/>
    <mesh name="L_ankle_pitch_link" file="L_ankle_pitch_link.STL"/>
    <mesh name="R_hip_yaw_link" file="R_hip_yaw_link.STL"/>
    <mesh name="R_hip_roll_link" file="R_hip_roll_link.STL"/>
    <mesh name="R_hip_pitch_link" file="R_hip_pitch_link.STL"/>
    <mesh name="R_knee_pitch_link" file="R_knee_pitch_link.STL"/>
    <mesh name="R_ankle_pitch_link" file="R_ankle_pitch_link.STL"/>
    <mesh name="waist_yaw_link" file="waist_yaw_link.STL"/>
    <mesh name="torso_link" file="torso_link.STL"/>
    <mesh name="Head_yaw_link" file="Head_yaw_link.STL"/>
    <mesh name="logo_link" file="logo_link.STL"/>
    <mesh name="L_shoulder_pitch_link" file="L_shoulder_pitch_link.STL"/>
    <mesh name="L_shoulder_roll_link" file="L_shoulder_roll_link.STL"/>
    <mesh name="L_shoulder_yaw_link" file="L_shoulder_yaw_link.STL"/>
    <mesh name="L_elbow_pitch_link" file="L_elbow_pitch_link.STL"/>
    <mesh name="L_forearm_yaw_link" file="L_forearm_yaw_link.STL"/>
    <mesh name="R_shoulder_pitch_link" file="R_shoulder_pitch_link.STL"/>
    <mesh name="R_shoulder_roll_link" file="R_shoulder_roll_link.STL"/>
    <mesh name="R_shoulder_yaw_link" file="R_shoulder_yaw_link.STL"/>
    <mesh name="R_elbow_pitch_link" file="R_elbow_pitch_link.STL"/>
    <mesh name="R_forearm_yaw_link" file="R_forearm_yaw_link.STL"/>
    <mesh name="L_base_link" file="L_base_link.STL"/>
    <mesh name="L_thumb_prox" file="L_thumb_prox.STL"/>
    <mesh name="L_thumb_dist" file="L_thumb_dist.STL"/>
    <mesh name="L_Index_prox" file="L_Index_prox.STL"/>
    <mesh name="L_index_dist" file="L_index_dist.STL"/>
    <mesh name="L_middle_prox" file="L_middle_prox.STL"/>
    <mesh name="L_middle_dist" file="L_middle_dist.STL"/>
    <mesh name="L_ring_prox" file="L_ring_prox.STL"/>
    <mesh name="L_ring_dist" file="L_ring_dist.STL"/>
    <mesh name="L_little_prox" file="L_little_prox.STL"/>
    <mesh name="L_little_dist" file="L_little_dist.STL"/>
    <mesh name="R_base_link" file="R_base_link.STL"/>
    <mesh name="R_thumb_prox" file="R_thumb_prox.STL"/>
    <mesh name="R_thumb_dist" file="R_thumb_dist.STL"/>
    <mesh name="R_index_prox" file="R_index_prox.STL"/>
    <mesh name="R_index_dist" file="R_index_dist.STL"/>
    <mesh name="R_middle_prox" file="R_middle_prox.STL"/>
    <mesh name="R_middle_dist" file="R_middle_dist.STL"/>
    <mesh name="R_ring_prox" file="R_ring_prox.STL"/>
    <mesh name="R_ring_dist" file="R_ring_dist.STL"/>
    <mesh name="R_little_prox" file="R_little_prox.STL"/>
    <mesh name="R_little_dist" file="R_little_dist.STL"/>
  </asset>

  <worldbody>
    <body name="pelvis_link" pos="0 0 0.91">
      <inertial pos="0.0294155 -5.69893e-05 0.251887" quat="0.994033 -0.000424129 -0.109076 -2.76984e-05" mass="20.4062" diaginertia="1.37187 1.08931 0.509498"/>
      <joint name="pelvis_link" type="free" limited="false" actuatorfrclimited="false"/>
      <geom type="mesh" contype="0" conaffinity="0" group="1" density="0" rgba="1 1 1 1" mesh="pelvis_link"/>
      <geom pos="0 0 0.08375" type="mesh" contype="0" conaffinity="0" group="1" density="0" rgba="1 1 1 1" mesh="waist_yaw_link"/>
      <geom pos="0 0 0.1205" quat="1 0 0 0" type="mesh" contype="0" conaffinity="0" group="1" density="0" rgba="0.823529 0.823529 0.823529 1" mesh="torso_link"/>
      <geom pos="0 0 0.485" quat="1 0 0 0" type="mesh" contype="0" conaffinity="0" group="1" density="0" rgba="1 1 1 1" mesh="Head_yaw_link"/>
      <geom pos="0 0 0.1205" quat="1 0 0 0" type="mesh" contype="0" conaffinity="0" group="1" density="0" rgba="1 0 0 1" mesh="logo_link"/>
      <geom pos="0 0.14043 0.41173" quat="0.560984 -0.430461 0.430459 0.560986" type="mesh" contype="0" conaffinity="0" group="1" density="0" rgba="1 1 1 1" mesh="L_shoulder_pitch_link"/>
      <geom pos="-2.04013e-07 0.195971 0.426612" quat="-3.89602e-06 -0.707107 -1.29867e-06 0.707107" type="mesh" contype="0" conaffinity="0" group="1" density="0" rgba="1 1 1 1" mesh="L_shoulder_roll_link"/>
      <geom pos="-2.04011e-07 0.19597 0.314612" quat="-1.29866e-06 -0.707109 0.707104 -3.89602e-06" type="mesh" contype="0" conaffinity="0" group="1" density="0" rgba="1 1 1 1" mesh="L_shoulder_yaw_link"/>
      <geom pos="0.0100003 0.195969 0.166612" quat="0.630181 0.630178 0.320739 -0.32074" type="mesh" contype="0" conaffinity="0" group="1" density="0" rgba="1 1 1 1" mesh="L_elbow_pitch_link"/>
      <geom pos="0.0657681 0.195969 0.0730053" quat="-0.218808 0.6724 -0.672401 0.218811" type="mesh" contype="0" conaffinity="0" group="1" density="0" rgba="1 1 1 1" mesh="L_forearm_yaw_link"/>
      <geom pos="0.154045 0.195968 -0.0482682" quat="-0.218807 -0.218811 -0.672398 0.672403" type="mesh" contype="0" conaffinity="0" group="1" density="0" rgba="0.75294 0.75294 0.75294 1" mesh="L_base_link"/>
      <geom pos="0.187172 0.172705 -0.0521474" quat="-0.513177 0.161445 -0.449185 0.713315" type="mesh" contype="0" conaffinity="0" group="1" density="0" rgba="0.75294 0.75294 0.75294 1" mesh="L_thumb_prox"/>
      <geom pos="0.196606 0.166221 -0.0447188" quat="-0.691052 0.0437895 -0.00490637 0.72146" type="mesh" contype="0" conaffinity="0" group="1" density="0" rgba="0.75294 0.75294 0.75294 1" mesh="L_thumb_dist"/>
      <geom pos="0.229453 0.193752 -0.102582" quat="-0.216555 -0.244775 -0.683948 0.65223" type="mesh" contype="0" conaffinity="0" group="1" density="0" rgba="0.75294 0.75294 0.75294 1" mesh="L_Index_prox"/>
      <geom pos="0.251059 0.19478 -0.130098" quat="-0.191893 -0.264552 -0.617734 0.715258" type="mesh" contype="0" conaffinity="0" group="1" density="0" rgba="0.75294 0.75294 0.75294 1" mesh="L_index_dist"/>
      <geom pos="0.214823 0.197738 -0.118171" quat="-0.218807 -0.218811 -0.672398 0.672403" type="mesh" contype="0" conaffinity="0" group="1" density="0" rgba="0.75294 0.75294 0.75294 1" mesh="L_middle_prox"/>
      <geom pos="0.23954 0.197738 -0.152127" quat="-0.197831 -0.237945 -0.607938 0.731202" type="mesh" contype="0" conaffinity="0" group="1" density="0" rgba="0.75294 0.75294 0.75294 1" mesh="L_middle_dist"/>
      <geom pos="0.196588 0.197752 -0.128979" quat="-0.225538 -0.188234 -0.673603 0.678203" type="mesh" contype="0" conaffinity="0" group="1" density="0" rgba="0.75294 0.75294 0.75294 1" mesh="L_ring_prox"/>
      <geom pos="0.220088 0.198139 -0.163787" quat="-0.209174 -0.206266 -0.61512 0.731661" type="mesh" contype="0" conaffinity="0" group="1" density="0" rgba="0.75294 0.75294 0.75294 1" mesh="L_ring_dist"/>
      <geom pos="0.176077 0.193752 -0.135852" quat="-0.215123 -0.174689 -0.682755 0.676056" type="mesh" contype="0" conaffinity="0" group="1" density="0" rgba="1 1 1 1" mesh="L_little_prox"/>
      <geom pos="0.194606 0.194623 -0.165532" quat="-0.196322 -0.195581 -0.610761 0.741739" type="mesh" contype="0" conaffinity="0" group="1" density="0" rgba="0.75294 0.75294 0.75294 1" mesh="L_little_dist"/>
      <geom pos="0 -0.14043 0.41173" quat="0.560984 0.430461 0.430459 -0.560986" type="mesh" contype="0" conaffinity="0" group="1" density="0" rgba="1 1 1 1" mesh="R_shoulder_pitch_link"/>
      <geom pos="-2.04013e-07 -0.195971 0.426612" quat="0.707107 1.29867e-06 0.707107 1.29867e-06" type="mesh" contype="0" conaffinity="0" group="1" density="0" rgba="1 1 1 1" mesh="R_shoulder_roll_link"/>
      <geom pos="-2.04011e-07 -0.19597 0.314612" quat="-3.89602e-06 0.707107 0.707107 1.29868e-06" type="mesh" contype="0" conaffinity="0" group="1" density="0" rgba="1 1 1 1" mesh="R_shoulder_yaw_link"/>
      <geom pos="0.00999925 -0.195969 0.166612" quat="-0.630181 0.630173 -0.320745 -0.320744" type="mesh" contype="0" conaffinity="0" group="1" density="0" rgba="1 1 1 1" mesh="R_elbow_pitch_link"/>
      <geom pos="0.0657656 -0.195969 0.0730044" quat="-0.218797 -0.672408 -0.672399 -0.218802" type="mesh" contype="0" conaffinity="0" group="1" density="0" rgba="1 1 1 1" mesh="R_forearm_yaw_link"/>
      <geom pos="0.154039 -0.195968 -0.0482717" quat="0.672408 -0.672399 -0.218794 -0.218805" type="mesh" contype="0" conaffinity="0" group="1" density="0" rgba="0.75294 0.75294 0.75294 1" mesh="R_base_link"/>
      <geom pos="0.188089 -0.17434 -0.0534193" quat="0.59805 -0.705546 -0.377279 -0.0469114" type="mesh" contype="0" conaffinity="0" group="1" density="0" rgba="1 1 1 1" mesh="R_thumb_prox"/>
      <geom pos="0.197791 -0.167841 -0.0463575" quat="0.516939 -0.516934 -0.48246 -0.482478" type="mesh" contype="0" conaffinity="0" group="1" density="0" rgba="0.75294 0.75294 0.75294 1" mesh="R_thumb_dist"/>
      <geom pos="0.22941 -0.199917 -0.102539" quat="0.628093 -0.706964 -0.236672 -0.222909" type="mesh" contype="0" conaffinity="0" group="1" density="0" rgba="0.75294 0.75294 0.75294 1" mesh="R_index_prox"/>
      <geom pos="0.250923 -0.203381 -0.129929" quat="0.693457 -0.642974 -0.257101 -0.199" type="mesh" contype="0" conaffinity="0" group="1" density="0" rgba="0.75294 0.75294 0.75294 1" mesh="R_index_dist"/>
      <geom pos="0.214609 -0.204171 -0.117894" quat="0.648532 -0.695456 -0.211025 -0.226307" type="mesh" contype="0" conaffinity="0" group="1" density="0" rgba="0.75294 0.75294 0.75294 1" mesh="R_middle_prox"/>
      <geom pos="0.239265 -0.207101 -0.151769" quat="0.709545 -0.633087 -0.230879 -0.206013" type="mesh" contype="0" conaffinity="0" group="1" density="0" rgba="0.75294 0.75294 0.75294 1" mesh="R_middle_dist"/>
      <geom pos="0.196377 -0.204046 -0.128706" quat="0.654156 -0.696196 -0.18063 -0.234016" type="mesh" contype="0" conaffinity="0" group="1" density="0" rgba="0.75294 0.75294 0.75294 1" mesh="R_ring_prox"/>
      <geom pos="0.2198 -0.20736 -0.16341" quat="0.709568 -0.639627 -0.199391 -0.218252" type="mesh" contype="0" conaffinity="0" group="1" density="0" rgba="0.75294 0.75294 0.75294 1" mesh="R_ring_dist"/>
      <geom pos="0.176039 -0.199601 -0.135816" quat="0.651966 -0.705003 -0.166612 -0.223945" type="mesh" contype="0" conaffinity="0" group="1" density="0" rgba="0.75294 0.75294 0.75294 1" mesh="R_little_prox"/>
      <geom pos="0.194482 -0.202904 -0.165379" quat="0.720026 -0.635335 -0.18844 -0.205916" type="mesh" contype="0" conaffinity="0" group="1" density="0" rgba="0.75294 0.75294 0.75294 1" mesh="R_little_dist"/>
      <body name="L_hip_yaw_link">
        <inertial pos="-0.0005618 0.019831 0.00885104" quat="0.416547 0.491409 -0.566922 0.513426" mass="0.841" diaginertia="0.00175713 0.00175343 0.000573392"/>
        <joint name="L_hip_yaw" pos="0 0 0" axis="0 0 1" range="-0.7854 0.7854" actuatorfrcrange="-30 30"/>
        <geom type="mesh" contype="0" conaffinity="0" group="1" density="0" rgba="1 1 1 1" mesh="L_hip_yaw_link"/>
        <body name="L_hip_roll_link" pos="-0.0095 0.1 0">
          <inertial pos="-0.0324725 0.00017925 -0.0726484" quat="0.655395 -0.252501 -0.247695 0.667344" mass="2.667" diaginertia="0.0108627 0.0094793 0.00603247"/>
          <joint name="L_hip_roll" pos="0 0 0" axis="1 0 0" range="-0.349 0.524" actuatorfrcrange="-45 45"/>
          <geom type="mesh" contype="0" conaffinity="0" group="1" density="0" rgba="1 1 1 1" mesh="L_hip_roll_link"/>
          <body name="L_hip_pitch_link" pos="0.0085 -0.001 -0.11">
            <inertial pos="0.00382921 0 -0.185484" quat="0.706562 0.0278169 0.0278188 0.706557" mass="1.664" diaginertia="0.0148443 0.0145077 0.0030868"/>
            <joint name="L_hip_pitch" pos="0 0 0" axis="0 -1 0" range="-0.526 2.4434" actuatorfrcrange="-45 45"/>
            <geom type="mesh" contype="0" conaffinity="0" group="1" density="0" rgba="1 1 1 1" mesh="L_hip_pitch_link"/>
            <body name="L_knee_pitch_link" pos="0 0 -0.35">
              <inertial pos="0.00140265 0 -0.15876" quat="0.706958 -0.0143173 -0.0143148 0.706965" mass="1.125" diaginertia="0.00999859 0.00987345 0.00100926"/>
              <joint name="L_knee_pitch" pos="0 0 0" axis="0 -1 0" range="-2.3561 0" actuatorfrcrange="-60 60"/>
              <geom type="mesh" contype="0" conaffinity="0" group="1" density="0" rgba="1 1 1 1" mesh="L_knee_pitch_link"/>
              <body name="L_ankle_pitch_link" pos="0 0 -0.35">
                <inertial pos="0.0393988 -0.000237278 -0.0784143" quat="0.000325049 0.702196 0.00149391 0.711983" mass="0.556154" diaginertia="0.00260529 0.00243297 0.000325398"/>
                <joint name="L_ankle_pitch" pos="0 0 0" axis="0 -1 0" range="-0.6 0.6" actuatorfrcrange="-30 30"/>
                <geom type="mesh" contype="0" conaffinity="0" group="1" density="0" rgba="1 1 1 1" mesh="L_ankle_pitch_link"/>
                <geom type="mesh" rgba="1 1 1 1" mesh="L_ankle_pitch_link"/>
              </body>
            </body>
          </body>
        </body>
      </body>
      <body name="R_hip_yaw_link">
        <inertial pos="-0.00116447 -0.0404495 0" quat="0.707002 0.707002 -0.0121739 -0.0121739" mass="0.219202" diaginertia="0.000598763 0.000555362 0.000156982"/>
        <joint name="R_hip_yaw" pos="0 0 0" axis="0 0 -1" range="-0.7854 0.7854" actuatorfrcrange="-30 30"/>
        <geom type="mesh" contype="0" conaffinity="0" group="1" density="0" rgba="1 1 1 1" mesh="R_hip_yaw_link"/>
        <body name="R_hip_roll_link" pos="-0.0095 -0.1 0">
          <inertial pos="-0.0324725 0.00017925 -0.0726484" quat="0.655395 -0.252501 -0.247695 0.667344" mass="2.667" diaginertia="0.0108627 0.0094793 0.00603247"/>
          <joint name="R_hip_roll" pos="0 0 0" axis="-1 0 0" range="-0.349 0.524" actuatorfrcrange="-45 45"/>
          <geom type="mesh" contype="0" conaffinity="0" group="1" density="0" rgba="1 1 1 1" mesh="R_hip_roll_link"/>
          <body name="R_hip_pitch_link" pos="0.0085 -0.001 -0.11">
            <inertial pos="0.00382921 0 -0.185485" quat="0.706557 0.0278188 0.0278169 0.706562" mass="1.664" diaginertia="0.0148443 0.0145077 0.0030868"/>
            <joint name="R_hip_pitch" pos="0 0 0" axis="0 -1 0" range="-0.526 2.4434" actuatorfrcrange="-45 45"/>
            <geom type="mesh" contype="0" conaffinity="0" group="1" density="0" rgba="1 1 1 1" mesh="R_hip_pitch_link"/>
            <body name="R_knee_pitch_link" pos="0 0 -0.35">
              <inertial pos="0.00140265 0 -0.15876" quat="0.706965 -0.0143148 -0.0143173 0.706958" mass="1.125" diaginertia="0.00999859 0.00987345 0.00100926"/>
              <joint name="R_knee_pitch" pos="0 0 0" axis="0 -1 0" range="-2.3561 0" actuatorfrcrange="-60 60"/>
              <geom type="mesh" contype="0" conaffinity="0" group="1" density="0" rgba="1 1 1 1" mesh="R_knee_pitch_link"/>
              <body name="R_ankle_pitch_link" pos="0 0 -0.35">
                <inertial pos="0.0393998 0.00023708 -0.0784145" quat="-0.000325049 0.702196 -0.00149391 0.711983" mass="0.556161" diaginertia="0.00260529 0.00243297 0.000325398"/>
                <joint name="R_ankle_pitch" pos="0 0 0" axis="0 -1 0" range="-0.6 0.6" actuatorfrcrange="-30 30"/>
                <geom type="mesh" contype="0" conaffinity="0" group="1" density="0" rgba="1 1 1 1" mesh="R_ankle_pitch_link"/>
                <geom type="mesh" rgba="1 1 1 1" mesh="R_ankle_pitch_link"/>
              </body>
            </body>
          </body>
        </body>
      </body>
    </body>
  </worldbody>
  <actuator>
    <motor name="juL" joint="L_hip_yaw"       /> <!-- Leg Left -->
    <motor name="jsL" joint="L_hip_roll"      />
    <motor name="jhL" joint="L_hip_pitch"     />
    <motor name="jkL" joint="L_knee_pitch"    />
    <motor name="jpL" joint="L_ankle_pitch"   />

    <motor name="juR" joint="R_hip_yaw"       /> <!-- Leg Right -->
    <motor name="jsR" joint="R_hip_roll"      />
    <motor name="jhR" joint="R_hip_pitch"     />
    <motor name="jkR" joint="R_knee_pitch"    />
    <motor name="jpR" joint="R_ankle_pitch"   />
  </actuator>
</mujoco>
