<mujoco model="x2d10">
  <compiler angle="radian" meshdir="./meshes/"/>
  <default>
    <joint damping="0.1" armature="0.01" frictionloss="0.0"/>
  </default>
  <asset>
    <mesh name="pelvis_link" file="pelvis_link.STL"/>
    <mesh name="L_hip_yaw_link" file="L_hip_yaw_link.STL"/>
    <mesh name="L_hip_roll_link" file="L_hip_roll_link.STL"/>
    <mesh name="L_hip_pitch_link" file="L_hip_pitch_link.STL"/>
    <mesh name="L_knee_pitch_link" file="L_knee_pitch_link.STL"/>
    <mesh name="L_ankle_pitch_link" file="L_ankle_pitch_link.STL"/>
    <mesh name="R_hip_yaw_link" file="R_hip_yaw_link.STL"/>
    <mesh name="R_hip_roll_link" file="R_hip_roll_link.STL"/>
    <mesh name="R_hip_pitch_link" file="R_hip_pitch_link.STL"/>
    <mesh name="R_knee_pitch_link" file="R_knee_pitch_link.STL"/>
    <mesh name="R_ankle_pitch_link" file="R_ankle_pitch_link.STL"/>
    <mesh name="waist_yaw_link" file="waist_yaw_link.STL"/>
    <mesh name="torso_link" file="torso_link.STL"/>
    <mesh name="Head_yaw_link" file="Head_yaw_link.STL"/>
    <mesh name="logo_link" file="logo_link.STL"/>
    <mesh name="L_shoulder_pitch_link" file="L_shoulder_pitch_link.STL"/>
    <mesh name="L_shoulder_roll_link" file="L_shoulder_roll_link.STL"/>
    <mesh name="L_shoulder_yaw_link" file="L_shoulder_yaw_link.STL"/>
    <mesh name="L_elbow_pitch_link" file="L_elbow_pitch_link.STL"/>
    <mesh name="L_forearm_yaw_link" file="L_forearm_yaw_link.STL"/>
    <mesh name="R_shoulder_pitch_link" file="R_shoulder_pitch_link.STL"/>
    <mesh name="R_shoulder_roll_link" file="R_shoulder_roll_link.STL"/>
    <mesh name="R_shoulder_yaw_link" file="R_shoulder_yaw_link.STL"/>
    <mesh name="R_elbow_pitch_link" file="R_elbow_pitch_link.STL"/>
    <mesh name="R_forearm_yaw_link" file="R_forearm_yaw_link.STL"/>
    <mesh name="L_base_link" file="L_base_link.STL"/>
    <mesh name="L_thumb_prox" file="L_thumb_prox.STL"/>
    <mesh name="L_thumb_dist" file="L_thumb_dist.STL"/>
    <mesh name="L_Index_prox" file="L_Index_prox.STL"/>
    <mesh name="L_index_dist" file="L_index_dist.STL"/>
    <mesh name="L_middle_prox" file="L_middle_prox.STL"/>
    <mesh name="L_middle_dist" file="L_middle_dist.STL"/>
    <mesh name="L_ring_prox" file="L_ring_prox.STL"/>
    <mesh name="L_ring_dist" file="L_ring_dist.STL"/>
    <mesh name="L_little_prox" file="L_little_prox.STL"/>
    <mesh name="L_little_dist" file="L_little_dist.STL"/>
    <mesh name="R_base_link" file="R_base_link.STL"/>
    <mesh name="R_thumb_prox" file="R_thumb_prox.STL"/>
    <mesh name="R_thumb_dist" file="R_thumb_dist.STL"/>
    <mesh name="R_index_prox" file="R_index_prox.STL"/>
    <mesh name="R_index_dist" file="R_index_dist.STL"/>
    <mesh name="R_middle_prox" file="R_middle_prox.STL"/>
    <mesh name="R_middle_dist" file="R_middle_dist.STL"/>
    <mesh name="R_ring_prox" file="R_ring_prox.STL"/>
    <mesh name="R_ring_dist" file="R_ring_dist.STL"/>
    <mesh name="R_little_prox" file="R_little_prox.STL"/>
    <mesh name="R_little_dist" file="R_little_dist.STL"/>
  </asset>

  <worldbody>
    <body name="pelvis_link" pos="0 0 0.91">
      <inertial pos="0.0310525 -5.70011e-05 0.247568" quat="0.993299 0.00047739 -0.115098 0.0104129" mass="20.4062" diaginertia="1.39771 1.11296 0.518885"/>
      <joint name="pelvis_link" type="free" limited="false" actuatorfrclimited="false"/>
      <geom type="mesh" contype="0" conaffinity="0" group="1" density="0" rgba="1 1 1 1" mesh="pelvis_link"/>
      <geom pos="0 0 0.08375" type="mesh" contype="0" conaffinity="0" group="1" density="0" rgba="1 1 1 1" mesh="waist_yaw_link"/>
      <geom pos="0 0 0.1205" quat="1 0 0 0" type="mesh" contype="0" conaffinity="0" group="1" density="0" rgba="0.823529 0.823529 0.823529 1" mesh="torso_link"/>
      <geom pos="0 0 0.485" quat="1 0 0 0" type="mesh" contype="0" conaffinity="0" group="1" density="0" rgba="1 1 1 1" mesh="Head_yaw_link"/>
      <geom pos="0 0 0.1205" quat="1 0 0 0" type="mesh" contype="0" conaffinity="0" group="1" density="0" rgba="1 0 0 1" mesh="logo_link"/>
      <geom pos="0 0.14043 0.41173" quat="0.499998 -0.500002 0.5 0.5" type="mesh" contype="0" conaffinity="0" group="1" density="0" rgba="1 1 1 1" mesh="L_shoulder_pitch_link"/>
      <geom pos="-2.11209e-07 0.19793 0.41173" quat="-3.89602e-06 -0.707107 -1.29867e-06 0.707107" type="mesh" contype="0" conaffinity="0" group="1" density="0" rgba="1 1 1 1" mesh="L_shoulder_roll_link"/>
      <geom pos="-2.11208e-07 0.19793 0.29973" quat="-1.29866e-06 -0.707109 0.707104 -3.89602e-06" type="mesh" contype="0" conaffinity="0" group="1" density="0" rgba="1 1 1 1" mesh="L_shoulder_yaw_link"/>
      <geom pos="0.0100003 0.197929 0.15173" quat="0.631459 0.631456 0.318216 -0.318217" type="mesh" contype="0" conaffinity="0" group="1" density="0" rgba="1 1 1 1" mesh="L_elbow_pitch_link"/>
      <geom pos="0.0665151 0.197928 0.0585723" quat="-0.221496 0.67152 -0.67152 0.221498" type="mesh" contype="0" conaffinity="0" group="1" density="0" rgba="1 1 1 1" mesh="L_forearm_yaw_link"/>
      <geom pos="0.155759 0.197928 -0.0619911" quat="-0.221495 -0.221499 -0.671518 0.671522" type="mesh" contype="0" conaffinity="0" group="1" density="0" rgba="0.75294 0.75294 0.75294 1" mesh="L_base_link"/>
      <geom pos="0.188916 0.174664 -0.0656051" quat="-0.514969 0.15859 -0.447129 0.713955" type="mesh" contype="0" conaffinity="0" group="1" density="0" rgba="0.75294 0.75294 0.75294 1" mesh="L_thumb_prox"/>
      <geom pos="0.198291 0.16818 -0.0581013" quat="-0.691066 0.0409033 -0.00214214 0.72163" type="mesh" contype="0" conaffinity="0" group="1" density="0" rgba="0.75294 0.75294 0.75294 1" mesh="L_thumb_dist"/>
      <geom pos="0.2316 0.195711 -0.1157" quat="-0.219289 -0.247382 -0.683077 0.651246" type="mesh" contype="0" conaffinity="0" group="1" density="0" rgba="0.75294 0.75294 0.75294 1" mesh="L_Index_prox"/>
      <geom pos="0.253425 0.196739 -0.143042" quat="-0.194362 -0.267411 -0.616962 0.714194" type="mesh" contype="0" conaffinity="0" group="1" density="0" rgba="0.75294 0.75294 0.75294 1" mesh="L_index_dist"/>
      <geom pos="0.217094 0.199698 -0.131405" quat="-0.221495 -0.221499 -0.671518 0.671522" type="mesh" contype="0" conaffinity="0" group="1" density="0" rgba="0.75294 0.75294 0.75294 1" mesh="L_middle_prox"/>
      <geom pos="0.242083 0.199697 -0.165163" quat="-0.200261 -0.240868 -0.607142 0.730244" type="mesh" contype="0" conaffinity="0" group="1" density="0" rgba="0.75294 0.75294 0.75294 1" mesh="L_middle_dist"/>
      <geom pos="0.198947 0.199711 -0.142359" quat="-0.228231 -0.190945 -0.672696 0.677445" type="mesh" contype="0" conaffinity="0" group="1" density="0" rgba="0.75294 0.75294 0.75294 1" mesh="L_ring_prox"/>
      <geom pos="0.222724 0.200099 -0.176978" quat="-0.211633 -0.209191 -0.614279 0.73083" type="mesh" contype="0" conaffinity="0" group="1" density="0" rgba="0.75294 0.75294 0.75294 1" mesh="L_ring_dist"/>
      <geom pos="0.178491 0.195712 -0.149396" quat="-0.217853 -0.177391 -0.681889 0.675352" type="mesh" contype="0" conaffinity="0" group="1" density="0" rgba="1 1 1 1" mesh="L_little_prox"/>
      <geom pos="0.197258 0.196582 -0.178927" quat="-0.198763 -0.198547 -0.609971 0.74095" type="mesh" contype="0" conaffinity="0" group="1" density="0" rgba="0.75294 0.75294 0.75294 1" mesh="L_little_dist"/>
      <geom pos="0 -0.14043 0.41173" quat="0.499998 0.500002 0.5 -0.5" type="mesh" contype="0" conaffinity="0" group="1" density="0" rgba="1 1 1 1" mesh="R_shoulder_pitch_link"/>
      <geom pos="-2.11209e-07 -0.19793 0.41173" quat="0.707107 1.29867e-06 0.707107 1.29867e-06" type="mesh" contype="0" conaffinity="0" group="1" density="0" rgba="1 1 1 1" mesh="R_shoulder_roll_link"/>
      <geom pos="-2.11208e-07 -0.19793 0.29973" quat="-3.89602e-06 0.707107 0.707107 1.29868e-06" type="mesh" contype="0" conaffinity="0" group="1" density="0" rgba="1 1 1 1" mesh="R_shoulder_yaw_link"/>
      <geom pos="0.00999925 -0.197929 0.15173" quat="-0.641138 0.64113 -0.29824 -0.298239" type="mesh" contype="0" conaffinity="0" group="1" density="0" rgba="1 1 1 1" mesh="R_elbow_pitch_link"/>
      <geom pos="0.0722478 -0.197928 0.0623017" quat="-0.242458 -0.664243 -0.664234 -0.242463" type="mesh" contype="0" conaffinity="0" group="1" density="0" rgba="1 1 1 1" mesh="R_forearm_yaw_link"/>
      <geom pos="0.168879 -0.197928 -0.052426" quat="0.664243 -0.664234 -0.242455 -0.242466" type="mesh" contype="0" conaffinity="0" group="1" density="0" rgba="0.75294 0.75294 0.75294 1" mesh="R_base_link"/>
      <geom pos="0.203208 -0.1763 -0.055152" quat="0.584323 -0.703444 -0.398209 -0.0718533" type="mesh" contype="0" conaffinity="0" group="1" density="0" rgba="1 1 1 1" mesh="R_thumb_prox"/>
      <geom pos="0.212386 -0.1698 -0.0474216" quat="0.49954 -0.499534 -0.500454 -0.500472" type="mesh" contype="0" conaffinity="0" group="1" density="0" rgba="0.75294 0.75294 0.75294 1" mesh="R_thumb_dist"/>
      <geom pos="0.247901 -0.201876 -0.101226" quat="0.619323 -0.698632 -0.258753 -0.247791" type="mesh" contype="0" conaffinity="0" group="1" density="0" rgba="0.75294 0.75294 0.75294 1" mesh="R_index_prox"/>
      <geom pos="0.271297 -0.20534 -0.127025" quat="0.683923 -0.635528 -0.281483 -0.221632" type="mesh" contype="0" conaffinity="0" group="1" density="0" rgba="0.75294 0.75294 0.75294 1" mesh="R_index_dist"/>
      <geom pos="0.234223 -0.206131 -0.117589" quat="0.640657 -0.687011 -0.233846 -0.25078" type="mesh" contype="0" conaffinity="0" group="1" density="0" rgba="0.75294 0.75294 0.75294 1" mesh="R_middle_prox"/>
      <geom pos="0.261213 -0.20906 -0.149635" quat="0.700929 -0.625399 -0.255847 -0.228291" type="mesh" contype="0" conaffinity="0" group="1" density="0" rgba="0.75294 0.75294 0.75294 1" mesh="R_middle_dist"/>
      <geom pos="0.216801 -0.206005 -0.129663" quat="0.647353 -0.687477 -0.203669 -0.25851" type="mesh" contype="0" conaffinity="0" group="1" density="0" rgba="0.75294 0.75294 0.75294 1" mesh="R_ring_prox"/>
      <geom pos="0.24262 -0.209319 -0.162624" quat="0.702066 -0.631502 -0.224379 -0.240754" type="mesh" contype="0" conaffinity="0" group="1" density="0" rgba="0.75294 0.75294 0.75294 1" mesh="R_ring_dist"/>
      <geom pos="0.197017 -0.20156 -0.138195" quat="0.64566 -0.696636 -0.189582 -0.248757" type="mesh" contype="0" conaffinity="0" group="1" density="0" rgba="0.75294 0.75294 0.75294 1" mesh="R_little_prox"/>
      <geom pos="0.217505 -0.204863 -0.166379" quat="0.712906 -0.62765 -0.213805 -0.228274" type="mesh" contype="0" conaffinity="0" group="1" density="0" rgba="0.75294 0.75294 0.75294 1" mesh="R_little_dist"/>
      <body name="L_hip_yaw_link">
        <inertial pos="-0.0005618 0.019831 0.00885104" quat="0.416547 0.491409 -0.566922 0.513426" mass="0.841" diaginertia="0.00175713 0.00175343 0.000573392"/>
        <joint name="L_hip_yaw" pos="0 0 0" axis="0 0 1" range="-0.7854 0.7854" actuatorfrcrange="-30 30"/>
        <geom type="mesh" contype="0" conaffinity="0" group="1" density="0" rgba="1 1 1 1" mesh="L_hip_yaw_link"/>
        <body name="L_hip_roll_link" pos="-0.0095 0.1 0">
          <inertial pos="-0.0324725 0.00017925 -0.0726484" quat="0.655395 -0.252501 -0.247695 0.667344" mass="2.667" diaginertia="0.0108627 0.0094793 0.00603247"/>
          <joint name="L_hip_roll" pos="0 0 0" axis="1 0 0" range="-0.349 0.524" actuatorfrcrange="-45 45"/>
          <geom type="mesh" contype="0" conaffinity="0" group="1" density="0" rgba="1 1 1 1" mesh="L_hip_roll_link"/>
          <body name="L_hip_pitch_link" pos="0.0085 -0.001 -0.11">
            <inertial pos="0.00382921 0 -0.185484" quat="0.706562 0.0278169 0.0278188 0.706557" mass="1.664" diaginertia="0.0148443 0.0145077 0.0030868"/>
            <joint name="L_hip_pitch" pos="0 0 0" axis="0 -1 0" range="-0.526 2.4434" actuatorfrcrange="-45 45"/>
            <geom type="mesh" contype="0" conaffinity="0" group="1" density="0" rgba="1 1 1 1" mesh="L_hip_pitch_link"/>
            <body name="L_knee_pitch_link" pos="0 0 -0.35">
              <inertial pos="0.00140265 0 -0.15876" quat="0.706958 -0.0143173 -0.0143148 0.706965" mass="1.125" diaginertia="0.00999859 0.00987345 0.00100926"/>
              <joint name="L_knee_pitch" pos="0 0 0" axis="0 -1 0" range="-2.3561 0" actuatorfrcrange="-60 60"/>
              <geom type="mesh" contype="0" conaffinity="0" group="1" density="0" rgba="1 1 1 1" mesh="L_knee_pitch_link"/>
              <body name="L_ankle_pitch_link" pos="0 0 -0.35">
                <inertial pos="0.0393988 -0.000237278 -0.0784143" quat="0.000325049 0.702196 0.00149391 0.711983" mass="0.556154" diaginertia="0.00260529 0.00243297 0.000325398"/>
                <joint name="L_ankle_pitch" pos="0 0 0" axis="0 -1 0" range="-0.6 0.6" actuatorfrcrange="-30 30"/>
                <geom type="mesh" contype="0" conaffinity="0" group="1" density="0" rgba="1 1 1 1" mesh="L_ankle_pitch_link"/>
                <geom type="mesh" rgba="1 1 1 1" mesh="L_ankle_pitch_link"/>
              </body>
            </body>
          </body>
        </body>
      </body>
      <body name="R_hip_yaw_link">
        <inertial pos="-0.00116447 -0.0404495 0" quat="0.707002 0.707002 -0.0121739 -0.0121739" mass="0.219202" diaginertia="0.000598763 0.000555362 0.000156982"/>
        <joint name="R_hip_yaw" pos="0 0 0" axis="0 0 -1" range="-0.7854 0.7854" actuatorfrcrange="-30 30"/>
        <geom type="mesh" contype="0" conaffinity="0" group="1" density="0" rgba="1 1 1 1" mesh="R_hip_yaw_link"/>
        <body name="R_hip_roll_link" pos="-0.0095 -0.1 0">
          <inertial pos="-0.0324725 0.00017925 -0.0726484" quat="0.655395 -0.252501 -0.247695 0.667344" mass="2.667" diaginertia="0.0108627 0.0094793 0.00603247"/>
          <joint name="R_hip_roll" pos="0 0 0" axis="-1 0 0" range="-0.349 0.524" actuatorfrcrange="-45 45"/>
          <geom type="mesh" contype="0" conaffinity="0" group="1" density="0" rgba="1 1 1 1" mesh="R_hip_roll_link"/>
          <body name="R_hip_pitch_link" pos="0.0085 -0.001 -0.11">
            <inertial pos="0.00382921 0 -0.185485" quat="0.706557 0.0278188 0.0278169 0.706562" mass="1.664" diaginertia="0.0148443 0.0145077 0.0030868"/>
            <joint name="R_hip_pitch" pos="0 0 0" axis="0 -1 0" range="-0.526 2.4434" actuatorfrcrange="-45 45"/>
            <geom type="mesh" contype="0" conaffinity="0" group="1" density="0" rgba="1 1 1 1" mesh="R_hip_pitch_link"/>
            <body name="R_knee_pitch_link" pos="0 0 -0.35">
              <inertial pos="0.00140265 0 -0.15876" quat="0.706965 -0.0143148 -0.0143173 0.706958" mass="1.125" diaginertia="0.00999859 0.00987345 0.00100926"/>
              <joint name="R_knee_pitch" pos="0 0 0" axis="0 -1 0" range="-2.3561 0" actuatorfrcrange="-60 60"/>
              <geom type="mesh" contype="0" conaffinity="0" group="1" density="0" rgba="1 1 1 1" mesh="R_knee_pitch_link"/>
              <body name="R_ankle_pitch_link" pos="0 0 -0.35">
                <inertial pos="0.0393998 0.00023708 -0.0784145" quat="-0.000325049 0.702196 -0.00149391 0.711983" mass="0.556161" diaginertia="0.00260529 0.00243297 0.000325398"/>
                <joint name="R_ankle_pitch" pos="0 0 0" axis="0 -1 0" range="-0.6 0.6" actuatorfrcrange="-30 30"/>
                <geom type="mesh" contype="0" conaffinity="0" group="1" density="0" rgba="1 1 1 1" mesh="R_ankle_pitch_link"/>
                <geom type="mesh" rgba="1 1 1 1" mesh="R_ankle_pitch_link"/>
              </body>
            </body>
          </body>
        </body>
      </body>
    </body>
  </worldbody>
  <actuator>
    <motor name="juL" joint="L_hip_yaw"       /> <!-- Leg Left -->
    <motor name="jsL" joint="L_hip_roll"      />
    <motor name="jhL" joint="L_hip_pitch"     />
    <motor name="jkL" joint="L_knee_pitch"    />
    <motor name="jpL" joint="L_ankle_pitch"   />

    <motor name="juR" joint="R_hip_yaw"       /> <!-- Leg Right -->
    <motor name="jsR" joint="R_hip_roll"      />
    <motor name="jhR" joint="R_hip_pitch"     />
    <motor name="jkR" joint="R_knee_pitch"    />
    <motor name="jpR" joint="R_ankle_pitch"   />
  </actuator>
</mujoco>
