<mujoco model="x2">
  <compiler angle="radian" meshdir="./meshes/"/>

  <asset>
    <mesh name="pelvis_link" file="pelvis_link.STL"/>
    <mesh name="L_hip_yaw_link" file="L_hip_yaw_link.STL"/>
    <mesh name="L_hip_roll_link" file="L_hip_roll_link.STL"/>
    <mesh name="L_hip_pitch_link" file="L_hip_pitch_link.STL"/>
    <mesh name="L_knee_pitch_link" file="L_knee_pitch_link.STL"/>
    <mesh name="L_ankle_pitch_link" file="L_ankle_pitch_link.STL"/>
    <mesh name="R_hip_yaw_link" file="R_hip_yaw_link.STL"/>
    <mesh name="R_hip_roll_link" file="R_hip_roll_link.STL"/>
    <mesh name="R_hip_pitch_link" file="R_hip_pitch_link.STL"/>
    <mesh name="R_knee_pitch_link" file="R_knee_pitch_link.STL"/>
    <mesh name="R_ankle_pitch_link" file="R_ankle_pitch_link.STL"/>
    <mesh name="waist_yaw_link" file="waist_yaw_link.STL"/>
    <mesh name="torso_link" file="torso_link.STL"/>
    <mesh name="Head_yaw_link" file="Head_yaw_link.STL"/>
    <mesh name="logo_link" file="logo_link.STL"/>
    <mesh name="L_shoulder_pitch_link" file="L_shoulder_pitch_link.STL"/>
    <mesh name="L_shoulder_roll_link" file="L_shoulder_roll_link.STL"/>
    <mesh name="L_shoulder_yaw_link" file="L_shoulder_yaw_link.STL"/>
    <mesh name="L_elbow_pitch_link" file="L_elbow_pitch_link.STL"/>
    <mesh name="L_forearm_yaw_link" file="L_forearm_yaw_link.STL"/>
    <mesh name="R_shoulder_pitch_link" file="R_shoulder_pitch_link.STL"/>
    <mesh name="R_shoulder_roll_link" file="R_shoulder_roll_link.STL"/>
    <mesh name="R_shoulder_yaw_link" file="R_shoulder_yaw_link.STL"/>
    <mesh name="R_elbow_pitch_link" file="R_elbow_pitch_link.STL"/>
    <mesh name="R_forearm_yaw_link" file="R_forearm_yaw_link.STL"/>
    <mesh name="L_base_link" file="L_base_link.STL"/>
    <mesh name="L_thumb_prox" file="L_thumb_prox.STL"/>
    <mesh name="L_thumb_dist" file="L_thumb_dist.STL"/>
    <mesh name="L_Index_prox" file="L_Index_prox.STL"/>
    <mesh name="L_index_dist" file="L_index_dist.STL"/>
    <mesh name="L_middle_prox" file="L_middle_prox.STL"/>
    <mesh name="L_middle_dist" file="L_middle_dist.STL"/>
    <mesh name="L_ring_prox" file="L_ring_prox.STL"/>
    <mesh name="L_ring_dist" file="L_ring_dist.STL"/>
    <mesh name="L_little_prox" file="L_little_prox.STL"/>
    <mesh name="L_little_dist" file="L_little_dist.STL"/>
    <mesh name="R_base_link" file="R_base_link.STL"/>
    <mesh name="R_thumb_prox" file="R_thumb_prox.STL"/>
    <mesh name="R_thumb_dist" file="R_thumb_dist.STL"/>
    <mesh name="R_index_prox" file="R_index_prox.STL"/>
    <mesh name="R_index_dist" file="R_index_dist.STL"/>
    <mesh name="R_middle_prox" file="R_middle_prox.STL"/>
    <mesh name="R_middle_dist" file="R_middle_dist.STL"/>
    <mesh name="R_ring_prox" file="R_ring_prox.STL"/>
    <mesh name="R_ring_dist" file="R_ring_dist.STL"/>
    <mesh name="R_little_prox" file="R_little_prox.STL"/>
    <mesh name="R_little_dist" file="R_little_dist.STL"/>
  </asset>

  <worldbody>
    <body name="pelvis_link" pos="0 0 0.91">
      <inertial pos="-0.00261991 1.21252e-07 0.320071" quat="0.999859 -1.79228e-08 0.0168126 -1.06588e-06" mass="11.9382" diaginertia="0.530594 0.503381 0.163908"/>
      <joint name="pelvis_link" type="free" limited="false" actuatorfrclimited="false"/>
      <geom type="mesh" contype="0" conaffinity="0" group="1" density="0" rgba="1 1 1 1" mesh="pelvis_link"/>
      <geom pos="0 0 0.08375" type="mesh" contype="0" conaffinity="0" group="1" density="0" rgba="1 1 1 1" mesh="waist_yaw_link"/>
      <geom pos="0 0 0.1205" quat="1 0 0 0" type="mesh" contype="0" conaffinity="0" group="1" density="0" rgba="0.823529 0.823529 0.823529 1" mesh="torso_link"/>
      <geom pos="0 0 0.485" quat="1 0 0 0" type="mesh" contype="0" conaffinity="0" group="1" density="0" rgba="1 1 1 1" mesh="Head_yaw_link"/>
      <geom pos="0 0 0.1205" quat="1 0 0 0" type="mesh" contype="0" conaffinity="0" group="1" density="0" rgba="1 0 0 1" mesh="logo_link"/>
      <body name="L_hip_yaw_link">
        <inertial pos="-0.0005618 0.019831 0.00885104" quat="0.416547 0.491409 -0.566922 0.513426" mass="0.841" diaginertia="0.00175713 0.00175343 0.000573392"/>
        <joint name="L_hip_yaw" pos="0 0 0" axis="0 0 1" range="-0.7854 0.7854" actuatorfrcrange="-30 30"/>
        <geom type="mesh" contype="0" conaffinity="0" group="1" density="0" rgba="1 1 1 1" mesh="L_hip_yaw_link"/>
        <body name="L_hip_roll_link" pos="-0.0095 0.1 0">
          <inertial pos="-0.0324725 0.00017925 -0.0726484" quat="0.655395 -0.252501 -0.247695 0.667344" mass="2.667" diaginertia="0.0108627 0.0094793 0.00603247"/>
          <joint name="L_hip_roll" pos="0 0 0" axis="1 0 0" range="-0.349 0.524" actuatorfrcrange="-45 45"/>
          <geom type="mesh" contype="0" conaffinity="0" group="1" density="0" rgba="1 1 1 1" mesh="L_hip_roll_link"/>
          <body name="L_hip_pitch_link" pos="0.0085 -0.001 -0.11">
            <inertial pos="0.00382921 0 -0.185484" quat="0.706562 0.0278169 0.0278188 0.706557" mass="1.664" diaginertia="0.0148443 0.0145077 0.0030868"/>
            <joint name="L_hip_pitch" pos="0 0 0" axis="0 -1 0" range="-0.526 2.4434" actuatorfrcrange="-45 45"/>
            <geom type="mesh" contype="0" conaffinity="0" group="1" density="0" rgba="1 1 1 1" mesh="L_hip_pitch_link"/>
            <body name="L_knee_pitch_link" pos="0 0 -0.35">
              <inertial pos="0.00140265 0 -0.15876" quat="0.706958 -0.0143173 -0.0143148 0.706965" mass="1.125" diaginertia="0.00999859 0.00987345 0.00100926"/>
              <joint name="L_knee_pitch" pos="0 0 0" axis="0 -1 0" range="-2.3561 0" actuatorfrcrange="-60 60"/>
              <geom type="mesh" contype="0" conaffinity="0" group="1" density="0" rgba="1 1 1 1" mesh="L_knee_pitch_link"/>
              <body name="L_ankle_pitch_link" pos="0 0 -0.35">
                <inertial pos="0.0393988 -0.000237278 -0.0784143" quat="0.000325049 0.702196 0.00149391 0.711983" mass="0.556154" diaginertia="0.00260529 0.00243297 0.000325398"/>
                <joint name="L_ankle_pitch" pos="0 0 0" axis="0 -1 0" range="-0.6 0.6" actuatorfrcrange="-30 30"/>
                <geom type="mesh" contype="0" conaffinity="0" group="1" density="0" rgba="1 1 1 1" mesh="L_ankle_pitch_link"/>
                <geom type="mesh" rgba="1 1 1 1" mesh="L_ankle_pitch_link"/>
              </body>
            </body>
          </body>
        </body>
      </body>
      <body name="R_hip_yaw_link">
        <inertial pos="-0.00116447 -0.0404495 0" quat="0.707002 0.707002 -0.0121739 -0.0121739" mass="0.219202" diaginertia="0.000598763 0.000555362 0.000156982"/>
        <joint name="R_hip_yaw" pos="0 0 0" axis="0 0 -1" range="-0.7854 0.7854" actuatorfrcrange="-30 30"/>
        <geom type="mesh" contype="0" conaffinity="0" group="1" density="0" rgba="1 1 1 1" mesh="R_hip_yaw_link"/>
        <body name="R_hip_roll_link" pos="-0.0095 -0.1 0">
          <inertial pos="-0.0324725 0.00017925 -0.0726484" quat="0.655395 -0.252501 -0.247695 0.667344" mass="2.667" diaginertia="0.0108627 0.0094793 0.00603247"/>
          <joint name="R_hip_roll" pos="0 0 0" axis="-1 0 0" range="-0.349 0.524" actuatorfrcrange="-45 45"/>
          <geom type="mesh" contype="0" conaffinity="0" group="1" density="0" rgba="1 1 1 1" mesh="R_hip_roll_link"/>
          <body name="R_hip_pitch_link" pos="0.0085 -0.001 -0.11">
            <inertial pos="0.00382921 0 -0.185485" quat="0.706557 0.0278188 0.0278169 0.706562" mass="1.664" diaginertia="0.0148443 0.0145077 0.0030868"/>
            <joint name="R_hip_pitch" pos="0 0 0" axis="0 -1 0" range="-0.526 2.4434" actuatorfrcrange="-45 45"/>
            <geom type="mesh" contype="0" conaffinity="0" group="1" density="0" rgba="1 1 1 1" mesh="R_hip_pitch_link"/>
            <body name="R_knee_pitch_link" pos="0 0 -0.35">
              <inertial pos="0.00140265 0 -0.15876" quat="0.706965 -0.0143148 -0.0143173 0.706958" mass="1.125" diaginertia="0.00999859 0.00987345 0.00100926"/>
              <joint name="R_knee_pitch" pos="0 0 0" axis="0 -1 0" range="-2.3561 0" actuatorfrcrange="-60 60"/>
              <geom type="mesh" contype="0" conaffinity="0" group="1" density="0" rgba="1 1 1 1" mesh="R_knee_pitch_link"/>
              <body name="R_ankle_pitch_link" pos="0 0 -0.35">
                <inertial pos="0.0393998 0.00023708 -0.0784145" quat="-0.000325049 0.702196 -0.00149391 0.711983" mass="0.556161" diaginertia="0.00260529 0.00243297 0.000325398"/>
                <joint name="R_ankle_pitch" pos="0 0 0" axis="0 -1 0" range="-0.6 0.6" actuatorfrcrange="-30 30"/>
                <geom type="mesh" contype="0" conaffinity="0" group="1" density="0" rgba="1 1 1 1" mesh="R_ankle_pitch_link"/>
                <geom type="mesh" rgba="1 1 1 1" mesh="R_ankle_pitch_link"/>
              </body>
            </body>
          </body>
        </body>
      </body>
      <body name="L_shoulder_pitch_link" pos="0 0.14043 0.41173" quat="0.499998 -0.500002 0.5 0.5">
        <inertial pos="4.4218e-09 -4.5215e-08 0.02287" quat="0.707107 0.707106 -1.10054e-06 -1.10055e-06" mass="0.763" diaginertia="5.177e-05 3.6513e-05 2.7775e-05"/>
        <joint name="L_shoulder_pitch" pos="0 0 0" axis="0 0 -1" range="-1.5707 3.1416" actuatorfrcrange="-50 50"/>
        <geom type="mesh" contype="0" conaffinity="0" group="1" density="0" rgba="1 1 1 1" mesh="L_shoulder_pitch_link"/>
        <body name="L_shoulder_roll_link" pos="0 0 0.0575" quat="0.707105 -0.707108 0 0">
          <inertial pos="0.03472 -0.00020364 -3.868e-09" quat="0.00242789 0.707103 -0.00242789 0.707103" mass="0.725" diaginertia="0.00084896 0.000839629 0.000223601"/>
          <joint name="L_shoulder_roll" pos="0 0 0" axis="0 0 -1" range="0 1.5707" actuatorfrcrange="-50 50"/>
          <geom type="mesh" contype="0" conaffinity="0" group="1" density="0" rgba="1 1 1 1" mesh="L_shoulder_roll_link"/>
          <body name="L_shoulder_yaw_link" pos="0.112 0 0" quat="0.499998 0.5 0.500002 0.5">
            <inertial pos="1.0693e-08 0.00040667 0.084068" quat="0.706773 0.0217385 -0.0217385 0.706773" mass="0.513" diaginertia="0.0012506 0.0012458 0.000218964"/>
            <joint name="L_shoulder_yaw" pos="0 0 0" axis="0 0 -1" range="-2.2689 2.2689" actuatorfrcrange="-50 50"/>
            <geom type="mesh" contype="0" conaffinity="0" group="1" density="0" rgba="1 1 1 1" mesh="L_shoulder_yaw_link"/>
            <body name="L_elbow_pitch_link" pos="0 -0.01 0.148" quat="-3.89602e-06 0.707107 1.29867e-06 0.707107">
              <inertial pos="0.056038 -0.011478 2.3322e-08" quat="0.487993 0.487986 0.511731 0.511726" mass="0.385" diaginertia="0.000273472 0.00024995 9.52465e-05"/>
              <joint name="L_elbow_pitch" pos="0 0 0" axis="0 0 1" range="0 2.5307" actuatorfrcrange="-50 50"/>
              <geom type="mesh" contype="0" conaffinity="0" group="1" density="0" rgba="1 1 1 1" mesh="L_elbow_pitch_link"/>
              <body name="L_forearm_yaw_link" pos="0.1085 -0.01 0" quat="-3.89602e-06 0.707107 1.29867e-06 0.707107">
                <inertial pos="0.00554114 -0.00294213 0.16308" quat="0.975155 0.00879109 -0.0285999 0.219495" mass="1.848" diaginertia="0.00235394 0.00210062 0.000468885"/>
                <joint name="L_forearm_yaw" pos="0 0 0" axis="0 0 -1" range="-2.2689 2.2689" actuatorfrcrange="-50 50"/>
                <geom type="mesh" contype="0" conaffinity="0" group="1" density="0" rgba="1 1 1 1" mesh="L_forearm_yaw_link"/>
                <geom pos="0 0 0.15" quat="0.499998 0.5 0.500002 0.5" type="mesh" contype="0" conaffinity="0" group="1" density="0" rgba="0.75294 0.75294 0.75294 1" mesh="L_base_link"/>
                <geom pos="0.0232632 -0.0244999 0.172632" quat="0.678956 0.691082 0.197532 0.149686" type="mesh" contype="0" conaffinity="0" group="1" density="0" rgba="0.75294 0.75294 0.75294 1" mesh="L_thumb_prox"/>
                <geom pos="0.0297472 -0.0364996 0.172178" quat="0.341814 0.939119 0.0119378 -0.0327968" type="mesh" contype="0" conaffinity="0" group="1" density="0" rgba="0.75294 0.75294 0.75294 1" mesh="L_thumb_dist"/>
                <geom pos="0.00221593 -0.029003 0.238291" quat="0.4854 0.488075 0.496161 0.529145" type="mesh" contype="0" conaffinity="0" group="1" density="0" rgba="0.75294 0.75294 0.75294 1" mesh="L_Index_prox"/>
                <geom pos="0.0011881 -0.0302778 0.273253" quat="0.435974 0.532688 0.544962 0.478734" type="mesh" contype="0" conaffinity="0" group="1" density="0" rgba="0.75294 0.75294 0.75294 1" mesh="L_index_dist"/>
                <geom pos="-0.00177033 -0.00800001 0.242284" quat="0.499998 0.5 0.500002 0.5" type="mesh" contype="0" conaffinity="0" group="1" density="0" rgba="0.75294 0.75294 0.75294 1" mesh="L_middle_prox"/>
                <geom pos="-0.00177018 -0.00800001 0.284284" quat="0.452065 0.543723 0.543725 0.452067" type="mesh" contype="0" conaffinity="0" group="1" density="0" rgba="0.75294 0.75294 0.75294 1" mesh="L_middle_dist"/>
                <geom pos="-0.00178422 0.013103 0.240291" quat="0.524111 0.501472 0.492949 0.480453" type="mesh" contype="0" conaffinity="0" group="1" density="0" rgba="0.75294 0.75294 0.75294 1" mesh="L_ring_prox"/>
                <geom pos="-0.0021715 0.014589 0.282263" quat="0.480778 0.543156 0.531047 0.437976" type="mesh" contype="0" conaffinity="0" group="1" density="0" rgba="0.75294 0.75294 0.75294 1" mesh="L_ring_dist"/>
                <geom pos="0.00221568 0.033731 0.233777" quat="0.536623 0.488059 0.497547 0.47569" type="mesh" contype="0" conaffinity="0" group="1" density="0" rgba="1 1 1 1" mesh="L_little_prox"/>
                <geom pos="0.00134527 0.0362172 0.268678" quat="0.484425 0.539906 0.543173 0.422844" type="mesh" contype="0" conaffinity="0" group="1" density="0" rgba="0.75294 0.75294 0.75294 1" mesh="L_little_dist"/>
              </body>
            </body>
          </body>
        </body>
      </body>
      <body name="R_shoulder_pitch_link" pos="0 -0.14043 0.41173" quat="0.499998 0.500002 0.5 -0.5">
        <inertial pos="4.4218e-09 -4.5215e-08 0.02287" quat="0.707107 0.707106 -1.10054e-06 -1.10055e-06" mass="0.763" diaginertia="5.177e-05 3.6513e-05 2.7775e-05"/>
        <joint name="R_shoulder_pitch" pos="0 0 0" axis="0 0 1" range="-1.5707 3.1416" actuatorfrcrange="-50 50"/>
        <geom type="mesh" contype="0" conaffinity="0" group="1" density="0" rgba="1 1 1 1" mesh="R_shoulder_pitch_link"/>
        <body name="R_shoulder_roll_link" pos="0 0 0.0575" quat="0.707105 -0.707108 0 0">
          <inertial pos="0.03472 -0.00020364 -3.8447e-09" quat="0.00242789 0.707103 -0.00242789 0.707103" mass="0.725" diaginertia="0.00084896 0.000839629 0.000223601"/>
          <joint name="R_shoulder_roll" pos="0 0 0" axis="0 0 -1" range="0 1.5707" actuatorfrcrange="-50 50"/>
          <geom type="mesh" contype="0" conaffinity="0" group="1" density="0" rgba="1 1 1 1" mesh="R_shoulder_roll_link"/>
          <body name="R_shoulder_yaw_link" pos="0.112 0 0" quat="0.499998 0.5 0.500002 0.5">
            <inertial pos="-1.0693e-08 -0.00040667 0.084068" quat="0.706773 -0.0217385 0.0217385 0.706773" mass="0.513" diaginertia="0.0012506 0.0012458 0.000218964"/>
            <joint name="R_shoulder_yaw" pos="0 0 0" axis="0 0 1" range="-2.2689 2.2689" actuatorfrcrange="-50 50"/>
            <geom type="mesh" contype="0" conaffinity="0" group="1" density="0" rgba="1 1 1 1" mesh="R_shoulder_yaw_link"/>
            <body name="R_elbow_pitch_link" pos="0 0.01 0.148" quat="-3.89602e-06 0.707107 1.29867e-06 0.707107">
              <inertial pos="0.056038 0.011478 -2.3316e-08" quat="0.511731 0.511726 0.487993 0.487986" mass="0.385" diaginertia="0.000273472 0.00024995 9.52465e-05"/>
              <joint name="R_elbow_pitch" pos="0 0 0" axis="0 0 -1" range="0 2.5307" actuatorfrcrange="-50 50"/>
              <geom type="mesh" contype="0" conaffinity="0" group="1" density="0" rgba="1 1 1 1" mesh="R_elbow_pitch_link"/>
              <body name="R_forearm_yaw_link" pos="0.1085 0.01 0" quat="-3.89602e-06 0.707107 1.29867e-06 0.707107">
                <inertial pos="0.00491094 0.00261627 0.163001" quat="0.986641 0.0011675 -0.053269 -0.153949" mass="1.848" diaginertia="0.00237351 0.00209087 0.000468981"/>
                <joint name="R_forearm_yaw" pos="0 0 0" axis="0 0 1" range="-2.2689 2.2689" actuatorfrcrange="-50 50"/>
                <geom type="mesh" contype="0" conaffinity="0" group="1" density="0" rgba="1 1 1 1" mesh="R_forearm_yaw_link"/>
                <geom pos="0 0 0.15" quat="0.499998 0.5 0.500002 0.5" type="mesh" contype="0" conaffinity="0" group="1" density="0" rgba="0.75294 0.75294 0.75294 1" mesh="R_base_link"/>
                <geom pos="0.021628 0.0245001 0.1742" quat="0.60751 0.607511 0.361844 0.361842" type="mesh" contype="0" conaffinity="0" group="1" density="0" rgba="1 1 1 1" mesh="R_thumb_prox"/>
                <geom pos="0.0281278 0.0364998 0.1742" quat="0.664459 0.241843 0.664466 0.241848" type="mesh" contype="0" conaffinity="0" group="1" density="0" rgba="0.75294 0.75294 0.75294 1" mesh="R_thumb_dist"/>
                <geom pos="-0.00394858 0.029003 0.238231" quat="0.545854 0.478916 0.469313 0.502422" type="mesh" contype="0" conaffinity="0" group="1" density="0" rgba="0.75294 0.75294 0.75294 1" mesh="R_index_prox"/>
                <geom pos="-0.00741272 0.0302778 0.273036" quat="0.497031 0.529413 0.515658 0.454729" type="mesh" contype="0" conaffinity="0" group="1" density="0" rgba="0.75294 0.75294 0.75294 1" mesh="R_index_dist"/>
                <geom pos="-0.00820349 0.00799997 0.241935" quat="0.517143 0.482246 0.482248 0.517145" type="mesh" contype="0" conaffinity="0" group="1" density="0" rgba="0.75294 0.75294 0.75294 1" mesh="R_middle_prox"/>
                <geom pos="-0.0111331 0.00799996 0.283833" quat="0.470766 0.527615 0.527617 0.470767" type="mesh" contype="0" conaffinity="0" group="1" density="0" rgba="0.75294 0.75294 0.75294 1" mesh="R_middle_dist"/>
                <geom pos="-0.00807822 -0.013103 0.239947" quat="0.49766 0.474356 0.484401 0.540997" type="mesh" contype="0" conaffinity="0" group="1" density="0" rgba="0.75294 0.75294 0.75294 1" mesh="R_ring_prox"/>
                <geom pos="-0.0113924 -0.0145891 0.28179" quat="0.456664 0.513942 0.527542 0.49902" type="mesh" contype="0" conaffinity="0" group="1" density="0" rgba="0.75294 0.75294 0.75294 1" mesh="R_ring_dist"/>
                <geom pos="-0.00363347 -0.033731 0.233727" quat="0.492431 0.478514 0.471162 0.553663" type="mesh" contype="0" conaffinity="0" group="1" density="0" rgba="0.75294 0.75294 0.75294 1" mesh="R_little_prox"/>
                <geom pos="-0.0069363 -0.0362173 0.268482" quat="0.441427 0.525934 0.524822 0.503088" type="mesh" contype="0" conaffinity="0" group="1" density="0" rgba="0.75294 0.75294 0.75294 1" mesh="R_little_dist"/>
              </body>
            </body>
          </body>
        </body>
      </body>
    </body>
  </worldbody>
  <actuator>
    <motor name="L_hip_yaw"        joint="L_hip_yaw"/>        <!-- Leg Left -->
    <motor name="L_hip_roll"       joint="L_hip_roll"/>
    <motor name="L_hip_pitch"      joint="L_hip_pitch"/>
    <motor name="L_knee_pitch"     joint="L_knee_pitch"/>
    <motor name="L_ankle_pitch"    joint="L_ankle_pitch"/>

    <motor name="R_hip_yaw"        joint="R_hip_yaw"/>        <!-- Leg Right -->
    <motor name="R_hip_roll"       joint="R_hip_roll"/>
    <motor name="R_hip_pitch"      joint="R_hip_pitch"/>
    <motor name="R_knee_pitch"     joint="R_knee_pitch"/>
    <motor name="R_ankle_pitch"    joint="R_ankle_pitch"/>

    <motor name="L_shoulder_pitch" joint="L_shoulder_pitch"/> <!-- Arm Left -->
    <motor name="L_shoulder_roll"  joint="L_shoulder_roll"/>
    <motor name="L_shoulder_yaw"   joint="L_shoulder_yaw"/>
    <motor name="L_elbow_pitch"    joint="L_elbow_pitch"/>
    <motor name="L_forearm_yaw"    joint="L_forearm_yaw"/>

    <motor name="R_shoulder_pitch" joint="R_shoulder_pitch"/> <!-- Arm Right -->
    <motor name="R_shoulder_roll"  joint="R_shoulder_roll"/>
    <motor name="R_shoulder_yaw"   joint="R_shoulder_yaw"/>
    <motor name="R_elbow_pitch"    joint="R_elbow_pitch"/>
    <motor name="R_forearm_yaw"    joint="R_forearm_yaw"/>
  </actuator>
</mujoco>
