<?xml version="1.0" encoding="utf-8"?>
<!-- This URDF was automatically created by SolidWorks to URDF Exporter! Originally created by Stephen Brawner (brawner@gmail.com) 
     Commit Version: 1.6.0-4-g7f85cfe  Build Version: 1.6.7995.38578
     For more information, please see http://wiki.ros.org/sw_urdf_exporter -->
<robot name="X02C_PRO">

  <mujoco>
    <compiler meshdir="./meshes" discardvisual="false" />
  </mujoco>

  <link name="world"></link>
  <joint name="pelvis_link" type="floating">
    <parent link="world" />
    <child link="pelvis_link" />
  </joint>

  <link name="pelvis_link">
    <inertial>
      <origin xyz="0 0 -0.0825" rpy="0 0 0" />
      <mass value="0.1" />
      <inertia ixx="0.00000995" ixy="0.00000000" ixz="0.00000000" iyy="0.00000995" iyz="0.00000000" izz="0.00000499" />
    </inertial>
    <visual>
      <origin xyz="0 0 0" rpy="0 0 0" />
      <geometry>
        <mesh filename="meshes/pelvis_link.STL" />
      </geometry>
      <material name="">
        <color rgba="1 1 1 1" />
      </material>
    </visual>
    <collision>
      <origin xyz="0 0 0" rpy="0 0 0" />
      <geometry>
        <mesh filename="meshes/pelvis_link.STL" />
      </geometry>
    </collision>
  </link>
  <link name="L_hip_yaw_link">
    <inertial>
      <origin xyz="7.60798799644618E-09 0.0271793203085457 0.00194453608690955" rpy="0 0 0" />
      <mass value="0.841" />
      <inertia ixx="0.00107031872068775" ixy="-2.52499195496695E-11" ixz="-1.50338303610374E-10" iyy="0.000288945732309292" iyz="-3.16539158137212E-05" izz="0.00108612875139249" />
    </inertial>
    <visual>
      <origin xyz="0 0 0" rpy="0 0 0" />
      <geometry>
        <mesh filename="meshes/L_hip_yaw_link.STL" />
      </geometry>
      <material name="">
        <color rgba="0.419607843137255 0.419607843137255 0.419607843137255 1" />
      </material>
    </visual>
<!--    <collision>-->
<!--      <origin xyz="0 0 0" rpy="0 0 0" />-->
<!--      <geometry>-->
<!--        <mesh filename="meshes/L_hip_yaw_link.STL" />-->
<!--      </geometry>-->
<!--    </collision>-->
  </link>
  <joint name="L_hip_yaw" type="revolute">
    <origin xyz="0 0 -0.1315" rpy="0 0 0" />
    <parent link="pelvis_link" />
    <child link="L_hip_yaw_link" />
    <axis xyz="0 0 1" />
    <limit lower="-0.785" upper="0.785" effort="50" velocity="51" />
  </joint>
  <link name="L_hip_roll_link">
    <inertial>
      <origin xyz="-0.0345843978167926 0.00017701693435701 -0.0717644851459002" rpy="0 0 0" />
      <mass value="2.667" />
      <inertia ixx="0.00779234409183086" ixy="-1.2981743980075E-05" ixz="0.00131344546936689" iyy="0.00895747549556099" iyz="-2.75139716717283E-05" izz="0.00580982154567831" />
    </inertial>
    <visual>
      <origin xyz="0 0 0" rpy="0 0 0" />
      <geometry>
        <mesh filename="meshes/L_hip_roll_link.STL" />
      </geometry>
      <material name="">
        <color rgba="0.419607843137255 0.419607843137255 0.419607843137255 1" />
      </material>
    </visual>
    <collision>
      <origin xyz="0 0 0" rpy="0 0 0" />
      <geometry>
        <mesh filename="meshes/L_hip_roll_link.STL" />
      </geometry>
    </collision>
  </link>
  <joint name="L_hip_roll" type="revolute">
    <origin xyz="0 0.12 -0.001" rpy="0 0 0" />
    <parent link="L_hip_yaw_link" />
    <child link="L_hip_roll_link" />
    <axis xyz="1 0 0" />
    <limit lower="-0.349" upper="0.534" effort="100" velocity="31" />
  </joint>
  <link name="L_hip_pitch_link">
    <inertial>
      <origin xyz="0.00822869 0 -0.16703084" rpy="0 0 0" />
      <mass value="1.8" />
      <inertia ixx="0.01698928" ixy="0.00000000" ixz="-0.00060774" iyy="0.01770562" iyz="-0.00000002" izz="0.00318692" />
    </inertial>
    <visual>
      <origin xyz="0 0 0" rpy="0 0 0" />
      <geometry>
        <mesh filename="meshes/L_hip_pitch_link.STL" />
      </geometry>
      <material name="">
        <color rgba="1.92 1.768 2.03 1" />
      </material>
    </visual>
    <collision>
      <origin xyz="0 0 0" rpy="0 0 0" />
      <geometry>
        <mesh filename="meshes/L_hip_pitch_link.STL" />
      </geometry>
    </collision>
  </link>
  <joint name="L_hip_pitch" type="revolute">
    <origin xyz="0 0 -0.11" rpy="0 0 0" />
    <parent link="L_hip_roll_link" />
    <child link="L_hip_pitch_link" />
    <axis xyz="0 -1 0" />
    <limit lower="-0.534" upper="2.094" effort="212" velocity="58.7" />
  </joint>
  <link name="L_knee_pitch_link">
    <inertial>
      <origin xyz="0.00111166 0 -0.14609747" rpy="0 0 0" />
      <mass value="1.125" />
      <inertia ixx="0.01158049" ixy="0.00000000" ixz="0.00032335" iyy="0.01172026" iyz="-0.00000001" izz="0.00121827" />
    </inertial>
    <visual>
      <origin xyz="0 0 0" rpy="0 0 0" />
      <geometry>
        <mesh filename="meshes/L_knee_pitch_link.STL" />
      </geometry>
      <material name="">
        <color rgba="1.92 1.768 2.03 1" />
      </material>
    </visual>
    <collision>
      <origin xyz="0 0 0" rpy="0 0 0" />
      <geometry>
        <mesh filename="meshes/L_knee_pitch_link.STL" />
      </geometry>
    </collision>
  </link>
  <joint name="L_knee_pitch" type="revolute">
    <origin xyz="0 0 -0.35" rpy="0 0 0" />
    <parent link="L_hip_pitch_link" />
    <child link="L_knee_pitch_link" />
    <axis xyz="0 -1 0" />
    <limit lower="-2.269" upper="0" effort="93" velocity="150" />
  </joint>
  <link name="L_ankle_pitch_link">
    <inertial>
      <origin xyz="0.002947529005065 -1.35445721857613E-05 -0.0240696249769604" rpy="0 0 0" />
      <mass value="0.3" />
      <inertia ixx="2.52265831562822E-05" ixy="1.13974328467384E-08" ixz="4.05976155526405E-06" iyy="4.97296355088603E-05" iyz="-1.90302704663154E-08" izz="3.33254911154604E-05" />
    </inertial>
    <visual>
      <origin xyz="0 0 0" rpy="0 0 0" />
      <geometry>
        <mesh filename="meshes/L_ankle_pitch_link.STL" />
      </geometry>
      <material name="">
        <color rgba="0.419607843137255 0.419607843137255 0.419607843137255 1" />
      </material>
    </visual>
    <collision>
      <origin xyz="0 0 0" rpy="0 0 0" />
      <geometry>
        <mesh filename="meshes/L_ankle_pitch_link.STL" />
      </geometry>
    </collision>
  </link>
  <joint name="L_ankle_pitch" type="revolute">
    <origin xyz="0 0 -0.35" rpy="0 0 0" />
    <parent link="L_knee_pitch_link" />
    <child link="L_ankle_pitch_link" />
    <axis xyz="0 -1 0" />
    <limit lower="-1.047" upper="1.047" effort="64.8" velocity="216.66" />
  </joint>
  <link name="L_ankle_roll_link">
    <inertial>
      <origin xyz="0.0511098207690309 2.27969964033264E-05 -0.029278150161492" rpy="0 0 0" />
      <mass value="0.6" />
      <inertia ixx="0.000357089092153518" ixy="-1.47307290241483E-08" ixz="2.90073852989151E-07" iyy="0.0032819389901749" iyz="-2.24180302072437E-07" izz="0.00355222542672962" />
    </inertial>
    <visual>
      <origin xyz="0 0 0" rpy="0 0 0" />
      <geometry>
        <mesh filename="meshes/L_ankle_roll_link.STL" />
      </geometry>
      <material name="">
        <color rgba="1.912 1.904 1.92 1" />
      </material>
    </visual>
<!--    <collision>-->
<!--      <origin xyz="0 0 0" rpy="0 0 0" />-->
<!--      <geometry>-->
<!--        <mesh filename="meshes/L_ankle_roll_link.STL" />-->
<!--      </geometry>-->
<!--    </collision>-->
    <collision>
      <origin xyz="-0.093 -0.0 -0.0415" rpy="0 0 0"/>
      <geometry>
        <sphere radius="0.005"/>
      </geometry>
    </collision>
    <collision>
      <origin xyz="0.18 0.0 -0.0415" rpy="0 0 0"/>
      <geometry>
        <sphere radius="0.005"/>
      </geometry>
    </collision>
    <collision>
      <origin xyz="0.095 -0.045 -0.0415" rpy="0 0 0"/>
      <geometry>
        <sphere radius="0.005"/>
      </geometry>
    </collision>
    <collision>
      <origin xyz="0.095 0.045 -0.0415" rpy="0 0 0"/>
      <geometry>
        <sphere radius="0.005"/>
      </geometry>
    </collision>
    <collision>
      <origin xyz="0.0 0.033 -0.0415" rpy="0 0 0"/>
      <geometry>
        <sphere radius="0.005"/>
      </geometry>
    </collision>
    <collision>
      <origin xyz="0.0 -0.033 -0.0415" rpy="0 0 0"/>
      <geometry>
        <sphere radius="0.005"/>
      </geometry>
    </collision>
  </link>
  <joint name="L_ankle_roll" type="revolute">
    <origin xyz="0 0 -0.058" rpy="0 0 0" />
    <parent link="L_ankle_pitch_link" />
    <child link="L_ankle_roll_link" />
    <axis xyz="1 0 0" />
    <limit lower="-0.534" upper="0.534" effort="20" velocity="150" />
  </joint>
  <link name="R_hip_yaw_link">
    <inertial>
      <origin xyz="-5.27551142154076E-09 -0.0504943859960314 0.0061080371632482" rpy="0 0 0" />
      <mass value="0.947" />
      <inertia ixx="0.000695242190542347" ixy="4.49155803872037E-11" ixz="1.47031067951023E-10" iyy="0.000199321074961206" iyz="-1.83516270583489E-05" izz="0.000602481821628707" />
    </inertial>
    <visual>
      <origin xyz="0 0 0" rpy="0 0 0" />
      <geometry>
        <mesh filename="meshes/R_hip_yaw_link.STL" />
      </geometry>
      <material name="">
        <color rgba="0.419607843137255 0.419607843137255 0.419607843137255 1" />
      </material>
    </visual>
<!--    <collision>-->
<!--      <origin xyz="0 0 0" rpy="0 0 0" />-->
<!--      <geometry>-->
<!--        <mesh filename="meshes/R_hip_yaw_link.STL" />-->
<!--      </geometry>-->
<!--    </collision>-->
  </link>
  <joint name="R_hip_yaw" type="revolute">
    <origin xyz="0 0 -0.1315" rpy="0 0 0" />
    <parent link="pelvis_link" />
    <child link="R_hip_yaw_link" />
    <axis xyz="0 0 -1" />
    <limit lower="-0.785" upper="0.785" effort="50" velocity="51" />
  </joint>
  <link name="R_hip_roll_link">
    <inertial>
      <origin xyz="-0.0345843143439835 -0.000177505716098009 -0.0717628990581374" rpy="0 0 0" />
      <mass value="2.667" />
      <inertia ixx="0.00779264216018636" ixy="1.29591042959458E-05" ixz="0.0013134506318962" iyy="0.0089577897233922" iyz="2.74658078135865E-05" izz="0.00580982688006484" />
    </inertial>
    <visual>
      <origin xyz="0 0 0" rpy="0 0 0" />
      <geometry>
        <mesh filename="meshes/R_hip_roll_link.STL" />
      </geometry>
      <material name="">
        <color rgba="0.419607843137255 0.419607843137255 0.419607843137255 1" />
      </material>
    </visual>
    <collision>
      <origin xyz="0 0 0" rpy="0 0 0" />
      <geometry>
        <mesh filename="meshes/R_hip_roll_link.STL" />
      </geometry>
    </collision>
  </link>
  <joint name="R_hip_roll" type="revolute">
    <origin xyz="0 -0.12 -0.001" rpy="0 0 0" />
    <parent link="R_hip_yaw_link" />
    <child link="R_hip_roll_link" />
    <axis xyz="-1 0 0" />
    <limit lower="-0.349" upper="0.534" effort="100" velocity="31" />
  </joint>
  <link name="R_hip_pitch_link">
    <inertial>
      <origin xyz="0.00822868 0 -0.16703110" rpy="0 0 0" />
      <mass value="1.8" />
      <inertia ixx="0.01698931" ixy="0.00000000" ixz="-0.00060774" iyy="0.01770564" iyz="-0.00000004" izz="0.00318691" />
    </inertial>
    <visual>
      <origin xyz="0 0 0" rpy="0 0 0" />
      <geometry>
        <mesh filename="meshes/R_hip_pitch_link.STL" />
      </geometry>
      <material name="">
        <color rgba="1.92 1.768 2.03 1" />
      </material>
    </visual>
    <collision>
      <origin xyz="0 0 0" rpy="0 0 0" />
      <geometry>
        <mesh filename="meshes/R_hip_pitch_link.STL" />
      </geometry>
    </collision>
  </link>
  <joint name="R_hip_pitch" type="revolute">
    <origin xyz="0 0 -0.11" rpy="0 0 0" />
    <parent link="R_hip_roll_link" />
    <child link="R_hip_pitch_link" />
    <axis xyz="0 -1 0" />
    <limit lower="-0.534" upper="2.094" effort="212" velocity="58.7" />
  </joint>
  <link name="R_knee_pitch_link">
    <inertial>
      <origin xyz="0.00111164 0 -0.14609739" rpy="0 0 0" />
      <mass value="1.125" />
      <inertia ixx="0.01158055" ixy="0.00000000" ixz="0.00032334" iyy="0.01172033" iyz="-0.00000001" izz="0.00121827" />
    </inertial>
    <visual>
      <origin xyz="0 0 0" rpy="0 0 0" />
      <geometry>
        <mesh filename="meshes/R_knee_pitch_link.STL" />
      </geometry>
      <material name="">
        <color rgba="1.92 1.768 2.03 1" />
      </material>
    </visual>
    <collision>
      <origin xyz="0 0 0" rpy="0 0 0" />
      <geometry>
        <mesh filename="meshes/R_knee_pitch_link.STL" />
      </geometry>
    </collision>
  </link>
  <joint name="R_knee_pitch" type="revolute">
    <origin xyz="0 0 -0.35" rpy="0 0 0" />
    <parent link="R_hip_pitch_link" />
    <child link="R_knee_pitch_link" />
    <axis xyz="0 -1 0" />
    <limit lower="-2.269" upper="0" effort="93" velocity="150" />
  </joint>
  <link name="R_ankle_pitch_link">
    <inertial>
      <origin xyz="0.002947529005065 -1.35445721857613E-05 -0.0240696249769604" rpy="0 0 0" />
      <mass value="0.3" />
      <inertia ixx="2.52265831562822E-05" ixy="1.13974328467384E-08" ixz="4.05976155526405E-06" iyy="4.97296355088603E-05" iyz="-1.90302704663154E-08" izz="3.33254911154604E-05" />
    </inertial>
    <visual>
      <origin xyz="0 0 0" rpy="0 0 0" />
      <geometry>
        <mesh filename="meshes/R_ankle_pitch_link.STL" />
      </geometry>
      <material name="">
        <color rgba="0.419607843137255 0.419607843137255 0.419607843137255 1" />
      </material>
    </visual>
    <collision>
      <origin xyz="0 0 0" rpy="0 0 0" />
      <geometry>
        <mesh filename="meshes/R_ankle_pitch_link.STL" />
      </geometry>
    </collision>
  </link>
  <joint name="R_ankle_pitch" type="revolute">
    <origin xyz="0 0 -0.35" rpy="0 0 0" />
    <parent link="R_knee_pitch_link" />
    <child link="R_ankle_pitch_link" />
    <axis xyz="0 -1 0" />
    <limit lower="-1.047" upper="1.047" effort="64.8" velocity="216.66" />
  </joint>
   <link name="R_ankle_roll_link">
    <inertial>
      <origin xyz="0.0511098207690309 2.27969964033264E-05 -0.029278150161492" rpy="0 0 0" />
      <mass value="0.6" />
      <inertia ixx="0.000357089092153518" ixy="-1.47307290241483E-08" ixz="2.90073852989151E-07" iyy="0.0032819389901749" iyz="-2.24180302072437E-07" izz="0.00355222542672962" />
    </inertial>
    <visual>
      <origin xyz="0 0 0" rpy="0 0 0" />
      <geometry>
        <mesh filename="meshes/R_ankle_roll_link.STL" />
      </geometry>
      <material name="">
        <color rgba="1.912 1.904 1.92 1" />
      </material>
    </visual>
<!--    <collision>-->
<!--      <origin xyz="0 0 0" rpy="0 0 0" />-->
<!--      <geometry>-->
<!--        <mesh filename="meshes/R_ankle_roll_link.STL" />-->
<!--      </geometry>-->
<!--    </collision>-->
     <collision>
      <origin xyz="-0.093 -0.0 -0.0415" rpy="0 0 0"/>
      <geometry>
        <sphere radius="0.005"/>
      </geometry>
    </collision>
    <collision>
      <origin xyz="0.18 0.0 -0.0415" rpy="0 0 0"/>
      <geometry>
        <sphere radius="0.005"/>
      </geometry>
    </collision>
    <collision>
      <origin xyz="0.095 -0.045 -0.0415" rpy="0 0 0"/>
      <geometry>
        <sphere radius="0.005"/>
      </geometry>
    </collision>
    <collision>
      <origin xyz="0.095 0.045 -0.0415" rpy="0 0 0"/>
      <geometry>
        <sphere radius="0.005"/>
      </geometry>
    </collision>
    <collision>
      <origin xyz="0.0 0.033 -0.0415" rpy="0 0 0"/>
      <geometry>
        <sphere radius="0.005"/>
      </geometry>
    </collision>
    <collision>
      <origin xyz="0.0 -0.033 -0.0415" rpy="0 0 0"/>
      <geometry>
        <sphere radius="0.005"/>
      </geometry>
    </collision>
  </link>
  <joint name="R_ankle_roll" type="revolute">
    <origin xyz="0 0 -0.058" rpy="0 0 0" />
    <parent link="R_ankle_pitch_link" />
    <child link="R_ankle_roll_link" />
    <axis xyz="-1 0 0" />
    <limit lower="-0.534" upper="0.534" effort="20" velocity="150" />
  </joint>
  <link name="waist_yaw_link">
    <inertial>
      <origin xyz="-7.27760878687527E-19 -6.91244363179086E-19 0.0844780395492087" rpy="0 0 0" />
      <mass value="0.9" />
      <inertia ixx="0.000789397817904938" ixy="2.47757137071841E-20" ixz="-4.70539675191386E-20" iyy="0.000789397817904938" iyz="-1.78208683316281E-20" izz="0.000614456207607347" />
    </inertial>
    <visual>
      <origin xyz="0 0 0" rpy="0 0 0" />
      <geometry>
        <mesh filename="meshes/waist_yaw_link.STL" />
      </geometry>
      <material name="">
        <color rgba="0.419607843137255 0.419607843137255 0.419607843137255 1" />
      </material>
    </visual>
    <collision>
      <origin xyz="0 0 0" rpy="0 0 0" />
      <geometry>
        <mesh filename="meshes/waist_yaw_link.STL" />
      </geometry>
    </collision>
  </link>
  <joint name="waist_yaw" type="fixed">
    <origin xyz="0 0 -0.1315" rpy="0 0 0" />
    <parent link="pelvis_link" />
    <child link="waist_yaw_link" />
    <axis xyz="0 0 1" />
    <limit lower="-1.047" upper="1.047" effort="50" velocity="51" />
  </joint>
  <link name="torso_link">
    <inertial>
      <origin xyz="-0.00340591 -0.00000583 0.26397135" rpy="0 0 0" />
      <mass value="11" />
      <inertia ixx="0.36783933" ixy="-0.00000182" ixz="0.00498413" iyy="0.35443672" iyz="-0.00000603" izz="0.07895943" />
    </inertial>
    <visual>
      <origin xyz="0 0 0" rpy="0 0 0" />
      <geometry>
        <mesh filename="meshes/torso_link.STL" />
      </geometry>
      <material name="">
        <color rgba="0.419607843137255 0.419607843137255 0.419607843137255 1" />
      </material>
    </visual>
    <collision>
      <origin xyz="0 0 0" rpy="0 0 0" />
      <geometry>
        <mesh filename="meshes/torso_link.STL" />
      </geometry>
    </collision>
  </link>
  <joint name="torso" type="fixed">
    <origin xyz="0 0 0.1315" rpy="0 0 0" />
    <parent link="waist_yaw_link" />
    <child link="torso_link" />
    <axis xyz="0 0 0" />
  </joint>
  <link name="L_shoulder_pitch_link">
    <inertial>
      <origin xyz="-2.80632734845493E-08 0.0291326785616021 -1.02659019285412E-07" rpy="0 0 0" />
      <mass value="1.276" />
      <inertia ixx="4.29470020278451E-05" ixy="4.34222768204146E-11" ixz="-1.34390059784514E-10" iyy="4.64958615810407E-05" iyz="-1.14430883948597E-10" izz="7.40782398851992E-05" />
    </inertial>
    <visual>
      <origin xyz="0 0 0" rpy="0 0 0" />
      <geometry>
        <mesh filename="meshes/L_shoulder_pitch_link.STL" />
      </geometry>
      <material name="">
        <color rgba="0.419607843137255 0.419607843137255 0.419607843137255 1" />
      </material>
    </visual>
    <collision>
      <origin xyz="0 0 0" rpy="0 0 0" />
      <geometry>
        <mesh filename="meshes/L_shoulder_pitch_link.STL" />
      </geometry>
    </collision>
  </link>
  <joint name="L_shoulder_pitch" type="fixed">
    <origin xyz="-0.01 0.13365 0.31135" rpy="0.17453 0.3 0" />
    <parent link="torso_link" />
    <child link="L_shoulder_pitch_link" />
    <axis xyz="0 -1 0" />
    <limit lower="-2.749" upper="2.749" effort="18" velocity="36" />
  </joint>
  <link name="L_shoulder_roll_link">
    <inertial>
      <origin xyz="0.000132649636071396 0.00797092570604596 -0.0452123729439792" rpy="0 0 0" />
      <mass value="1.126" />
      <inertia ixx="0.00147895653317204" ixy="-3.2910073590523E-07" ixz="1.87137523621959E-06" iyy="0.0014110761279569" iyz="0.00014229856792806" izz="0.000629153731234364" />
    </inertial>
    <visual>
      <origin xyz="0 0 0" rpy="0 0 0" />
      <geometry>
        <mesh filename="meshes/L_shoulder_roll_link.STL" />
      </geometry>
      <material name="">
        <color rgba="1.92 1.768 2.03 1" />
      </material>
    </visual>
    <collision>
      <origin xyz="0 0 0" rpy="0 0 0" />
      <geometry>
        <mesh filename="meshes/L_shoulder_roll_link.STL" />
      </geometry>
    </collision>
  </link>
  <joint name="L_shoulder_roll" type="fixed">
    <origin xyz="0 0.0588 0" rpy="-0.17453 0 0" />
    <parent link="L_shoulder_pitch_link" />
    <child link="L_shoulder_roll_link" />
    <axis xyz="1 0 0" />
    <limit lower="-0.2618" upper="2.653" effort="14" velocity="36" />
  </joint>
  <link name="L_shoulder_yaw_link">
    <inertial>
      <origin xyz="-0.000937011401745718 4.75487526713225E-07 -0.0773527192708968" rpy="0 0 0" />
      <mass value="0.896" />
      <inertia ixx="0.00109806029670413" ixy="-5.77566462223446E-09" ixz="-7.48731699662002E-05" iyy="0.00103821738088399" iyz="2.58264706046006E-08" izz="0.000549881092070551" />
    </inertial>
    <visual>
      <origin xyz="0 0 0" rpy="0 0 0" />
      <geometry>
        <mesh filename="meshes/L_shoulder_yaw_link.STL" />
      </geometry>
      <material name="">
        <color rgba="1.92 1.768 2.03 1" />
      </material>
    </visual>
    <collision>
      <origin xyz="0 0 0" rpy="0 0 0" />
      <geometry>
        <mesh filename="meshes/L_shoulder_yaw_link.STL" />
      </geometry>
    </collision>
  </link>
  <joint name="L_shoulder_yaw" type="fixed">
    <origin xyz="0 0.018928 -0.10734" rpy="0.17453 0 0" />
    <parent link="L_shoulder_roll_link" />
    <child link="L_shoulder_yaw_link" />
    <axis xyz="0 0 1" />
    <limit lower="-2.618" upper="2.618" effort="14" velocity="36" />
  </joint>
  <link name="L_elbow_pitch_link">
    <inertial>
      <origin xyz="-0.0109697635260577 -1.45412191596139E-06 -0.0945581243402238" rpy="0 0 0" />
      <mass value="0.576" />
      <inertia ixx="0.00184674284721301" ixy="6.72541641648033E-09" ixz="8.12637869080638E-05" iyy="0.00182412307996488" iyz="2.45378699783184E-08" izz="0.000406334367845279" />
    </inertial>
    <visual>
      <origin xyz="0 0 0" rpy="0 0 0" />
      <geometry>
        <mesh filename="meshes/L_elbow_pitch_link.STL" />
      </geometry>
      <material name="">
        <color rgba="1.92 1.768 2.03 1" />
      </material>
    </visual>
    <collision>
      <origin xyz="0 0 0" rpy="0 0 0" />
      <geometry>
        <mesh filename="meshes/L_elbow_pitch_link.STL" />
      </geometry>
    </collision>
  </link>
  <joint name="L_elbow_pitch" type="fixed">
    <origin xyz="0.01 0 -0.151" rpy="0 -1.57 0" />
    <parent link="L_shoulder_yaw_link" />
    <child link="L_elbow_pitch_link" />
    <axis xyz="0 -1 0" />
    <limit lower="0" upper="2.304" effort="14" velocity="36" />
  </joint>
  <link name="L_wrist_yaw_Link">
    <inertial>
      <origin xyz="0.0054707 0.0020666 -0.097398" rpy="0 0 0" />
      <mass value="0.692" />
      <inertia ixx="0.00070889" ixy="-3.6471E-05" ixz="4.4198E-05" iyy="0.00081301" iyz="-5.6072E-06" izz="0.00020641" />
    </inertial>
    <visual>
      <origin xyz="0 0 0" rpy="0 0 0" />
      <geometry>
        <mesh filename="meshes/L_wrist_yaw_Link.STL" />
      </geometry>
      <material name="">
        <color rgba="1.88 1.904 1.92 1" />
      </material>
    </visual>
    <collision>
      <origin xyz="0 0 0" rpy="0 0 0" />
      <geometry>
        <mesh filename="meshes/L_wrist_yaw_Link.STL" />
      </geometry>
    </collision>
  </link>
  <joint name="L_wrist_yaw" type="fixed">
    <origin xyz="-0.01 0 -0.166" rpy="0 0 0" />
    <parent link="L_elbow_pitch_link" />
    <child link="L_wrist_yaw_Link" />
    <axis xyz="0 0 1" />
    <limit lower="-2.793" upper="2.793" effort="2.2" velocity="36" />
  </joint>
  <link name="R_shoulder_pitch_link">
    <inertial>
      <origin xyz="-2.737E-07 -0.029133 -8.3115E-08" rpy="0 0 0" />
      <mass value="1.276" />
      <inertia ixx="4.2947E-05" ixy="-7.2808E-13" ixz="1.6724E-10" iyy="4.6496E-05" iyz="1.1363E-10" izz="7.4078E-05" />
    </inertial>
    <visual>
      <origin xyz="0 0 0" rpy="0 0 0" />
      <geometry>
        <mesh filename="meshes/R_shoulder_pitch_link.STL" />
      </geometry>
      <material name="">
        <color rgba="0.41961 0.41961 0.41961 1" />
      </material>
    </visual>
    <collision>
      <origin xyz="0 0 0" rpy="0 0 0" />
      <geometry>
        <mesh filename="meshes/R_shoulder_pitch_link.STL" />
      </geometry>
    </collision>
  </link>
  <joint name="R_shoulder_pitch" type="fixed">
    <origin xyz="-0.01 -0.13365 0.31135" rpy="-0.17453 0.3 0" />
    <parent link="torso_link" />
    <child link="R_shoulder_pitch_link" />
    <axis xyz="0 -1 0" />
    <limit lower="-2.749" upper="2.749" effort="18" velocity="36" />
  </joint>
  <link name="R_shoulder_roll_link">
    <inertial>
      <origin xyz="0.00013299 -0.0079731 -0.045212" rpy="0 0 0" />
      <mass value="1.126" />
      <inertia ixx="0.001479" ixy="3.3149E-07" ixz="1.8717E-06" iyy="0.0014111" iyz="-0.0001423" izz="0.00062915" />
    </inertial>
    <visual>
      <origin xyz="0 0 0" rpy="0 0 0" />
      <geometry>
        <mesh filename="meshes/R_shoulder_roll_link.STL" />
      </geometry>
      <material name="">
        <color rgba="1.92 1.768 2.03 1" />
      </material>
    </visual>
    <collision>
      <origin xyz="0 0 0" rpy="0 0 0" />
      <geometry>
        <mesh filename="meshes/R_shoulder_roll_link.STL" />
      </geometry>
    </collision>
  </link>
  <joint name="R_shoulder_roll" type="fixed">
    <origin xyz="0 -0.0588 0" rpy="0.17453 0 0" />
    <parent link="R_shoulder_pitch_link" />
    <child link="R_shoulder_roll_link" />
    <axis xyz="-1 0 0" />
    <limit lower="-0.2618" upper="2.653" effort="14" velocity="36" />
  </joint>
  <link name="R_shoulder_yaw_Link">
    <inertial>
      <origin xyz="-0.00093758 -3.1963E-07 -0.077353" rpy="0 0 0" />
      <mass value="0.896" />
      <inertia ixx="0.0010981" ixy="9.9144E-09" ixz="-7.4888E-05" iyy="0.0010382" iyz="-2.1083E-08" izz="0.00054988" />
    </inertial>
    <visual>
      <origin xyz="0 0 0" rpy="0 0 0" />
      <geometry>
        <mesh filename="meshes/R_shoulder_yaw_Link.STL" />
      </geometry>
      <material name="">
        <color rgba="1.92 1.768 2.03 1" />
      </material>
    </visual>
    <collision>
      <origin xyz="0 0 0" rpy="0 0 0" />
      <geometry>
        <mesh filename="meshes/R_shoulder_yaw_Link.STL" />
      </geometry>
    </collision>
  </link>
  <joint name="R_shoulder_yaw" type="fixed">
    <origin xyz="0 -0.018928 -0.10734" rpy="-0.17453 0 0" />
    <parent link="R_shoulder_roll_link" />
    <child link="R_shoulder_yaw_Link" />
    <axis xyz="0 0 -1" />
    <limit lower="-2.618" upper="2.618" effort="14" velocity="36" />
  </joint>
  <link name="R_elbow_pitch_Link">
    <inertial>
      <origin xyz="-0.010969 -6.7823E-07 -0.094556" rpy="0 0 0" />
      <mass value="0.576" />
      <inertia ixx="0.0018468" ixy="2.5872E-09" ixz="8.1255E-05" iyy="0.0018242" iyz="3.6589E-09" izz="0.00040637" />
    </inertial>
    <visual>
      <origin xyz="0 0 0" rpy="0 0 0" />
      <geometry>
        <mesh filename="meshes/R_elbow_pitch_Link.STL" />
      </geometry>
      <material name="">
        <color rgba="1.92 1.768 2.03 1" />
      </material>
    </visual>
    <collision>
      <origin xyz="0 0 0" rpy="0 0 0" />
      <geometry>
        <mesh filename="meshes/R_elbow_pitch_Link.STL" />
      </geometry>
    </collision>
  </link>
  <joint name="R_elbow_pitch" type="fixed">
    <origin xyz="0.01 0 -0.151" rpy="0 -1.57 0" />
    <parent link="R_shoulder_yaw_Link" />
    <child link="R_elbow_pitch_Link" />
    <axis xyz="0 -1 0" />
    <limit lower="0" upper="2.304" effort="14" velocity="36" />
  </joint>
  <link name="R_wrist_yaw_Link">
    <inertial>
      <origin xyz="0.005469 -0.0020643 -0.097398" rpy="0 0 0" />
      <mass value="0.692" />
      <inertia ixx="0.00070888" ixy="3.6471E-05" ixz="4.4192E-05" iyy="0.00081301" iyz="5.6107E-06" izz="0.00020641" />
    </inertial>
    <visual>
      <origin xyz="0 0 0" rpy="0 0 0" />
      <geometry>
        <mesh filename="meshes/R_wrist_yaw_Link.STL" />
      </geometry>
      <material name="">
        <color rgba="1.88 1.904 1.92 1" />
      </material>
    </visual>
    <collision>
      <origin xyz="0 0 0" rpy="0 0 0" />
      <geometry>
        <mesh filename="meshes/R_wrist_yaw_Link.STL" />
      </geometry>
    </collision>
  </link>
  <joint name="R_wrist_yaw" type="fixed">
    <origin xyz="-0.01 0 -0.166" rpy="0 0 0" />
    <parent link="R_elbow_pitch_Link" />
    <child link="R_wrist_yaw_Link" />
    <axis xyz="0 0 -1" />
    <limit lower="-2.793" upper="2.793" effort="2.2" velocity="36" />
  </joint>
    <link name="torso_face_Link">
    <inertial>
      <origin xyz="-0.00039751 -6.9471E-06 0.22856" rpy="0 0 0" />
      <mass value="5" />
      <inertia ixx="0.25328" ixy="1.0632E-06" ixz="0.0016242" iyy="0.22585" iyz="-4.1782E-06" izz="0.14558" />
    </inertial>
    <visual>
      <origin xyz="0 0 0" rpy="0 0 0" />
      <geometry>
        <mesh filename="meshes/torso_face_Link.STL" />
      </geometry>
      <material name="">
        <color rgba="1.92 1.768 2.03 1" />
      </material>
    </visual>
    <collision>
      <origin xyz="0 0 0" rpy="0 0 0" />
      <geometry>
        <mesh filename="meshes/torso_face_Link.STL" />
      </geometry>
    </collision>
  </link>
  <joint name="torso_face" type="fixed">
    <origin xyz="0 0 0.1315" rpy="0 0 0" />
    <parent link="waist_yaw_link" />
    <child link="torso_face_Link" />
    <axis xyz="0 0 0" />
  </joint>
</robot>