<mujoco model="X02C_PRO">
  <compiler angle="radian" meshdir="./meshes/"/>
  <statistic meansize="0.144785" extent="1.23314" center="0.025392 2.0634e-05 -0.245975"/>
  <default>
    <joint damping="0.1" armature="0.01" frictionloss="0.1"/>
  </default>
  <asset>
    <mesh name="pelvis_link" file="pelvis_link.STL"/>
    <mesh name="L_hip_yaw_link" file="L_hip_yaw_link.STL"/>
    <mesh name="L_hip_roll_link" file="L_hip_roll_link.STL"/>
    <mesh name="L_hip_pitch_link" file="L_hip_pitch_link.STL"/>
    <mesh name="L_knee_pitch_link" file="L_knee_pitch_link.STL"/>
    <mesh name="L_ankle_pitch_link" file="L_ankle_pitch_link.STL"/>
    <mesh name="L_ankle_roll_link" file="L_ankle_roll_link.STL"/>
    <mesh name="R_hip_yaw_link" file="R_hip_yaw_link.STL"/>
    <mesh name="R_hip_roll_link" file="R_hip_roll_link.STL"/>
    <mesh name="R_hip_pitch_link" file="R_hip_pitch_link.STL"/>
    <mesh name="R_knee_pitch_link" file="R_knee_pitch_link.STL"/>
    <mesh name="R_ankle_pitch_link" file="R_ankle_pitch_link.STL"/>
    <mesh name="R_ankle_roll_link" file="R_ankle_roll_link.STL"/>
    <mesh name="waist_yaw_link" file="waist_yaw_link.STL"/>
    <mesh name="torso_link" file="torso_link.STL"/>
    <mesh name="L_shoulder_pitch_link" file="L_shoulder_pitch_link.STL"/>
    <mesh name="L_shoulder_roll_link" file="L_shoulder_roll_link.STL"/>
    <mesh name="L_shoulder_yaw_link" file="L_shoulder_yaw_link.STL"/>
    <mesh name="L_elbow_pitch_link" file="L_elbow_pitch_link.STL"/>
    <mesh name="L_wrist_yaw_Link" file="L_wrist_yaw_Link.STL"/>
    <mesh name="R_shoulder_pitch_link" file="R_shoulder_pitch_link.STL"/>
    <mesh name="R_shoulder_roll_link" file="R_shoulder_roll_link.STL"/>
    <mesh name="R_shoulder_yaw_Link" file="R_shoulder_yaw_Link.STL"/>
    <mesh name="R_elbow_pitch_Link" file="R_elbow_pitch_Link.STL"/>
    <mesh name="R_wrist_yaw_Link" file="R_wrist_yaw_Link.STL"/>
    <mesh name="torso_face_Link" file="torso_face_Link.STL"/>
  </asset>

  <worldbody>
    <body name="pelvis_link" pos="0 0 1.047">
      <inertial pos="0.00166403 -3.87989e-06 0.218859" quat="0.99859 -1.45588e-05 -0.0530919 -3.99699e-06" mass="26.132" diaginertia="1.27427 0.89055 0.669676"/>
      <joint name="pelvis_link" type="free" limited="false" actuatorfrclimited="false"/>
      <geom type="mesh" contype="0" conaffinity="0" group="1" density="0" rgba="1 1 1 1" mesh="pelvis_link"/>
      <geom type="mesh" rgba="1 1 1 1" mesh="pelvis_link"/>
      <geom pos="0 0 -0.1315" type="mesh" contype="0" conaffinity="0" group="1" density="0" rgba="0.419608 0.419608 0.419608 1" mesh="waist_yaw_link"/>
      <geom pos="0 0 -0.1315" type="mesh" rgba="0.419608 0.419608 0.419608 1" mesh="waist_yaw_link"/>
      <geom type="mesh" contype="0" conaffinity="0" group="1" density="0" rgba="0.419608 0.419608 0.419608 1" mesh="torso_link"/>
      <geom type="mesh" rgba="0.419608 0.419608 0.419608 1" mesh="torso_link"/>
      <geom pos="-0.01 0.13365 0.31135" quat="0.985009 0.0861756 0.148869 -0.0130242" type="mesh" contype="0" conaffinity="0" group="1" density="0" rgba="0.419608 0.419608 0.419608 1" mesh="L_shoulder_pitch_link"/>
      <geom pos="-0.01 0.13365 0.31135" quat="0.985009 0.0861756 0.148869 -0.0130242" type="mesh" rgba="0.419608 0.419608 0.419608 1" mesh="L_shoulder_pitch_link"/>
      <geom pos="-0.00698264 0.191557 0.321104" quat="0.988771 0 0.149438 0" type="mesh" contype="0" conaffinity="0" group="1" density="0" rgba="2.032 1.888 1.872 1" mesh="L_shoulder_roll_link"/>
      <geom pos="-0.00698264 0.191557 0.321104" quat="0.988771 0 0.149438 0" type="mesh" rgba="2.032 1.888 1.872 1" mesh="L_shoulder_roll_link"/>
      <geom pos="-0.0387038 0.210485 0.218558" quat="0.985009 0.0861756 0.148869 -0.0130242" type="mesh" contype="0" conaffinity="0" group="1" density="0" rgba="2.032 1.888 1.872 1" mesh="L_shoulder_yaw_link"/>
      <geom pos="-0.0387038 0.210485 0.218558" quat="0.985009 0.0861756 0.148869 -0.0130242" type="mesh" rgba="2.032 1.888 1.872 1" mesh="L_shoulder_yaw_link"/>
      <geom pos="-0.0730961 0.236705 0.073539" quat="0.802008 0.0517538 -0.59092 -0.0701243" type="mesh" contype="0" conaffinity="0" group="1" density="0" rgba="2.032 1.888 1.872 1" mesh="L_elbow_pitch_link"/>
      <geom pos="-0.0730961 0.236705 0.073539" quat="0.802008 0.0517538 -0.59092 -0.0701243" type="mesh" rgba="2.032 1.888 1.872 1" mesh="L_elbow_pitch_link"/>
      <geom pos="0.0825334 0.238465 0.0149524" quat="0.802008 0.0517538 -0.59092 -0.0701243" type="mesh" contype="0" conaffinity="0" group="1" density="0" rgba="1.88 1.904 1.92 1" mesh="L_wrist_yaw_Link"/>
      <geom pos="0.0825334 0.238465 0.0149524" quat="0.802008 0.0517538 -0.59092 -0.0701243" type="mesh" rgba="1.88 1.904 1.92 1" mesh="L_wrist_yaw_Link"/>
      <geom pos="-0.01 -0.13365 0.31135" quat="0.985009 -0.0861756 0.148869 0.0130242" type="mesh" contype="0" conaffinity="0" group="1" density="0" rgba="0.41961 0.41961 0.41961 1" mesh="R_shoulder_pitch_link"/>
      <geom pos="-0.01 -0.13365 0.31135" quat="0.985009 -0.0861756 0.148869 0.0130242" type="mesh" rgba="0.41961 0.41961 0.41961 1" mesh="R_shoulder_pitch_link"/>
      <geom pos="-0.00698264 -0.191557 0.321104" quat="0.988771 0 0.149438 0" type="mesh" contype="0" conaffinity="0" group="1" density="0" rgba="2.032 1.888 1.872 1" mesh="R_shoulder_roll_link"/>
      <geom pos="-0.00698264 -0.191557 0.321104" quat="0.988771 0 0.149438 0" type="mesh" rgba="2.032 1.888 1.872 1" mesh="R_shoulder_roll_link"/>
      <geom pos="-0.0387038 -0.210485 0.218558" quat="0.985009 -0.0861756 0.148869 0.0130242" type="mesh" contype="0" conaffinity="0" group="1" density="0" rgba="2.032 1.888 1.872 1" mesh="R_shoulder_yaw_Link"/>
      <geom pos="-0.0387038 -0.210485 0.218558" quat="0.985009 -0.0861756 0.148869 0.0130242" type="mesh" rgba="2.032 1.888 1.872 1" mesh="R_shoulder_yaw_Link"/>
      <geom pos="-0.0730961 -0.236705 0.073539" quat="0.802008 -0.0517538 -0.59092 0.0701243" type="mesh" contype="0" conaffinity="0" group="1" density="0" rgba="2.032 1.888 1.872 1" mesh="R_elbow_pitch_Link"/>
      <geom pos="-0.0730961 -0.236705 0.073539" quat="0.802008 -0.0517538 -0.59092 0.0701243" type="mesh" rgba="2.032 1.888 1.872 1" mesh="R_elbow_pitch_Link"/>
      <geom pos="0.0825334 -0.238465 0.0149524" quat="0.802008 -0.0517538 -0.59092 0.0701243" type="mesh" contype="0" conaffinity="0" group="1" density="0" rgba="1.88 1.904 1.92 1" mesh="R_wrist_yaw_Link"/>
      <geom pos="0.0825334 -0.238465 0.0149524" quat="0.802008 -0.0517538 -0.59092 0.0701243" type="mesh" rgba="1.88 1.904 1.92 1" mesh="R_wrist_yaw_Link"/>
      <geom type="mesh" contype="0" conaffinity="0" group="1" density="0" rgba="2.032 1.888 1.872 1" mesh="torso_face_Link"/>
      <geom type="mesh" rgba="2.032 1.888 1.872 1" mesh="torso_face_Link"/>
      <site name="imu" pos="0 0 0.01"/>
      <body name="L_hip_yaw_link" pos="0 0 -0.1315">
        <inertial pos="7.60799e-09 0.0271793 0.00194454" quat="0.489994 0.509805 -0.509809 0.489999" mass="0.841" diaginertia="0.00108738 0.00107032 0.000287691"/>
        <joint name="L_hip_yaw" pos="0 0 0" axis="0 0 1" range="-0.785 0.785" actuatorfrcrange="-50 50"/>
        <geom type="mesh" contype="0" conaffinity="0" group="1" density="0" rgba="0.419608 0.419608 0.419608 1" mesh="L_hip_yaw_link"/>
        <body name="L_hip_roll_link" pos="0 0.12 -0.001">
          <inertial pos="-0.0345844 0.000177017 -0.0717645" quat="0.672496 -0.167325 -0.156368 0.703776" mass="2.667" diaginertia="0.00895868 0.00844549 0.00515547"/>
          <joint name="L_hip_roll" pos="0 0 0" axis="1 0 0" range="-0.349 0.534" actuatorfrcrange="-100 100"/>
          <geom type="mesh" contype="0" conaffinity="0" group="1" density="0" rgba="0.419608 0.419608 0.419608 1" mesh="L_hip_roll_link"/>
          <geom type="mesh" rgba="0.419608 0.419608 0.419608 1" mesh="L_hip_roll_link"/>
          <body name="L_hip_pitch_link" pos="0 0 -0.11">
            <inertial pos="0.00822869 0 -0.167031" quat="0.706936 0.0155262 0.0155262 0.706936" mass="1.8" diaginertia="0.0177056 0.017016 0.00316021"/>
            <joint name="L_hip_pitch" pos="0 0 0" axis="0 -1 0" range="-0.534 2.094" actuatorfrcrange="-212 212"/>
            <geom type="mesh" contype="0" conaffinity="0" group="1" density="0" rgba="2.032 1.888 1.872 1" mesh="L_hip_pitch_link"/>
            <geom type="mesh" rgba="2.032 1.888 1.872 1" mesh="L_hip_pitch_link"/>
            <body name="L_knee_pitch_link" pos="0 0 -0.35">
              <inertial pos="0.00111166 0 -0.146097" quat="0.707021 -0.0110178 -0.0110178 0.707021" mass="1.125" diaginertia="0.0117203 0.0115906 0.00120819"/>
              <joint name="L_knee_pitch" pos="0 0 0" axis="0 -1 0" range="-2.269 0" actuatorfrcrange="-93 93"/>
              <geom type="mesh" contype="0" conaffinity="0" group="1" density="0" rgba="2.032 1.888 1.872 1" mesh="L_knee_pitch_link"/>
              <geom type="mesh" rgba="2.032 1.888 1.872 1" mesh="L_knee_pitch_link"/>
              <body name="L_ankle_pitch_link" pos="0 0 -0.35">
                <inertial pos="0.00294753 -1.35446e-05 -0.0240696" quat="0.393037 0.587932 0.588193 0.392284" mass="0.3" diaginertia="4.97297e-05 3.50101e-05 2.35419e-05"/>
                <joint name="L_ankle_pitch" pos="0 0 0" axis="0 -1 0" range="-1.047 1.047" actuatorfrcrange="-64.8 64.8"/>
                <geom type="mesh" contype="0" conaffinity="0" group="1" density="0" rgba="0.419608 0.419608 0.419608 1" mesh="L_ankle_pitch_link"/>
                <geom type="mesh" rgba="0.419608 0.419608 0.419608 1" mesh="L_ankle_pitch_link"/>
                <body name="L_ankle_roll_link" pos="0 0 -0.058">
                  <inertial pos="0.0511098 2.2797e-05 -0.0292782" quat="-0.00029501 0.707139 -0.00029148 0.707075" mass="0.6" diaginertia="0.00355223 0.00328194 0.000357089"/>
                  <joint name="L_ankle_roll" pos="0 0 0" axis="1 0 0" range="-0.534 0.534" actuatorfrcrange="-20 20"/>
                  <geom type="mesh" contype="0" conaffinity="0" group="1" density="0" rgba="1.912 1.904 1.92 1" mesh="L_ankle_roll_link"/>
                  <geom size="0.005" pos="-0.093 0 -0.0415" rgba="1.912 1.904 1.92 1"/>
                  <geom size="0.005" pos="0.18 0 -0.0415" rgba="1.912 1.904 1.92 1"/>
                  <geom size="0.005" pos="0.095 -0.045 -0.0415" rgba="1.912 1.904 1.92 1"/>
                  <geom size="0.005" pos="0.095 0.045 -0.0415" rgba="1.912 1.904 1.92 1"/>
                  <geom size="0.005" pos="0 0.033 -0.0415" rgba="1.912 1.904 1.92 1"/>
                  <geom size="0.005" pos="0 -0.033 -0.0415" rgba="1.912 1.904 1.92 1"/>
                </body>
              </body>
            </body>
          </body>
        </body>
      </body>
      <body name="R_hip_yaw_link" pos="0 0 -0.1315">
        <inertial pos="-5.27551e-09 -0.0504944 0.00610804" quat="0.690877 0.722973 -5.69551e-07 5.44266e-07" mass="0.947" diaginertia="0.000695242 0.000603315 0.000198487"/>
        <joint name="R_hip_yaw" pos="0 0 0" axis="0 0 -1" range="-0.785 0.785" actuatorfrcrange="-50 50"/>
        <geom type="mesh" contype="0" conaffinity="0" group="1" density="0" rgba="0.419608 0.419608 0.419608 1" mesh="R_hip_yaw_link"/>
        <body name="R_hip_roll_link" pos="0 -0.12 -0.001">
          <inertial pos="-0.0345843 -0.000177506 -0.0717629" quat="0.70375 -0.156367 -0.167303 0.672529" mass="2.667" diaginertia="0.00895899 0.00844574 0.00515553"/>
          <joint name="R_hip_roll" pos="0 0 0" axis="-1 0 0" range="-0.349 0.534" actuatorfrcrange="-100 100"/>
          <geom type="mesh" contype="0" conaffinity="0" group="1" density="0" rgba="0.419608 0.419608 0.419608 1" mesh="R_hip_roll_link"/>
          <geom type="mesh" rgba="0.419608 0.419608 0.419608 1" mesh="R_hip_roll_link"/>
          <body name="R_hip_pitch_link" pos="0 0 -0.11">
            <inertial pos="0.00822868 0 -0.167031" quat="0.706937 0.0155252 0.0155272 0.706935" mass="1.8" diaginertia="0.0177056 0.017016 0.0031602"/>
            <joint name="R_hip_pitch" pos="0 0 0" axis="0 -1 0" range="-0.534 2.094" actuatorfrcrange="-212 212"/>
            <geom type="mesh" contype="0" conaffinity="0" group="1" density="0" rgba="2.032 1.888 1.872 1" mesh="R_hip_pitch_link"/>
            <geom type="mesh" rgba="2.032 1.888 1.872 1" mesh="R_hip_pitch_link"/>
            <body name="R_knee_pitch_link" pos="0 0 -0.35">
              <inertial pos="0.00111164 0 -0.146097" quat="0.707021 -0.0110174 -0.0110174 0.707021" mass="1.125" diaginertia="0.0117203 0.0115906 0.00120819"/>
              <joint name="R_knee_pitch" pos="0 0 0" axis="0 -1 0" range="-2.269 0" actuatorfrcrange="-93 93"/>
              <geom type="mesh" contype="0" conaffinity="0" group="1" density="0" rgba="2.032 1.888 1.872 1" mesh="R_knee_pitch_link"/>
              <geom type="mesh" rgba="2.032 1.888 1.872 1" mesh="R_knee_pitch_link"/>
              <body name="R_ankle_pitch_link" pos="0 0 -0.35">
                <inertial pos="0.00294753 -1.35446e-05 -0.0240696" quat="0.393037 0.587932 0.588193 0.392284" mass="0.3" diaginertia="4.97297e-05 3.50101e-05 2.35419e-05"/>
                <joint name="R_ankle_pitch" pos="0 0 0" axis="0 -1 0" range="-1.047 1.047" actuatorfrcrange="-64.8 64.8"/>
                <geom type="mesh" contype="0" conaffinity="0" group="1" density="0" rgba="0.419608 0.419608 0.419608 1" mesh="R_ankle_pitch_link"/>
                <geom type="mesh" rgba="0.419608 0.419608 0.419608 1" mesh="R_ankle_pitch_link"/>
                <body name="R_ankle_roll_link" pos="0 0 -0.058">
                  <inertial pos="0.0511098 2.2797e-05 -0.0292782" quat="-0.00029501 0.707139 -0.00029148 0.707075" mass="0.6" diaginertia="0.00355223 0.00328194 0.000357089"/>
                  <joint name="R_ankle_roll" pos="0 0 0" axis="-1 0 0" range="-0.534 0.534" actuatorfrcrange="-20 20"/>
                  <geom type="mesh" contype="0" conaffinity="0" group="1" density="0" rgba="1.912 1.904 1.92 1" mesh="R_ankle_roll_link"/>
                  <geom size="0.005" pos="-0.093 0 -0.0415" rgba="1.912 1.904 1.92 1"/>
                  <geom size="0.005" pos="0.18 0 -0.0415" rgba="1.912 1.904 1.92 1"/>
                  <geom size="0.005" pos="0.095 -0.045 -0.0415" rgba="1.912 1.904 1.92 1"/>
                  <geom size="0.005" pos="0.095 0.045 -0.0415" rgba="1.912 1.904 1.92 1"/>
                  <geom size="0.005" pos="0 0.033 -0.0415" rgba="1.912 1.904 1.92 1"/>
                  <geom size="0.005" pos="0 -0.033 -0.0415" rgba="1.912 1.904 1.92 1"/>
                </body>
              </body>
            </body>
          </body>
        </body>
      </body>
    </body>
  </worldbody>
  <actuator>
    <motor name="L_hip_pitch"     joint="L_hip_pitch"     />
    <motor name="L_hip_roll"      joint="L_hip_roll"      />
    <motor name="L_hip_yaw"       joint="L_hip_yaw"       />
    <motor name="L_knee_pitch"    joint="L_knee_pitch"    />
    <motor name="L_ankle_pitch"   joint="L_ankle_pitch"   />
    <motor name="L_ankle_roll"    joint="L_ankle_roll"   />

    <motor name="R_hip_pitch"     joint="R_hip_pitch"     />
    <motor name="R_hip_roll"      joint="R_hip_roll"      />
    <motor name="R_hip_yaw"       joint="R_hip_yaw"       />
    <motor name="R_knee_pitch"    joint="R_knee_pitch"    />
    <motor name="R_ankle_pitch"   joint="R_ankle_pitch"   />
    <motor name="R_ankle_roll"    joint="R_ankle_roll"   />
  </actuator>
  <sensor>
    <!-- 身体的的姿态 -->
    <gyro          name="gyro"    site='imu' noise='0.005' cutoff='34.9'/>
    <accelerometer name="acc"     site='imu' noise='0.005' cutoff='157'/>
    <framequat     name='bq'      objtype='site' noise='0.001' objname='imu'/>
    <framelinvel   name="blv"  objtype='site' objname='imu'/>
  </sensor>
</mujoco>
