<?xml version="1.0" encoding="utf-8"?>
<!-- This URDF was automatically created by SolidWorks to URDF Exporter! Originally created by Stephen Brawner (brawner@gmail.com) 
     Commit Version: 1.6.0-4-g7f85cfe  Build Version: 1.6.7995.38578
     For more information, please see http://wiki.ros.org/sw_urdf_exporter -->
<robot name="x03">
  <mujoco>
    <compiler meshdir="./meshes" discardvisual="false"/>
  </mujoco>

<!--  <link name="world"></link>-->
<!--  <joint name="pelvis_link" type="floating">-->
<!--    <parent link="world"/>-->
<!--    <child link="pelvis_link"/>-->
<!--  </joint>-->

  <link name="pelvis_link">
    <inertial>
      <origin xyz="-0.0061086 2.746E-07 -0.21231" rpy="0 0 0" />
      <mass value="3.69" />
      <inertia ixx="0.0058423" ixy="-8.0542E-09" ixz="1.1152E-05" iyy="0.0051067" iyz="2.0728E-09" izz="0.0079343" />
    </inertial>
    <!-- <inertial>
      <origin xyz="-0.01046077 -0.0000361 -0.20362414" rpy="0 0 0" />
      <mass value="3.69" />
      <inertia ixx="0.01159608" ixy="0.00003693" ixz="0.00048158" iyy="0.01140767" iyz="0.00006057" izz="0.01432514" />
    </inertial> -->
    <visual>
      <origin xyz="0 0 0" rpy="0 0 0" />
      <geometry>
        <mesh filename="meshes/pelvis_link.STL" />
      </geometry>
      <material name="">
        <color rgba="1 1 1 1" />
      </material>
    </visual>
    <collision>
      <origin xyz="0 0 0" rpy="0 0 0" />
      <geometry>
        <mesh filename="meshes/pelvis_link.STL" />
      </geometry>
    </collision>
  </link>
  <link name="waist_yaw_link">
    <!-- <inertial>
      <origin xyz="-0.00010782 1.0324E-08 0.037701" rpy="0 0 0" />
      <mass value="0.431" />
      <inertia ixx="5.8141E-05" ixy="1.4741E-12" ixz="-4.4183E-07" iyy="5.4231E-05" iyz="2.8156E-11" izz="4.0894E-05" />
    </inertial> -->
    <inertial>
      <origin xyz="-0.00016709 0 0.03880532" rpy="0 0 0" />
      <mass value="0.431" />
      <inertia ixx="0.00012958" ixy="0.00000000" ixz="0.00000125" iyy="0.00014283" iyz="0.00000000" izz="0.00012590" />
    </inertial>
    <visual>
      <origin xyz="0 0 0" rpy="0 0 0" />
      <geometry>
        <mesh filename="meshes/waist_yaw_link.STL" />
      </geometry>
      <material name="">
        <color rgba="1 1 1 1" />
      </material>
    </visual>
<!--    <collision>-->
<!--      <origin xyz="0 0 0" rpy="0 0 0" />-->
<!--      <geometry>-->
<!--        <mesh filename="meshes1/waist_yaw_link.STL" />-->
<!--      </geometry>-->
<!--    </collision>-->
  </link>
  <joint name="waist_yaw" type="revolute">
    <origin xyz="0 0 -0.133" rpy="0 0 0" />
    <parent link="pelvis_link" />
    <child link="waist_yaw_link" />
    <axis xyz="0 0 1" />
    <limit lower="-0.7854" upper="0.7854" effort="72" velocity="117.5" />
  </joint>
  <link name="waist_roll_link">
    <!-- <inertial>
      <origin xyz="0.0016564 8.6014E-09 0.25012" rpy="0 0 0" />
      <mass value="10.81" />
      <inertia ixx="0.26699" ixy="-1.2638E-07" ixz="-0.0010145" iyy="0.24688" iyz="5.2967E-07" izz="0.14561" />
    </inertial> -->
    <inertial>
      <origin xyz="0.00192930 0 0.22004922" rpy="0 0 0" />
      <mass value="10.81" />
      <inertia ixx="0.22443657" ixy="-0.00000184" ixz="-0.00006764" iyy="0.21289330" iyz="-0.00000063" izz="0.07877090" />
    </inertial>
    <visual>
      <origin xyz="0 0 0" rpy="0 0 0" />
      <geometry>
        <mesh filename="meshes/waist_roll_link.STL" />
      </geometry>
      <material name="">
        <color rgba="1 1 1 1" />
      </material>
    </visual>
<!--    <collision>-->
<!--      <origin xyz="0 0 0" rpy="0 0 0" />-->
<!--      <geometry>-->
<!--        <mesh filename="meshes1/waist_roll_link.STL" />-->
<!--      </geometry>-->
<!--    </collision>-->
  </link>
  <joint name="waist_roll" type="revolute">
    <origin xyz="0 0 0.043" rpy="0 0 0" />
    <parent link="waist_yaw_link" />
    <child link="waist_roll_link" />
    <axis xyz="1 0 0" />
    <limit lower="-0.4363" upper="0.4363" effort="36" velocity="235" />
  </joint>
  <link name="head_link">
    <!-- <inertial>
      <origin xyz="0.018295 8.7152E-05 0.16186" rpy="0 0 0" />
      <mass value="1.07" />
      <inertia ixx="0.0066666" ixy="-1.0327E-06" ixz="-0.00038297" iyy="0.0069077" iyz="-2.0282E-06" izz="0.0042095" />
    </inertial> -->
    <inertial>
      <origin xyz="0.01828675 0.00008734 0.16188204" rpy="0 0 0" />
      <mass value="1.07" />
      <inertia ixx="0.00976863" ixy="-0.00000175" ixz="-0.00056000" iyy="0.01011603" iyz="-0.00000206" izz="0.00616231" />
    </inertial>
    <visual>
      <origin xyz="0 0 0" rpy="0 0 0" />
      <geometry>
        <mesh filename="meshes/head_link.STL" />
      </geometry>
      <material name="">
        <color rgba="1 1 1 1" />
      </material>
    </visual>
    <collision>
      <origin xyz="0 0 0" rpy="0 0 0" />
      <geometry>
        <mesh filename="meshes/head_link.STL" />
      </geometry>
    </collision>
  </link>
  <joint name="head" type="fixed">
    <origin xyz="0 0 0.404" rpy="0 0 0" />
    <parent link="waist_roll_link" />
    <child link="head_link" />
    <axis xyz="0 0 1" />
    <limit lower="-1.5708" upper="1.5708" effort="12" velocity="50" />
  </joint>


  <link name="L_hip_roll_link">
    <!-- <inertial>
      <origin xyz="-0.00010782 0.0052987 4.3837E-09" rpy="0 0 0" />
      <mass value="0.231" />
      <inertia ixx="5.8141E-05" ixy="4.4183E-07" ixz="2.4175E-12" iyy="4.0894E-05" iyz="-2.6168E-11" izz="5.4231E-05" />
    </inertial> -->
    <inertial>
      <origin xyz="-0.00016709 0.00419468 0" rpy="0 0 0" />
      <mass value="0.231" />
      <inertia ixx="0.00012958" ixy="-0.00000125" ixz="0.00000000" iyy="0.00012590" iyz="0.00000000" izz="0.00014283" />
    </inertial>
    <visual>
      <origin xyz="0 0 0" rpy="0 0 0" />
      <geometry>
        <mesh filename="meshes/L_hip_roll_link.STL" />
      </geometry>
      <material name="">
        <color rgba="1 1 1 1" />
      </material>
    </visual>
<!--    <collision>-->
<!--      <origin xyz="0 0 0" rpy="0 0 0" />-->
<!--      <geometry>-->
<!--        <mesh filename="meshes1/L_hip_roll_link.STL" />-->
<!--      </geometry>-->
<!--    </collision>-->
  </link>
  <joint name="L_hip_roll" type="revolute">
    <origin xyz="0 0.05 -0.214" rpy="0 0 0" />
    <parent link="pelvis_link" />
    <child link="L_hip_roll_link" />
    <axis xyz="1 0 0" />
    <limit lower="-1.0472" upper="1.0472" effort="36" velocity="235" />
  </joint>
  <link name="L_hip_pitch_link">
    <inertial>
      <origin xyz="-2.9363E-09 -0.02482 -0.0053157" rpy="0 0 0" />
      <mass value="0.562" />
      <inertia ixx="0.00026071" ixy="-6.4779E-11" ixz="-2.9358E-11" iyy="6.9776E-05" iyz="-4.6302E-05" izz="0.00026873" />
    </inertial>
    <!-- <inertial>
      <origin xyz="0 0.02482051 -0.00531577" rpy="0 0 0" />
      <mass value="0.562" />
      <inertia ixx="0.00026070" ixy="0.00000000" ixz="0.00000000" iyy="0.00006978" iyz="-0.00004630" izz="0.00026873" />
    </inertial> -->
    <visual>
      <origin xyz="0 0 0" rpy="0 0 0" />
      <geometry>
        <mesh filename="meshes/L_hip_pitch_link.STL" />
      </geometry>
      <material name="">
        <color rgba="1 0 0 1" />
      </material>
    </visual>
<!--    <collision>-->
<!--      <origin xyz="0 0 0" rpy="0 0 0" />-->
<!--      <geometry>-->
<!--        <mesh filename="meshes1/L_hip_pitch_link.STL" />-->
<!--      </geometry>-->
<!--    </collision>-->
  </link>
  <joint name="L_hip_pitch" type="revolute">
    <origin xyz="0 0.0430000000000016 0" rpy="0 0 0" />
    <parent link="L_hip_roll_link" />
    <child link="L_hip_pitch_link" />
    <axis xyz="0 -1 0" />
    <limit lower="-1.0472" upper="1.0472" effort="72" velocity="117.5" />
  </joint>
  <link name="L_hip_yaw_link">
    <!-- <inertial>
      <origin xyz="0.00019541 -4.5701E-06 -0.12457" rpy="0 0 0" />
      <mass value="2.324" />
      <inertia ixx="0.016246" ixy="-1.1614E-07" ixz="6.5017E-05" iyy="0.015818" iyz="-5.3925E-06" izz="0.0019584" />
    </inertial> -->
    <inertial>
      <origin xyz="0.00019541 0.00000455 -0.12907016" rpy="0 0 0" />
      <mass value="2.324" />
      <inertia ixx="0.02774437" ixy="-0.00000020" ixz="-0.00011103" iyy="0.02701229" iyz="-0.00000921" izz="0.00334446" />
    </inertial>
    <visual>
      <origin xyz="0 0 0" rpy="0 0 0" />
      <geometry>
        <mesh filename="meshes/L_hip_yaw_link.STL" />
      </geometry>
      <material name="">
        <color rgba="1 1 1 1" />
      </material>
    </visual>
    <collision>
      <origin xyz="0 0 0" rpy="0 0 0" />
      <geometry>
        <mesh filename="meshes/L_hip_yaw_link.STL" />
      </geometry>
    </collision>
  </link>
  <joint name="L_hip_yaw" type="revolute">
    <origin xyz="0 0.0519999999999982 -0.0425000000000013" rpy="0 0 0" />
    <parent link="L_hip_pitch_link" />
    <child link="L_hip_yaw_link" />
    <axis xyz="0 0 1" />
    <limit lower="-1.0472" upper="1.0472" effort="24" velocity="37" />
  </joint>
  <link name="L_knee_pitch_link">
    <!-- <inertial>
      <origin xyz="0.0019953 -6.2094E-06 -0.13673" rpy="0 0 0" />
      <mass value="0.757" />
      <inertia ixx="0.0056575" ixy="-3.9452E-09" ixz="-7.3205E-05" iyy="0.0057189" iyz="-5.0616E-07" izz="0.00014517" />
    </inertial> -->
    <inertial>
      <origin xyz="0.00263046 -0.00011593 -0.16331546" rpy="0 0 0" />
      <mass value="0.757" />
      <inertia ixx="0.01062442" ixy="0.00000019" ixz="0.00026927" iyy="0.01076371" iyz="0.00001282" izz="0.00033913" />
    </inertial>
    <visual>
      <origin xyz="0 0 0" rpy="0 0 0" />
      <geometry>
        <mesh filename="meshes/L_knee_pitch_link.STL" />
      </geometry>
      <material name="">
        <color rgba="1 1 1 1" />
      </material>
    </visual>
    <collision>
      <origin xyz="0 0 0" rpy="0 0 0" />
      <geometry>
        <mesh filename="meshes/L_knee_pitch_link.STL" />
      </geometry>
    </collision>
  </link>
  <joint name="L_knee_pitch" type="revolute">
    <origin xyz="0 0 -0.3875" rpy="0 0 0" />
    <parent link="L_hip_yaw_link" />
    <child link="L_knee_pitch_link" />
    <axis xyz="0 -1 0" />
    <limit lower="-2.3736" upper="0" effort="93.6" velocity="90" />
  </joint>
  <link name="L_ankle_pitch_link">
    <!-- <inertial>
      <origin xyz="0.02994 -0.0019506 -0.0613" rpy="0 0 0" />
      <mass value="0.465" />
      <inertia ixx="0.00069882" ixy="8.37E-05" ixz="0.00029456" iyy="0.0025593" iyz="-1.9449E-05" izz="0.00225" />
    </inertial> -->
    <inertial>
      <origin xyz="0.03993828 -0.00195001 -0.07629968" rpy="0 0 0" />
      <mass value="0.465" />
      <inertia ixx="0.00055" ixy="0.0" ixz="-0.00000898" iyy="0.00215" iyz="0.0" izz="0.0026" />
    </inertial>
    <visual>
      <origin xyz="0 0 0" rpy="0 0 0" />
      <geometry>
        <mesh filename="meshes/L_ankle_pitch_link.STL" />
      </geometry>
      <material name="">
        <color rgba="1 1 1 1" />
      </material>
    </visual>
<!--    <collision>-->
<!--      <origin xyz="0 0 0" rpy="0 0 0" />-->
<!--      <geometry>-->
<!--        <mesh filename="meshes1/L_ankle_pitch_link.STL" />-->
<!--      </geometry>-->
<!--    </collision>-->
<!--    <collision>-->
<!--     <origin xyz="0.02 -0.04 0.02" rpy="0 0 0"/>-->
<!--     <geometry>-->
<!--     <box size="0.26 0.09 0.05"/>-->
<!--     </geometry>-->
<!--    </collision>-->
    <collision>
      <origin xyz="-0.105 -0.0 -0.072" rpy="0 0 0"/>
      <geometry>
        <sphere radius="0.005"/>
      </geometry>
    </collision>
    <collision>
      <origin xyz="0.145 -0.01 -0.05" rpy="0 0 0"/>
      <geometry>
        <sphere radius="0.005"/>
      </geometry>
    </collision>
    <collision>
      <origin xyz="0.07 0.045 -0.056" rpy="0 0 0"/>
      <geometry>
        <sphere radius="0.005"/>
      </geometry>
    </collision>
    <collision>
      <origin xyz="0.07 -0.045 -0.056" rpy="0 0 0"/>
      <geometry>
        <sphere radius="0.005"/>
      </geometry>
    </collision>
    <collision>
      <origin xyz="0.0 0.035 -0.062" rpy="0 0 0"/>
      <geometry>
        <sphere radius="0.005"/>
      </geometry>
    </collision>
    <collision>
      <origin xyz="0.0 -0.03 -0.062" rpy="0 0 0"/>
      <geometry>
        <sphere radius="0.005"/>
      </geometry>
    </collision>
    <collision>
      <origin xyz="-0.05 0.035 -0.067" rpy="0 0 0"/>
      <geometry>
        <sphere radius="0.005"/>
      </geometry>
    </collision>
    <collision>
      <origin xyz="-0.05 -0.03 -0.067" rpy="0 0 0"/>
      <geometry>
        <sphere radius="0.005"/>
      </geometry>
    </collision>
  </link>
  <joint name="L_ankle_pitch" type="revolute">
    <origin xyz="0 0 -0.4" rpy="0 0 0" />
    <parent link="L_knee_pitch_link" />
    <child link="L_ankle_pitch_link" />
    <axis xyz="0 -1 0" />
    <limit lower="-1.0472" upper="1.0472" effort="64.8" velocity="130" />
  </joint>
  <link name="R_hip_roll_link">
    <!-- <inertial>
      <origin xyz="-0.00010782 -0.0052987 -1.2399E-11" rpy="0 0 0" />
      <mass value="0.231" />
      <inertia ixx="5.8141E-05" ixy="-4.4181E-07" ixz="5.8834E-12" iyy="4.0894E-05" iyz="4.9391E-11" izz="5.4231E-05" />
    </inertial> -->
    <inertial>
      <origin xyz="-0.00010806 -0.00529873 0" rpy="0 0 0" />
      <mass value="0.231" />
      <inertia ixx="0.00012958" ixy="0.00000125" ixz="-0.00000000" iyy="0.00012590" iyz="0.00000000" izz="0.00014283" />
    </inertial>
    <visual>
      <origin xyz="0 0 0" rpy="0 0 0" />
      <geometry>
        <mesh filename="meshes/R_hip_roll_link.STL" />
      </geometry>
      <material name="">
        <color rgba="1 1 1 1" />
      </material>
    </visual>
<!--    <collision>-->
<!--      <origin xyz="0 0 0" rpy="0 0 0" />-->
<!--      <geometry>-->
<!--        <mesh filename="meshes1/R_hip_roll_link.STL" />-->
<!--      </geometry>-->
<!--    </collision>-->
  </link>
  <joint name="R_hip_roll" type="revolute">
    <origin xyz="0 -0.05 -0.214" rpy="0 0 0" />
    <parent link="pelvis_link" />
    <child link="R_hip_roll_link" />
    <axis xyz="-1 0 0" />
    <limit lower="-1.0472" upper="1.0472" effort="36" velocity="235" />
  </joint>
  <link name="R_hip_pitch_link">
    <inertial>
      <origin xyz="-2.9363E-09 -0.02482 -0.0053157" rpy="0 0 0" />
      <mass value="0.562" />
      <inertia ixx="0.00026070" ixy="-0.00000000" ixz="0.00000000" iyy="0.00006978" iyz="0.00004630" izz="0.00026873" />
    </inertial>
    <!-- <inertial>
      <origin xyz="0 -0.02482051 -0.00531577" rpy="0 0 0" />
      <mass value="0.562" />
      <inertia ixx="0.00026070" ixy="0.00000000" ixz="0.00000000" iyy="0.00006978" iyz="0.00004630" izz="0.00026873" />
    </inertial> -->
    <visual>
      <origin xyz="0 0 0" rpy="0 0 0" />
      <geometry>
        <mesh filename="meshes/R_hip_pitch_link.STL" />
      </geometry>
      <material name="">
        <color rgba="1 0 0 1" />
      </material>
    </visual>
<!--    <collision>-->
<!--      <origin xyz="0 0 0" rpy="0 0 0" />-->
<!--      <geometry>-->
<!--        <mesh filename="meshes1/R_hip_pitch_link.STL" />-->
<!--      </geometry>-->
<!--    </collision>-->
  </link>
  <joint name="R_hip_pitch" type="revolute">
    <origin xyz="0 -0.0430000000000016 0" rpy="0 0 0" />
    <parent link="R_hip_roll_link" />
    <child link="R_hip_pitch_link" />
    <axis xyz="0 -1 0" />
    <limit lower="-1.0472" upper="1.0472" effort="72" velocity="117.5" />
  </joint>
  <link name="R_hip_yaw_link">
    <!-- <inertial>
      <origin xyz="0.00019541 4.5682E-06 -0.12457" rpy="0 0 0" />
      <mass value="2.324" />
      <inertia ixx="0.016246" ixy="1.1637E-07" ixz="6.5017E-05" iyy="0.015818" iyz="5.3927E-06" izz="0.0019584" />
    </inertial> -->
    <inertial>
      <origin xyz="0.00019541 0.00000455 -0.12457016" rpy="0 0 0" />
      <mass value="2.324" />
      <inertia ixx="0.02774437" ixy="-0.00000020" ixz="0.00011103" iyy="0.02701229" iyz="0.00000921" izz="0.00334446" />
    </inertial>
    <visual>
      <origin xyz="0 0 0" rpy="0 0 0" />
      <geometry>
        <mesh filename="meshes/R_hip_yaw_link.STL" />
      </geometry>
      <material name="">
        <color rgba="1 1 1 1" />
      </material>
    </visual>
    <collision>
      <origin xyz="0 0 0" rpy="0 0 0" />
      <geometry>
        <mesh filename="meshes/R_hip_yaw_link.STL" />
      </geometry>
    </collision>
  </link>
  <joint name="R_hip_yaw" type="revolute">
    <origin xyz="0 -0.0519999999999984 -0.0425000000000004" rpy="0 0 0" />
    <parent link="R_hip_pitch_link" />
    <child link="R_hip_yaw_link" />
    <axis xyz="0 0 -1" />
    <limit lower="-1.0472" upper="1.0472" effort="24" velocity="37" />
  </joint>
  <link name="R_knee_pitch_link">
    <!-- <inertial>
      <origin xyz="0.0019954 6.1928E-06 -0.13673" rpy="0 0 0" />
      <mass value="0.757" />
      <inertia ixx="0.0056575" ixy="4.1588E-09" ixz="-7.3209E-05" iyy="0.0057189" iyz="5.0676E-07" izz="0.00014517" />
    </inertial> -->
    <inertial>
      <origin xyz="0.00263046 -0.00011593 -0.16331546" rpy="0 0 0" />
      <mass value="0.757" />
      <inertia ixx="0.01062442" ixy="-0.00000019" ixz="0.00026927" iyy="0.01076371" iyz="-0.00001282" izz="0.00033913" />
    </inertial>
    <visual>
      <origin xyz="0 0 0" rpy="0 0 0" />
      <geometry>
        <mesh filename="meshes/R_knee_pitch_link.STL" />
      </geometry>
      <material name="">
        <color rgba="1 1 1 1" />
      </material>
    </visual>
    <collision>
      <origin xyz="0 0 0" rpy="0 0 0" />
      <geometry>
        <mesh filename="meshes/R_knee_pitch_link.STL" />
      </geometry>
    </collision>
  </link>
  <joint name="R_knee_pitch" type="revolute">
    <origin xyz="0 0 -0.3875" rpy="0 0 0" />
    <parent link="R_hip_yaw_link" />
    <child link="R_knee_pitch_link" />
    <axis xyz="0 -1 0" />
    <limit lower="-2.3736" upper="0" effort="93.6" velocity="90" />
  </joint>
  <link name="R_ankle_pitch_link">
    <!-- <inertial>
      <origin xyz="0.02994 0.0019509 -0.0613" rpy="0 0 0" />
      <mass value="0.465" />
      <inertia ixx="0.00069883" ixy="-8.3713E-05" ixz="0.00029456" iyy="0.0025593" iyz="1.9449E-05" izz="0.00225" />
    </inertial> -->
    <inertial>
      <origin xyz="0.03993828 -0.00195001 -0.07629968" rpy="0 0 0" />
      <mass value="0.465" />
      <inertia ixx="0.00055" ixy="0.0" ixz="-0.00000898" iyy="0.00215" iyz="0.0" izz="0.0026" />
    </inertial>
    <visual>
      <origin xyz="0 0 0" rpy="0 0 0" />
      <geometry>
        <mesh filename="meshes/R_ankle_pitch_link.STL" />
      </geometry>
      <material name="">
        <color rgba="1 1 1 1" />
      </material>
    </visual>
<!--    <collision>-->
<!--      <origin xyz="0 0 0" rpy="0 0 0" />-->
<!--      <geometry>-->
<!--        <mesh filename="meshes1/R_ankle_pitch_link.STL" />-->
<!--      </geometry>-->
<!--    </collision>-->
<!--    <collision>-->
<!--     <origin xyz="0.02 0.04 0.02" rpy="0 0 0"/>-->
<!--     <geometry>-->
<!--     <box size="0.26 0.09 0.05"/>-->
<!--     </geometry>-->
<!--    </collision>-->
    <collision>
      <origin xyz="-0.105 -0.0 -0.072" rpy="0 0 0"/>
      <geometry>
        <sphere radius="0.005"/>
      </geometry>
    </collision>
    <collision>
      <origin xyz="0.145 0.01 -0.05" rpy="0 0 0"/>
      <geometry>
        <sphere radius="0.005"/>
      </geometry>
    </collision>
    <collision>
      <origin xyz="0.07 0.045 -0.056" rpy="0 0 0"/>
      <geometry>
        <sphere radius="0.005"/>
      </geometry>
    </collision>
    <collision>
      <origin xyz="0.07 -0.045 -0.056" rpy="0 0 0"/>
      <geometry>
        <sphere radius="0.005"/>
      </geometry>
    </collision>
    <collision>
      <origin xyz="0.0 -0.035 -0.062" rpy="0 0 0"/>
      <geometry>
        <sphere radius="0.005"/>
      </geometry>
    </collision>
    <collision>
      <origin xyz="0.0 0.03 -0.062" rpy="0 0 0"/>
      <geometry>
        <sphere radius="0.005"/>
      </geometry>
    </collision>
    <collision>
      <origin xyz="-0.05 -0.035 -0.067" rpy="0 0 0"/>
      <geometry>
        <sphere radius="0.005"/>
      </geometry>
    </collision>
    <collision>
      <origin xyz="-0.05 0.03 -0.067" rpy="0 0 0"/>
      <geometry>
        <sphere radius="0.005"/>
      </geometry>
    </collision>
  </link>
  <joint name="R_ankle_pitch" type="revolute">
    <origin xyz="0 0 -0.4" rpy="0 0 0" />
    <parent link="R_knee_pitch_link" />
    <child link="R_ankle_pitch_link" />
    <axis xyz="0 -1 0" />
    <limit lower="-1.0472" upper="1.0472" effort="64.8" velocity="130" />
  </joint>

  <link name="logo_link">
    <inertial>
      <origin xyz="0.0871329867578759 0.000311413849754188 0.196173346059318" rpy="0 0 0" />
      <mass value="0.00512067016238132" />
      <inertia ixx="1.2355192806412E-06" ixy="-8.30865245553351E-11" ixz="4.47381968459601E-07" iyy="1.10152197064289E-06" iyz="5.47449851950253E-10" izz="9.74577588908281E-07" />
    </inertial>
    <visual>
      <origin xyz="0 0 0" rpy="0 0 0" />
      <geometry>
        <mesh filename="meshes/logo_link.STL" />
      </geometry>
      <material name="">
        <color rgba="1 0 0 1" />
      </material>
    </visual>
    <collision>
      <origin xyz="0 0 0" rpy="0 0 0" />
      <geometry>
        <mesh filename="meshes/logo_link.STL" />
      </geometry>
    </collision>
  </link>
  <joint name="logo" type="fixed">
    <origin xyz="0 0 0.09" rpy="0 0 0" />
    <parent link="waist_roll_link" />
    <child link="logo_link" />
    <axis xyz="0 0 0" />
  </joint>

<!--  <link name="L_shoulder_pitch_link">-->
<!--    <inertial>-->
<!--      <origin xyz="4.4218E-09 -4.5215E-08 0.02287" rpy="0 0 0" />-->
<!--      <mass value="0.763" />-->
<!--      <inertia ixx="5.177E-05" ixy="-7.4692E-11" ixz="6.7773E-12" iyy="2.7775E-05" iyz="1.632E-11" izz="3.6513E-05" />-->
<!--    </inertial>-->
<!--    <visual>-->
<!--      <origin xyz="0 0 0" rpy="0 0 0" />-->
<!--      <geometry>-->
<!--        <mesh filename="meshes1/L_shoulder_pitch_link.STL" />-->
<!--      </geometry>-->
<!--      <material name="">-->
<!--        <color rgba="1 1 1 1" />-->
<!--      </material>-->
<!--    </visual>-->
<!--    <collision>-->
<!--      <origin xyz="0 0 0" rpy="0 0 0" />-->
<!--      <geometry>-->
<!--        <mesh filename="meshes1/L_shoulder_pitch_link.STL" />-->
<!--      </geometry>-->
<!--    </collision>-->
<!--  </link>-->
<!--  <joint name="L_shoulder_pitch" type="fixed">-->
<!--    <origin xyz="0 0.140425190814725 0.371226723951712" rpy="0 1.30899693899578 1.5707963267949" />-->
<!--    <parent link="waist_roll_link" />-->
<!--    <child link="L_shoulder_pitch_link" />-->
<!--    <axis xyz="0 0 -1" />-->
<!--    <limit lower="-1.5707" upper="3.1416" effort="12" velocity="50" />-->
<!--  </joint>-->
<!--  <link name="L_shoulder_roll_link">-->
<!--    <inertial>-->
<!--      <origin xyz="0.03472 -0.00020364 -3.8868E-09" rpy="0 0 0" />-->
<!--      <mass value="0.725" />-->
<!--      <inertia ixx="0.00022363" ixy="4.2302E-06" ixz="1.3678E-10" iyy="0.0008396" iyz="-9.6421E-12" izz="0.00084896" />-->
<!--    </inertial>-->
<!--    <visual>-->
<!--      <origin xyz="0 0 0" rpy="0 0 0" />-->
<!--      <geometry>-->
<!--        <mesh filename="meshes1/L_shoulder_roll_link.STL" />-->
<!--      </geometry>-->
<!--      <material name="">-->
<!--        <color rgba="1 1 1 1" />-->
<!--      </material>-->
<!--    </visual>-->
<!--    <collision>-->
<!--      <origin xyz="0 0 0" rpy="0 0 0" />-->
<!--      <geometry>-->
<!--        <mesh filename="meshes1/L_shoulder_roll_link.STL" />-->
<!--      </geometry>-->
<!--    </collision>-->
<!--  </link>-->
<!--  <joint name="L_shoulder_roll" type="fixed">-->
<!--    <origin xyz="0 0 0.0574999999999974" rpy="-1.5707963267949 0.261799387799121 0" />-->
<!--    <parent link="L_shoulder_pitch_link" />-->
<!--    <child link="L_shoulder_roll_link" />-->
<!--    <axis xyz="0 0 -1" />-->
<!--    <limit lower="0" upper="1.5707" effort="6.6" velocity="50" />-->
<!--  </joint>-->
<!--  <link name="L_shoulder_yaw_link">-->
<!--    <inertial>-->
<!--      <origin xyz="1.0693E-08 0.00040667 0.084068" rpy="0 0 0" />-->
<!--      <mass value="0.513" />-->
<!--      <inertia ixx="0.0012458" ixy="5.297E-11" ixz="3.2573E-10" iyy="0.0012467" iyz="6.3281E-05" izz="0.00022286" />-->
<!--    </inertial>-->
<!--    <visual>-->
<!--      <origin xyz="0 0 0" rpy="0 0 0" />-->
<!--      <geometry>-->
<!--        <mesh filename="meshes1/L_shoulder_yaw_link.STL" />-->
<!--      </geometry>-->
<!--      <material name="">-->
<!--        <color rgba="1 1 1 1" />-->
<!--      </material>-->
<!--    </visual>-->
<!--    <collision>-->
<!--      <origin xyz="0 0 0" rpy="0 0 0" />-->
<!--      <geometry>-->
<!--        <mesh filename="meshes1/L_shoulder_yaw_link.STL" />-->
<!--      </geometry>-->
<!--    </collision>-->
<!--  </link>-->
<!--  <joint name="L_shoulder_yaw" type="fixed">-->
<!--    <origin xyz="0.112 0 0" rpy="1.5707963267949 0 1.5707963267949" />-->
<!--    <parent link="L_shoulder_roll_link" />-->
<!--    <child link="L_shoulder_yaw_link" />-->
<!--    <axis xyz="0 0 -1" />-->
<!--    <limit lower="-2.2689" upper="2.2689" effort="6.6" velocity="50" />-->
<!--  </joint>-->
<!--  <link name="L_elbow_pitch_link">-->
<!--    <inertial>-->
<!--      <origin xyz="0.056038 -0.011478 2.3323E-08" rpy="0 0 0" />-->
<!--      <mass value="0.385" />-->
<!--      <inertia ixx="9.5648E-05" ixy="-8.4499E-06" ixz="-2.3351E-10" iyy="0.00027307" iyz="-3.1898E-10" izz="0.00024995" />-->
<!--    </inertial>-->
<!--    <visual>-->
<!--      <origin xyz="0 0 0" rpy="0 0 0" />-->
<!--      <geometry>-->
<!--        <mesh filename="meshes1/L_elbow_pitch_link.STL" />-->
<!--      </geometry>-->
<!--      <material name="">-->
<!--        <color rgba="1 1 1 1" />-->
<!--      </material>-->
<!--    </visual>-->
<!--    <collision>-->
<!--      <origin xyz="0 0 0" rpy="0 0 0" />-->
<!--      <geometry>-->
<!--        <mesh filename="meshes1/L_elbow_pitch_link.STL" />-->
<!--      </geometry>-->
<!--    </collision>-->
<!--  </link>-->
<!--  <joint name="L_elbow_pitch" type="fixed">-->
<!--    <origin xyz="0 -0.01 0.148" rpy="1.5708 -3.14 1.5708" />-->
<!--    <parent link="L_shoulder_yaw_link" />-->
<!--    <child link="L_elbow_pitch_link" />-->
<!--    <axis xyz="0 0 1" />-->
<!--    <limit lower="0" upper="2.5307" effort="6.6" velocity="50" />-->
<!--  </joint>-->
<!--  <link name="L_elbow_yaw_link">-->
<!--    <inertial>-->
<!--      <origin xyz="0.0070988 -0.0018426 0.14628" rpy="0 0 0" />-->
<!--      <mass value="1.3" />-->
<!--      <inertia ixx="0.00024244" ixy="9.1137E-07" ixz="-8.1946E-07" iyy="0.00024264" iyz="-2.2014E-08" izz="0.00014634" />-->
<!--    </inertial>-->
<!--    <visual>-->
<!--      <origin xyz="0 0 0" rpy="0 0 0" />-->
<!--      <geometry>-->
<!--        <mesh filename="meshes1/L_elbow_yaw_link.STL" />-->
<!--      </geometry>-->
<!--      <material name="">-->
<!--        <color rgba="1 1 1 1" />-->
<!--      </material>-->
<!--    </visual>-->
<!--    <collision>-->
<!--      <origin xyz="0 0 0" rpy="0 0 0" />-->
<!--      <geometry>-->
<!--        <mesh filename="meshes1/L_elbow_yaw_link.STL" />-->
<!--      </geometry>-->
<!--    </collision>-->
<!--  </link>-->
<!--  <joint name="L_elbow_yaw" type="fixed">-->
<!--    <origin xyz="0.1085 -0.01 0" rpy="1.5708 -1.5708 1.5708" />-->
<!--    <parent link="L_elbow_pitch_link" />-->
<!--    <child link="L_elbow_yaw_link" />-->
<!--    <axis xyz="0 0 -1" />-->
<!--    <limit lower="-2.2689" upper="2.2689" effort="1" velocity="50" />-->
<!--  </joint>-->


<!--  <link name="R_shoulder_pitch_link">-->
<!--    <inertial>-->
<!--      <origin xyz="4.4218E-09 -4.5215E-08 0.02287" rpy="0 0 0" />-->
<!--      <mass value="0.763" />-->
<!--      <inertia ixx="5.177E-05" ixy="-7.4692E-11" ixz="6.7773E-12" iyy="2.7775E-05" iyz="1.632E-11" izz="3.6513E-05" />-->
<!--    </inertial>-->
<!--    <visual>-->
<!--      <origin xyz="0 0 0" rpy="0 0 0" />-->
<!--      <geometry>-->
<!--        <mesh filename="meshes1/R_shoulder_pitch_link.STL" />-->
<!--      </geometry>-->
<!--      <material name="">-->
<!--        <color rgba="1 1 1 1" />-->
<!--      </material>-->
<!--    </visual>-->
<!--    <collision>-->
<!--      <origin xyz="0 0 0" rpy="0 0 0" />-->
<!--      <geometry>-->
<!--        <mesh filename="meshes1/R_shoulder_pitch_link.STL" />-->
<!--      </geometry>-->
<!--    </collision>-->
<!--  </link>-->
<!--  <joint name="R_shoulder_pitch" type="fixed">-->
<!--    <origin xyz="0 -0.140425190814725 0.371226723951712" rpy="0 1.30899693899578 -1.5707963267949" />-->
<!--    <parent link="waist_roll_link" />-->
<!--    <child link="R_shoulder_pitch_link" />-->
<!--    <axis xyz="0 0 1" />-->
<!--    <limit lower="-1.5707" upper="3.1416" effort="12" velocity="50" />-->
<!--  </joint>-->
<!--  <link name="R_shoulder_roll_link">-->
<!--    <inertial>-->
<!--      <origin xyz="0.03472 -0.00020363 -9.9611E-09" rpy="0 0 0" />-->
<!--      <mass value="0.725" />-->
<!--      <inertia ixx="0.00022363" ixy="4.2301E-06" ixz="2.1321E-10" iyy="0.0008396" iyz="6.4173E-11" izz="0.00084896" />-->
<!--    </inertial>-->
<!--    <visual>-->
<!--      <origin xyz="0 0 0" rpy="0 0 0" />-->
<!--      <geometry>-->
<!--        <mesh filename="meshes1/R_shoulder_roll_link.STL" />-->
<!--      </geometry>-->
<!--      <material name="">-->
<!--        <color rgba="1 1 1 1" />-->
<!--      </material>-->
<!--    </visual>-->
<!--    <collision>-->
<!--      <origin xyz="0 0 0" rpy="0 0 0" />-->
<!--      <geometry>-->
<!--        <mesh filename="meshes1/R_shoulder_roll_link.STL" />-->
<!--      </geometry>-->
<!--    </collision>-->
<!--  </link>-->
<!--  <joint name="R_shoulder_roll" type="fixed">-->
<!--    <origin xyz="0 0 0.0574999999999973" rpy="-1.5707963267949 0.261799387799121 0" />-->
<!--    <parent link="R_shoulder_pitch_link" />-->
<!--    <child link="R_shoulder_roll_link" />-->
<!--    <axis xyz="0 0 -1" />-->
<!--    <limit lower="0" upper="1.5707" effort="6.6" velocity="50" />-->
<!--  </joint>-->
<!--  <link name="R_shoulder_yaw_link">-->
<!--    <inertial>-->
<!--      <origin xyz="-1.0693E-08 -0.00040667 0.084068" rpy="0 0 0" />-->
<!--      <mass value="0.513" />-->
<!--      <inertia ixx="0.0012458" ixy="5.2971E-11" ixz="-3.2573E-10" iyy="0.0012467" iyz="-6.3281E-05" izz="0.00022286" />-->
<!--    </inertial>-->
<!--    <visual>-->
<!--      <origin xyz="0 0 0" rpy="0 0 0" />-->
<!--      <geometry>-->
<!--        <mesh filename="meshes1/R_shoulder_yaw_link.STL" />-->
<!--      </geometry>-->
<!--      <material name="">-->
<!--        <color rgba="1 1 1 1" />-->
<!--      </material>-->
<!--    </visual>-->
<!--    <collision>-->
<!--      <origin xyz="0 0 0" rpy="0 0 0" />-->
<!--      <geometry>-->
<!--        <mesh filename="meshes1/R_shoulder_yaw_link.STL" />-->
<!--      </geometry>-->
<!--    </collision>-->
<!--  </link>-->
<!--  <joint name="R_shoulder_yaw" type="fixed">-->
<!--    <origin xyz="0.112 0 0" rpy="1.5707963267949 0 1.5707963267949" />-->
<!--    <parent link="R_shoulder_roll_link" />-->
<!--    <child link="R_shoulder_yaw_link" />-->
<!--    <axis xyz="0 0 1" />-->
<!--    <limit lower="-2.2689" upper="2.2689" effort="6.6" velocity="50" />-->
<!--  </joint>-->
<!--  <link name="R_elbow_pitch_link">-->
<!--    <inertial>-->
<!--      <origin xyz="0.056038 0.011478 -2.3324E-08" rpy="0 0 0" />-->
<!--      <mass value="0.385" />-->
<!--      <inertia ixx="9.5648E-05" ixy="8.4499E-06" ixz="2.3351E-10" iyy="0.00027307" iyz="-3.1898E-10" izz="0.00024995" />-->
<!--    </inertial>-->
<!--    <visual>-->
<!--      <origin xyz="0 0 0" rpy="0 0 0" />-->
<!--      <geometry>-->
<!--        <mesh filename="meshes1/R_elbow_pitch_link.STL" />-->
<!--      </geometry>-->
<!--      <material name="">-->
<!--        <color rgba="1 1 1 1" />-->
<!--      </material>-->
<!--    </visual>-->
<!--    <collision>-->
<!--      <origin xyz="0 0 0" rpy="0 0 0" />-->
<!--      <geometry>-->
<!--        <mesh filename="meshes1/R_elbow_pitch_link.STL" />-->
<!--      </geometry>-->
<!--    </collision>-->
<!--  </link>-->
<!--  <joint name="R_elbow_pitch" type="fixed">-->
<!--    <origin xyz="0 0.01 0.148" rpy="1.5708 0 1.5708" />-->
<!--    <parent link="R_shoulder_yaw_link" />-->
<!--    <child link="R_elbow_pitch_link" />-->
<!--    <axis xyz="0 0 -1" />-->
<!--    <limit lower="0" upper="2.5307" effort="6.6" velocity="50" />-->
<!--  </joint>-->
<!--  <link name="R_elbow_yaw_link">-->
<!--    <inertial>-->
<!--      <origin xyz="0.0070988 0.0018422 0.14628" rpy="0 0 0" />-->
<!--      <mass value="1.3" />-->
<!--      <inertia ixx="0.00024245" ixy="-9.1191E-07" ixz="-8.2197E-07" iyy="0.00024264" iyz="1.7973E-08" izz="0.00014634" />-->
<!--    </inertial>-->
<!--    <visual>-->
<!--      <origin xyz="0 0 0" rpy="0 0 0" />-->
<!--      <geometry>-->
<!--        <mesh filename="meshes1/R_elbow_yaw_link.STL" />-->
<!--      </geometry>-->
<!--      <material name="">-->
<!--        <color rgba="1 1 1 1" />-->
<!--      </material>-->
<!--    </visual>-->
<!--    <collision>-->
<!--      <origin xyz="0 0 0" rpy="0 0 0" />-->
<!--      <geometry>-->
<!--        <mesh filename="meshes1/R_elbow_yaw_link.STL" />-->
<!--      </geometry>-->
<!--    </collision>-->
<!--  </link>-->
<!--  <joint name="R_elbow_yaw" type="fixed">-->
<!--    <origin xyz="0.1085 0.01 0" rpy="1.5708 -1.5708 1.5708" />-->
<!--    <parent link="R_elbow_pitch_link" />-->
<!--    <child link="R_elbow_yaw_link" />-->
<!--    <axis xyz="0 0 1" />-->
<!--    <limit lower="-2.2689" upper="2.2689" effort="1" velocity="50" />-->
<!--  </joint>-->
</robot>