<mujoco model="E1_12dof">
  <compiler angle="radian" meshdir="./meshes/"/>
  <statistic meansize="0.144785" extent="1.23314" center="0.025392 2.0634e-05 -0.245975"/>
  <default>
    <joint damping="0.1" armature="0.01" frictionloss="0.3"/>
  </default>
  <asset>
    <mesh name="pelvis" file="pelvis.STL"/>
    <mesh name="left_hip_pitch_link" file="left_hip_pitch_link.STL"/>
    <mesh name="left_hip_roll_link" file="left_hip_roll_link.STL"/>
    <mesh name="left_hip_yaw_link" file="left_hip_yaw_link.STL"/>
    <mesh name="left_knee_link" file="left_knee_link.STL"/>
    <mesh name="left_ankle_pitch_link" file="left_ankle_pitch_link.STL"/>
    <mesh name="right_hip_pitch_link" file="right_hip_pitch_link.STL"/>
    <mesh name="right_hip_roll_link" file="right_hip_roll_link.STL"/>
    <mesh name="right_hip_yaw_link" file="right_hip_yaw_link.STL"/>
    <mesh name="right_knee_link" file="right_knee_link.STL"/>
    <mesh name="right_ankle_pitch_link" file="right_ankle_pitch_link.STL"/>
    <mesh name="torso_link" file="torso_link.STL"/>
    <mesh name="left_shoulder_pitch_link" file="left_shoulder_pitch_link.STL"/>
    <mesh name="left_shoulder_roll_link" file="left_shoulder_roll_link.STL"/>
    <mesh name="left_shoulder_yaw_link" file="left_shoulder_yaw_link.STL"/>
    <mesh name="right_shoulder_pitch_link" file="right_shoulder_pitch_link.STL"/>
    <mesh name="right_shoulder_roll_link" file="right_shoulder_roll_link.STL"/>
    <mesh name="right_shoulder_yaw_link" file="right_shoulder_yaw_link.STL"/>
  </asset>

  <worldbody>
    <body name="pelvis" pos="0 0 0.754">
      <inertial pos="-0.000783647 -0.000908128 0.220941" quat="0.999977 0.00448128 -0.00502837 -6.11387e-05" mass="13.832" diaginertia="0.307113 0.203414 0.123242"/>
      <joint name="floating_base_joint" type="free" limited="false" actuatorfrclimited="false"/>
      <geom type="mesh" contype="0" conaffinity="0" group="1" density="0" rgba="1 1 1 1" mesh="pelvis"/>
      <geom type="mesh" rgba="1 1 1 1" mesh="pelvis"/>
      <geom pos="0 0 0.111" quat="1 0 0 0" type="mesh" contype="0" conaffinity="0" group="1" density="0" rgba="0.419608 0.419608 0.419608 1" mesh="torso_link"/>
      <geom size="0.08 0.08 0.15" pos="0 0 0.241" type="box" rgba="0.419608 0.419608 0.419608 1"/>
      <geom pos="0 0.095 0.35" quat="1 0 0 0" type="mesh" contype="0" conaffinity="0" group="1" density="0" rgba="0.419608 0.419608 0.419608 1" mesh="left_shoulder_pitch_link"/>
      <geom pos="0 0.15 0.35" quat="1 0 0 0" type="mesh" contype="0" conaffinity="0" group="1" density="0" rgba="1 1 1 1" mesh="left_shoulder_roll_link"/>
      <geom pos="0 0.15 0.299" quat="1 0 0 0" type="mesh" contype="0" conaffinity="0" group="1" density="0" rgba="1 1 1 1" mesh="left_shoulder_yaw_link"/>
      <geom pos="0 -0.095 0.35" quat="1 0 0 0" type="mesh" contype="0" conaffinity="0" group="1" density="0" rgba="0.419608 0.419608 0.419608 1" mesh="right_shoulder_pitch_link"/>
      <geom pos="0 -0.15 0.35" quat="1 0 0 0" type="mesh" contype="0" conaffinity="0" group="1" density="0" rgba="1 1 1 1" mesh="right_shoulder_roll_link"/>
      <geom pos="0 -0.15 0.299" quat="1 0 0 0" type="mesh" contype="0" conaffinity="0" group="1" density="0" rgba="1 1 1 1" mesh="right_shoulder_yaw_link"/>
      <site name="imu" pos="0 0 -0.06"/>
      <body name="left_hip_pitch_link" pos="0 0.0575 0">
        <inertial pos="0.0192954 0.0308444 -0.00578934" quat="0.596098 0.717966 0.34423 -0.103431" mass="0.145" diaginertia="0.000127162 0.000104737 3.89609e-05"/>
        <joint name="left_hip_pitch_joint" pos="0 0 0" axis="0 1 0" range="-2.7053 2.7053" actuatorfrcrange="-60 60"/>
        <geom type="mesh" contype="0" conaffinity="0" group="1" density="0" rgba="0.419608 0.419608 0.419608 1" mesh="left_hip_pitch_link"/>
        <body name="left_hip_roll_link" pos="0 0.0575 -0.015">
          <inertial pos="-0.00147244 0.00041537 -0.0372145" quat="0.99892 0.00322789 0.0298082 0.035486" mass="1.39" diaginertia="0.0025721 0.00235517 0.0014478"/>
          <joint name="left_hip_roll_joint" pos="0 0 0" axis="1 0 0" range="-0.1745 2.618" actuatorfrcrange="-36 36"/>
          <geom type="mesh" contype="0" conaffinity="0" group="1" density="0" rgba="1 1 1 1" mesh="left_hip_roll_link"/>
          <body name="left_hip_yaw_link" pos="0 0 -0.098">
            <inertial pos="0.00070152 0.00025365 -0.126147" quat="0.701604 0.0137633 0.00110639 0.712434" mass="2.39" diaginertia="0.0164698 0.0161258 0.00277234"/>
            <joint name="left_hip_yaw_joint" pos="0 0 0" axis="0 0 1" range="-2.4871 3.0107" actuatorfrcrange="-36 36"/>
            <geom type="mesh" contype="0" conaffinity="0" group="1" density="0" rgba="1 1 1 1" mesh="left_hip_yaw_link"/>
            <body name="left_knee_link" pos="0 0 -0.222">
              <inertial pos="0.00414084 -0.00040825 -0.133269" quat="0.71811 0.0034837 -0.00195689 0.695918" mass="1.408" diaginertia="0.0207885 0.0207451 0.00057952"/>
              <joint name="left_knee_joint" pos="0 0 0" axis="0 1 0" range="0 2.4435" actuatorfrcrange="-60 60"/>
              <geom type="mesh" contype="0" conaffinity="0" group="1" density="0" rgba="1 1 1 1" mesh="left_knee_link"/>
              <geom type="mesh" rgba="1 1 1 1" mesh="left_knee_link"/>
              <body name="left_ankle_pitch_link" pos="0 0 -0.32">
                <inertial pos="-0.0142672 -0.00101925 -0.0429843" quat="0.707107 0 0 0.707107" mass="0.597" diaginertia="0.00072568 0.00065314 0.00044755"/>
                <joint name="left_ankle_pitch_joint" pos="0 0 0" axis="0 1 0" range="-1.5708 1.5708" actuatorfrcrange="-60 60"/>
                <geom type="mesh" contype="0" conaffinity="0" group="1" density="0" rgba="0.419608 0.419608 0.419608 1" mesh="left_ankle_pitch_link"/>
                <body name="left_ankle_roll_link" pos="0 0 -0.06">
                  <inertial pos="0.0115206 0 -0.0294706" quat="0 0.693826 0 0.720142" mass="0.294" diaginertia="0.000794803 0.00074194 0.000149907"/>
                  <joint name="left_ankle_roll_joint" pos="0 0 0" axis="1 0 0" range="-1.5708 1.5708" actuatorfrcrange="-14 14"/>
                  <geom size="0.075 0.025 0.005" pos="0.02 0 -0.04" type="box" contype="0" conaffinity="0" group="1" density="0" rgba="1 1 1 1"/>
                  <geom size="0.005" pos="0.107 0.035 -0.045" rgba="1 1 1 1"/>
                  <geom size="0.005" pos="0.107 -0.035 -0.045" rgba="1 1 1 1"/>
                  <geom size="0.005" pos="-0.073 0.035 -0.045" rgba="1 1 1 1"/>
                  <geom size="0.005" pos="-0.073 -0.035 -0.045" rgba="1 1 1 1"/>
                </body>
              </body>
            </body>
          </body>
        </body>
      </body>
      <body name="right_hip_pitch_link" pos="0 -0.0575 0">
        <inertial pos="0.0192954 -0.0308444 -0.00578934" quat="0.717966 0.596098 0.103431 -0.34423" mass="0.145" diaginertia="0.000127162 0.000104737 3.89609e-05"/>
        <joint name="right_hip_pitch_joint" pos="0 0 0" axis="0 1 0" range="-2.7053 2.7053" actuatorfrcrange="-60 60"/>
        <geom type="mesh" contype="0" conaffinity="0" group="1" density="0" rgba="0.41961 0.41961 0.41961 1" mesh="right_hip_pitch_link"/>
        <body name="right_hip_roll_link" pos="0 -0.0575 -0.015">
          <inertial pos="-0.00147237 -0.00041532 -0.0372145" quat="0.99892 -0.00323341 0.0298083 -0.0354861" mass="1.39" diaginertia="0.00257209 0.00235517 0.0014478"/>
          <joint name="right_hip_roll_joint" pos="0 0 0" axis="1 0 0" range="-2.618 0.1745" actuatorfrcrange="-36 36"/>
          <geom type="mesh" contype="0" conaffinity="0" group="1" density="0" rgba="1 1 1 1" mesh="right_hip_roll_link"/>
          <body name="right_hip_yaw_link" pos="0 0 -0.098">
            <inertial pos="0.00070152 -0.00025365 -0.126147" quat="0.712423 0.00110658 0.0137633 0.701614" mass="2.39" diaginertia="0.0164698 0.0161258 0.00277233"/>
            <joint name="right_hip_yaw_joint" pos="0 0 0" axis="0 0 1" range="-3.0107 2.4871" actuatorfrcrange="-36 36"/>
            <geom type="mesh" contype="0" conaffinity="0" group="1" density="0" rgba="1 1 1 1" mesh="right_hip_yaw_link"/>
            <body name="right_knee_link" pos="0 0 -0.222">
              <inertial pos="0.00414085 0.00040825 -0.133269" quat="0.695918 -0.00195689 0.0034837 0.71811" mass="1.408" diaginertia="0.0207885 0.0207451 0.00057952"/>
              <joint name="right_knee_joint" pos="0 0 0" axis="0 1 0" range="0 2.4435" actuatorfrcrange="-60 60"/>
              <geom type="mesh" contype="0" conaffinity="0" group="1" density="0" rgba="1 1 1 1" mesh="right_knee_link"/>
              <geom type="mesh" rgba="1 1 1 1" mesh="right_knee_link"/>
              <body name="right_ankle_pitch_link" pos="0 0 -0.32">
                <inertial pos="-0.0142671 0.00101913 -0.0429843" quat="0.707107 0 0 0.707107" mass="0.597" diaginertia="0.00072569 0.00065314 0.00044755"/>
                <joint name="right_ankle_pitch_joint" pos="0 0 0" axis="0 1 0" range="-1.5708 1.5708" actuatorfrcrange="-60 60"/>
                <geom type="mesh" contype="0" conaffinity="0" group="1" density="0" rgba="0.419608 0.419608 0.419608 1" mesh="right_ankle_pitch_link"/>
                <body name="right_ankle_roll_link" pos="0 0 -0.06">
                  <inertial pos="0.0115206 0 -0.0294706" quat="0 0.693826 0 0.720142" mass="0.294" diaginertia="0.000794803 0.00074194 0.000149907"/>
                  <joint name="right_ankle_roll_joint" pos="0 0 0" axis="1 0 0" range="-1.5708 1.5708" actuatorfrcrange="-14 14"/>
                  <geom size="0.075 0.025 0.005" pos="0.02 0 -0.04" type="box" contype="0" conaffinity="0" group="1" density="0" rgba="1 1 1 1"/>
                  <geom size="0.005" pos="0.107 0.035 -0.045" rgba="1 1 1 1"/>
                  <geom size="0.005" pos="0.107 -0.035 -0.045" rgba="1 1 1 1"/>
                  <geom size="0.005" pos="-0.073 0.035 -0.045" rgba="1 1 1 1"/>
                  <geom size="0.005" pos="-0.073 -0.035 -0.045" rgba="1 1 1 1"/>
                </body>
              </body>
            </body>
          </body>
        </body>
      </body>
    </body>
  </worldbody>
    <actuator>
    <motor name="left_hip_pitch_joint"   joint="left_hip_pitch_joint"   /> <!-- Leg Left -->
    <motor name="left_hip_roll_joint"    joint="left_hip_roll_joint"    />
    <motor name="left_hip_yaw_joint"     joint="left_hip_yaw_joint"     />
    <motor name="left_knee_joint"        joint="left_knee_joint"  />
    <motor name="left_ankle_pitch_joint" joint="left_ankle_pitch_joint" />
    <motor name="left_ankle_roll_joint"  joint="left_ankle_roll_joint"  />

    <motor name="right_hip_pitch_joint"   joint="right_hip_pitch_joint"   /> <!-- Right Left -->
    <motor name="right_hip_roll_joint"    joint="right_hip_roll_joint"    />
    <motor name="right_hip_yaw_joint"     joint="right_hip_yaw_joint"     />
    <motor name="right_knee_joint"        joint="right_knee_joint"  />
    <motor name="right_ankle_pitch_joint" joint="right_ankle_pitch_joint" />
    <motor name="right_ankle_roll_joint"  joint="right_ankle_roll_joint"  />
  </actuator>
  <sensor>
    <!-- 身体的的姿态 -->
    <gyro          name="gyro"    site='imu' noise='0.005' cutoff='34.9'/>
    <accelerometer name="acc"     site='imu' noise='0.005' cutoff='157'/>
    <framequat     name='bq'      objtype='site' noise='0.001' objname='imu'/>
    <framelinvel   name="blv"  objtype='site' objname='imu'/>
  </sensor>
</mujoco>
