<mujoco model="E1_1105">
  <compiler angle="radian" meshdir="./meshes/"/>
  <statistic meansize="0.144785" extent="1.23314" center="0.025392 2.0634e-05 -0.245975"/>
  <default>
    <joint damping="0.1" armature="0.01" frictionloss="0.1"/>
  </default>
  <asset>
    <mesh name="pelvis" file="pelvis.STL"/>
    <mesh name="left_hip_pitch_link" file="left_hip_pitch_link.STL"/>
    <mesh name="left_hip_roll_link" file="left_hip_roll_link.STL"/>
    <mesh name="left_hip_yaw_link" file="left_hip_yaw_link.STL"/>
    <mesh name="left_knee_link" file="left_knee_link.STL"/>
    <mesh name="left_ankle_pitch_link" file="left_ankle_pitch_link.STL"/>
    <mesh name="left_ankle_roll_link" file="left_ankle_roll_link.STL"/>
    <mesh name="right_hip_pitch_link" file="right_hip_pitch_link.STL"/>
    <mesh name="right_hip_roll_link" file="right_hip_roll_link.STL"/>
    <mesh name="right_hip_yaw_link" file="right_hip_yaw_link.STL"/>
    <mesh name="right_knee_link" file="right_knee_link.STL"/>
    <mesh name="right_ankle_pitch_link" file="right_ankle_pitch_link.STL"/>
    <mesh name="right_ankle_roll_link" file="right_ankle_roll_link.STL"/>
    <mesh name="waist_yaw_link" file="waist_yaw_link.STL"/>
    <mesh name="torso_link" file="torso_link.STL"/>
    <mesh name="left_shoulder_pitch_link" file="left_shoulder_pitch_link.STL"/>
    <mesh name="left_shoulder_roll_link" file="left_shoulder_roll_link.STL"/>
    <mesh name="left_shoulder_yaw_link" file="left_shoulder_yaw_link.STL"/>
    <mesh name="left_elbow_link" file="left_elbow_link.STL"/>
    <mesh name="left_wrist_roll_link" file="left_wrist_roll_link.STL"/>
    <mesh name="left_wrist_pitch_link" file="left_wrist_pitch_link.STL"/>
    <mesh name="left_wrist_yaw_link" file="left_wrist_yaw_link.STL"/>
    <mesh name="right_shoulder_pitch_link" file="right_shoulder_pitch_link.STL"/>
    <mesh name="right_shoulder_roll_link" file="right_shoulder_roll_link.STL"/>
    <mesh name="right_shoulder_yaw_link" file="right_shoulder_yaw_link.STL"/>
    <mesh name="right_elbow_link" file="right_elbow_link.STL"/>
    <mesh name="right_wrist_roll_link" file="right_wrist_roll_link.STL"/>
    <mesh name="right_wrist_pitch_link" file="right_wrist_pitch_link.STL"/>
    <mesh name="right_wrist_yaw_link" file="right_wrist_yaw_link.STL"/>
    <mesh name="head_pitch_link" file="head_pitch_link.STL"/>
    <mesh name="head_yaw_link" file="head_yaw_link.STL"/>
  </asset>

  <worldbody>
    <body name="pelvis" pos="0 0 0.72">
      <inertial pos="0.0217024 1.52633e-06 0.213657" quat="0.999086 1.84256e-06 -0.0427348 3.71837e-06" mass="13.9103" diaginertia="0.403285 0.33437 0.181247"/>
      <joint name="pelvis" type="free" limited="false" actuatorfrclimited="false"/>
      <geom type="mesh" contype="0" conaffinity="0" group="1" density="0" rgba="1 1 1 1" mesh="pelvis"/>
      <geom type="mesh" rgba="1 1 1 1" mesh="pelvis"/>
      <geom pos="0 0 0.111" quat="1 0 0 0" type="mesh" contype="0" conaffinity="0" group="1" density="0" rgba="1 1 1 1" mesh="waist_yaw_link"/>
      <geom pos="0 0 0.111" quat="1 0 0 0" type="mesh" rgba="1 1 1 1" mesh="waist_yaw_link"/>
      <geom pos="0 0 0.111" quat="1 0 0 0" type="mesh" contype="0" conaffinity="0" group="1" density="0" rgba="0.419608 0.419608 0.419608 1" mesh="torso_link"/>
      <geom pos="0 0 0.111" quat="1 0 0 0" type="mesh" rgba="0.419608 0.419608 0.419608 1" mesh="torso_link"/>
      <geom pos="0 0.095 0.35" quat="1 0 0 0" type="mesh" contype="0" conaffinity="0" group="1" density="0" rgba="0.419608 0.419608 0.419608 1" mesh="left_shoulder_pitch_link"/>
      <geom pos="0 0.095 0.35" quat="1 0 0 0" type="mesh" rgba="0.419608 0.419608 0.419608 1" mesh="left_shoulder_pitch_link"/>
      <geom pos="0 0.15 0.35" quat="1 0 0 0" type="mesh" contype="0" conaffinity="0" group="1" density="0" rgba="1 1 1 1" mesh="left_shoulder_roll_link"/>
      <geom pos="0 0.15 0.35" quat="1 0 0 0" type="mesh" rgba="1 1 1 1" mesh="left_shoulder_roll_link"/>
      <geom pos="0 0.15 0.299" quat="1 0 0 0" type="mesh" contype="0" conaffinity="0" group="1" density="0" rgba="1 1 1 1" mesh="left_shoulder_yaw_link"/>
      <geom pos="0 0.15 0.299" quat="1 0 0 0" type="mesh" rgba="1 1 1 1" mesh="left_shoulder_yaw_link"/>
      <geom pos="0 0.15 0.14" quat="1 0 0 0" type="mesh" contype="0" conaffinity="0" group="1" density="0" rgba="1 1 1 1" mesh="left_elbow_link"/>
      <geom pos="0 0.15 0.14" quat="1 0 0 0" type="mesh" rgba="1 1 1 1" mesh="left_elbow_link"/>
      <geom pos="0.125 0.15 0.14" quat="1 0 0 0" type="mesh" contype="0" conaffinity="0" group="1" density="0" rgba="1 1 1 1" mesh="left_wrist_roll_link"/>
      <geom pos="0.125 0.15 0.14" quat="1 0 0 0" type="mesh" rgba="1 1 1 1" mesh="left_wrist_roll_link"/>
      <geom pos="0.16 0.15 0.14" quat="1 0 0 0" type="mesh" contype="0" conaffinity="0" group="1" density="0" rgba="0.419608 0.419608 0.419608 1" mesh="left_wrist_pitch_link"/>
      <geom pos="0.16 0.15 0.14" quat="1 0 0 0" type="mesh" rgba="0.419608 0.419608 0.419608 1" mesh="left_wrist_pitch_link"/>
      <geom pos="0.23 0.15 0.14" quat="1 0 0 0" type="mesh" contype="0" conaffinity="0" group="1" density="0" rgba="1 1 1 1" mesh="left_wrist_yaw_link"/>
      <geom pos="0.23 0.15 0.14" quat="1 0 0 0" type="mesh" rgba="1 1 1 1" mesh="left_wrist_yaw_link"/>
      <geom pos="0 -0.095 0.35" quat="1 0 0 0" type="mesh" contype="0" conaffinity="0" group="1" density="0" rgba="0.419608 0.419608 0.419608 1" mesh="right_shoulder_pitch_link"/>
      <geom pos="0 -0.095 0.35" quat="1 0 0 0" type="mesh" rgba="0.419608 0.419608 0.419608 1" mesh="right_shoulder_pitch_link"/>
      <geom pos="0 -0.15 0.35" quat="1 0 0 0" type="mesh" contype="0" conaffinity="0" group="1" density="0" rgba="1 1 1 1" mesh="right_shoulder_roll_link"/>
      <geom pos="0 -0.15 0.35" quat="1 0 0 0" type="mesh" rgba="1 1 1 1" mesh="right_shoulder_roll_link"/>
      <geom pos="0 -0.15 0.299" quat="1 0 0 0" type="mesh" contype="0" conaffinity="0" group="1" density="0" rgba="1 1 1 1" mesh="right_shoulder_yaw_link"/>
      <geom pos="0 -0.15 0.299" quat="1 0 0 0" type="mesh" rgba="1 1 1 1" mesh="right_shoulder_yaw_link"/>
      <geom pos="0 -0.15 0.14" quat="1 0 0 0" type="mesh" contype="0" conaffinity="0" group="1" density="0" rgba="1 1 1 1" mesh="right_elbow_link"/>
      <geom pos="0 -0.15 0.14" quat="1 0 0 0" type="mesh" rgba="1 1 1 1" mesh="right_elbow_link"/>
      <geom pos="0.125 -0.15 0.14" quat="1 0 0 0" type="mesh" contype="0" conaffinity="0" group="1" density="0" rgba="1 1 1 1" mesh="right_wrist_roll_link"/>
      <geom pos="0.125 -0.15 0.14" quat="1 0 0 0" type="mesh" rgba="1 1 1 1" mesh="right_wrist_roll_link"/>
      <geom pos="0.16 -0.15 0.14" quat="1 0 0 0" type="mesh" contype="0" conaffinity="0" group="1" density="0" rgba="0.419608 0.419608 0.419608 1" mesh="right_wrist_pitch_link"/>
      <geom pos="0.16 -0.15 0.14" quat="1 0 0 0" type="mesh" rgba="0.419608 0.419608 0.419608 1" mesh="right_wrist_pitch_link"/>
      <geom pos="0.23 -0.15 0.14" quat="1 0 0 0" type="mesh" contype="0" conaffinity="0" group="1" density="0" rgba="1 1 1 1" mesh="right_wrist_yaw_link"/>
      <geom pos="0.23 -0.15 0.14" quat="1 0 0 0" type="mesh" rgba="1 1 1 1" mesh="right_wrist_yaw_link"/>
      <geom pos="0 0 0.415" type="mesh" contype="0" conaffinity="0" group="1" density="0" rgba="0.41961 0.41961 0.41961 1" mesh="head_pitch_link"/>
      <geom pos="0 0 0.415" type="mesh" rgba="0.41961 0.41961 0.41961 1" mesh="head_pitch_link"/>
      <geom pos="-0.01 0 0.51" quat="1 0 0 0" type="mesh" contype="0" conaffinity="0" group="1" density="0" rgba="0.41961 0.41961 0.41961 1" mesh="head_yaw_link"/>
      <geom pos="-0.01 0 0.51" quat="1 0 0 0" type="mesh" rgba="0.41961 0.41961 0.41961 1" mesh="head_yaw_link"/>
      <site name="imu" pos="0 0 0.07"/>
      <body name="left_hip_pitch_link" pos="0 0.0575 0">
        <inertial pos="1.52452e-07 0.0407814 -0.00956053" quat="0.592227 0.386358 -0.386353 0.592221" mass="0.3" diaginertia="0.000317827 0.000269878 0.000219248"/>
        <joint name="left_hip_pitch_joint" pos="0 0 0" axis="0 1 0" range="-2.7053 2.7053" actuatorfrcrange="-60 60"/>
        <geom type="mesh" contype="0" conaffinity="0" group="1" density="0" rgba="0.419608 0.419608 0.419608 1" mesh="left_hip_pitch_link"/>
        <body name="left_hip_roll_link" pos="0 0.0575 -0.015">
          <inertial pos="6.63802e-08 -8.12334e-10 -0.0406012" quat="0.707107 0.707107 2.95659e-05 -2.50883e-05" mass="0.8" diaginertia="0.000627678 0.000614448 0.000508449"/>
          <joint name="left_hip_roll_joint" pos="0 0 0" axis="1 0 0" range="-0.1745 2.618" actuatorfrcrange="-36 36"/>
          <geom type="mesh" contype="0" conaffinity="0" group="1" density="0" rgba="1 1 1 1" mesh="left_hip_roll_link"/>
          <body name="left_hip_yaw_link" pos="0 0 -0.098">
            <inertial pos="0.00321298 1.33388e-07 -0.102007" quat="0.706677 -0.0261199 -0.0261147 0.706572" mass="1.9" diaginertia="0.00881788 0.00853861 0.00259586"/>
            <joint name="left_hip_yaw_joint" pos="0 0 0" axis="0 0 1" range="-2.4871 3.0107" actuatorfrcrange="-36 36"/>
            <geom type="mesh" contype="0" conaffinity="0" group="1" density="0" rgba="1 1 1 1" mesh="left_hip_yaw_link"/>
            <geom type="mesh" rgba="1 1 1 1" mesh="left_hip_yaw_link"/>
            <body name="left_knee_link" pos="0 0 -0.222">
              <inertial pos="0.0109278 5.37661e-06 -0.133602" quat="0.707173 0.000299726 0.000294909 0.70704" mass="0.8" diaginertia="0.0103757 0.01028 0.000978037"/>
              <joint name="left_knee_joint" pos="0 0 0" axis="0 1 0" range="0 2.4435" actuatorfrcrange="-36 36"/>
              <geom type="mesh" contype="0" conaffinity="0" group="1" density="0" rgba="1 1 1 1" mesh="left_knee_link"/>
              <body name="left_ankle_pitch_link" pos="0 0 -0.32">
                <inertial pos="-0.0132527 1.28367e-08 -0.0294211" quat="0.690572 0.152022 0.152022 0.690572" mass="0.5" diaginertia="0.000394405 0.000374273 0.000108787"/>
                <joint name="left_ankle_pitch_joint" pos="0 0 0" axis="0 1 0" range="-1.5708 1.5708" actuatorfrcrange="-36 36"/>
                <geom type="mesh" contype="0" conaffinity="0" group="1" density="0" rgba="0.419608 0.419608 0.419608 1" mesh="left_ankle_pitch_link"/>
                <geom type="mesh" rgba="0.419608 0.419608 0.419608 1" mesh="left_ankle_pitch_link"/>
                <body name="left_ankle_roll_link" pos="0 0 -0.06">
                  <inertial pos="0.0284593 4.64078e-07 -0.0168246" quat="2.67431e-06 0.71048 -1.23847e-05 0.703717" mass="0.3" diaginertia="0.00140279 0.00130743 0.000296875"/>
                  <joint name="left_ankle_roll_joint" pos="0 0 0" axis="1 0 0" range="-1.5708 1.5708" actuatorfrcrange="-14 14"/>
                  <geom type="mesh" contype="0" conaffinity="0" group="1" density="0" rgba="1 1 1 1" mesh="left_ankle_roll_link"/>
                  <geom type="mesh" rgba="1 1 1 1" mesh="left_ankle_roll_link"/>
                </body>
              </body>
            </body>
          </body>
        </body>
      </body>
      <body name="right_hip_pitch_link" pos="0 -0.0575 0">
        <inertial pos="-1.5244e-07 -0.040781 -0.0095605" quat="0.386352 0.592222 -0.592228 0.386357" mass="0.3" diaginertia="0.000317824 0.00026988 0.000219246"/>
        <joint name="right_hip_pitch_joint" pos="0 0 0" axis="0 1 0" range="-2.7053 2.7053" actuatorfrcrange="-60 60"/>
        <geom type="mesh" contype="0" conaffinity="0" group="1" density="0" rgba="0.41961 0.41961 0.41961 1" mesh="right_hip_pitch_link"/>
        <body name="right_hip_roll_link" pos="0 -0.0575 -0.015">
          <inertial pos="6.63802e-08 -8.12333e-10 -0.0406012" quat="0.707107 0.707107 2.95659e-05 -2.50883e-05" mass="0.8" diaginertia="0.000627678 0.000614448 0.000508449"/>
          <joint name="right_hip_roll_joint" pos="0 0 0" axis="1 0 0" range="-2.618 0.1745" actuatorfrcrange="-36 36"/>
          <geom type="mesh" contype="0" conaffinity="0" group="1" density="0" rgba="1 1 1 1" mesh="right_hip_roll_link"/>
          <body name="right_hip_yaw_link" pos="0 0 -0.098">
            <inertial pos="0.00321298 1.33247e-07 -0.102007" quat="0.706677 -0.0261199 -0.0261147 0.706572" mass="1.9" diaginertia="0.00881788 0.00853861 0.00259586"/>
            <joint name="right_hip_yaw_joint" pos="0 0 0" axis="0 0 1" range="-3.0107 2.4871" actuatorfrcrange="-36 36"/>
            <geom type="mesh" contype="0" conaffinity="0" group="1" density="0" rgba="1 1 1 1" mesh="right_hip_yaw_link"/>
            <geom type="mesh" rgba="1 1 1 1" mesh="right_hip_yaw_link"/>
            <body name="right_knee_link" pos="0 0 -0.222">
              <inertial pos="0.0109278 5.36565e-06 -0.133602" quat="0.707173 0.000299683 0.000294943 0.707041" mass="0.8" diaginertia="0.0103757 0.01028 0.000978037"/>
              <joint name="right_knee_joint" pos="0 0 0" axis="0 1 0" range="0 2.4435" actuatorfrcrange="-36 36"/>
              <geom type="mesh" contype="0" conaffinity="0" group="1" density="0" rgba="1 1 1 1" mesh="right_knee_link"/>
              <body name="right_ankle_pitch_link" pos="0 0 -0.32">
                <inertial pos="-0.0132527 1.28367e-08 -0.0294211" quat="0.690572 0.152022 0.152022 0.690572" mass="0.5" diaginertia="0.000394405 0.000374273 0.000108787"/>
                <joint name="right_ankle_pitch_joint" pos="0 0 0" axis="0 1 0" range="-1.5708 1.5708" actuatorfrcrange="-36 36"/>
                <geom type="mesh" contype="0" conaffinity="0" group="1" density="0" rgba="0.419608 0.419608 0.419608 1" mesh="right_ankle_pitch_link"/>
                <geom type="mesh" rgba="0.419608 0.419608 0.419608 1" mesh="right_ankle_pitch_link"/>
                <body name="right_ankle_roll_link" pos="0 0 -0.06">
                  <inertial pos="0.0284593 4.64741e-07 -0.0168246" quat="2.68614e-06 0.71048 -1.23695e-05 0.703717" mass="0.3" diaginertia="0.00140279 0.00130743 0.000296875"/>
                  <joint name="right_ankle_roll_joint" pos="0 0 0" axis="1 0 0" range="-1.5708 1.5708" actuatorfrcrange="-14 14"/>
                  <geom type="mesh" contype="0" conaffinity="0" group="1" density="0" rgba="1 1 1 1" mesh="right_ankle_roll_link"/>
                  <geom type="mesh" rgba="1 1 1 1" mesh="right_ankle_roll_link"/>
                </body>
              </body>
            </body>
          </body>
        </body>
      </body>
    </body>
  </worldbody>
  <actuator>
    <motor name="left_hip_pitch_joint"     joint="left_hip_pitch_joint"     />
    <motor name="left_hip_roll_joint"      joint="left_hip_roll_joint"      />
    <motor name="left_hip_yaw_joint"       joint="left_hip_yaw_joint"       />
    <motor name="left_knee_joint"          joint="left_knee_joint"    />
    <motor name="left_ankle_pitch_joint"   joint="left_ankle_pitch_joint"   />
    <motor name="left_ankle_roll_joint"    joint="left_ankle_roll_joint"   />

    <motor name="right_hip_pitch_joint"     joint="right_hip_pitch_joint"     />
    <motor name="right_hip_roll_joint"      joint="right_hip_roll_joint"      />
    <motor name="right_hip_yaw_joint"       joint="right_hip_yaw_joint"       />
    <motor name="right_knee_joint"          joint="right_knee_joint"    />
    <motor name="right_ankle_pitch_joint"   joint="right_ankle_pitch_joint"   />
    <motor name="right_ankle_roll_joint"    joint="right_ankle_roll_joint"   />
  </actuator>
  <sensor>
    <!-- 身体的的姿态 -->
    <gyro          name="gyro"    site='imu' noise='0.005' cutoff='34.9'/>
    <accelerometer name="acc"     site='imu' noise='0.005' cutoff='157'/>
    <framequat     name='bq'      objtype='site' noise='0.001' objname='imu'/>
    <framelinvel   name="blv"  objtype='site' objname='imu'/>
  </sensor>
</mujoco>
